Workbook

Sheet Instruções
A1: VALVIC MARCENARIA · GESTÃO MENSAL 2026 — COMO USAR
A2: Leia uma vez. As definições daqui é que impedem o número de mudar conforme quem preenche.
B4: O QUE ESTA PLANILHA RESPONDE
B5: A pergunta do Walton | C5: O que aconteceu na empresa em cada mês, em regime de competência: quanto se vendeu, quanto de material virou móvel, quanto se fabricou, quanto se instalou e quanto se faturou.
B6: O que ela NÃO responde | C6: Se o dinheiro entrou na conta. Isto é competência, não caixa — o mesmo mês dá números bem diferentes pelos dois critérios. As colunas de recebimento e de parcelas já existem para o dia em que o Walton pedir a visão de caixa.
B8: AS DEFINIÇÕES — QUANDO CADA COISA CONTA
B9: R$ vendido | C9: No mês da assinatura do contrato. Vale pelo projeto inteiro. | D9: aba Projetos
B10: Material comprado | C10: No mês da compra, pelo valor cheio — parcelamento não divide o valor, porque parcela é caixa e não competência. | D10: aba Compras
B11: R$ fabricado | C11: No mês em que o ambiente é liberado no portão da fábrica, conferido (POP-01). Ambiente que atravessa o mês conta inteiro no mês em que ficou pronto. | D11: aba Ambientes
B12: Material aplicado | C12: Junto com o R$ fabricado: o material de um ambiente conta no mês em que aquele ambiente ficou pronto. | D12: calculado
B13: R$ instalado | C13: No mês em que o ambiente é montado e aceito pelo cliente. | D13: aba Ambientes
B14: R$ faturado | C14: No mês da emissão da nota. Segue o contrato, não a entrega. | D14: aba Faturamento
B15: Custo fixo | C15: Na competência do mês: folha, estrutura e frota. | D15: aba Custo Fixo
B17: COMO SE PREENCHE
B18: Passo 1 | C18: Cadastre o contrato em Projetos: nome, valor e o mês da venda.
B19: Passo 2 | C19: Quebre o projeto em ambientes na aba Ambientes, com o valor de cada um. A soma tem de fechar com o contrato — a coluna Confere avisa quando não fecha.
B20: Passo 3 | C20: Conforme a obra anda, marque o Mês fabricado e o Mês instalado de cada ambiente. É só isso que move o R$ fabricado, o R$ instalado e o material aplicado.
B21: Passo 4 | C21: Lance as compras em Compras, uma linha por nota, com o projeto. Compra que não é de projeto nenhum (fita, cola, parafuso, ferramenta) fica com o projeto em branco e vira material de uso geral.
B22: Passo 5 | C22: Lance as notas em Faturamento e o custo fixo do mês em Custo Fixo.
B23: Passo 6 | C23: As lâminas de Jan a Dez e a de Ano 2026 se calculam sozinhas. Não digite nada nelas.
B25: O QUE CUIDAR
C26: • Fundo creme é onde se digita. Fundo azul-claro é calculado — não digite por cima, a fórmula se perde.
C27: • O nome do projeto tem de ser escrito igual nas quatro abas. Se sair diferente, a coluna Aviso em Ambientes acende e a soma do projeto não fecha.
C28: • O rateio do material por valor é aproximação: cozinha consome mais material por real que um home. No total do mês se compensa. Quando você souber o material real de um ambiente, informe na coluna Material apurado — o rateio passa a se aplicar só ao que sobrou.
C29: • Ambiente grande demais para caber num mês se quebra em dois ambientes. Não lance percentual: seria trazer de volta a estimativa que o lançamento por ambiente veio resolver.
C30: • Quem informa que o ambiente ficou pronto e que foi aceito precisa ter nome. Sem dono, a planilha desatualiza em três semanas e vira ficção.

Sheet Projetos
A1: VALVIC MARCENARIA · PROJETOS — um contrato por linha
A2: Só o que identifica e o valor. O detalhe vai para a aba Ambientes.
A3: Projeto | B3: Valor do contrato | C3: Mês da venda | D3: Origem / vendedor | E3: Status | F3: Σ ambientes | G3: Confere? | H3: nº mês
F4: =IF($A4="","",SUMIF(Ambientes!$A:$A,$A4,Ambientes!$C:$C)) | G4: =IF($A4="","",IF($B4="","informe o valor do contrato",IF(ABS($B4-$F4)<1,"OK","difere em "&TEXT($B4-$F4,"R$ #,##0")))) | H4: =IF($C4="","",IFERROR(MATCH($C4,Listas!$A$4:$A$15,0),""))
F5: =IF($A5="","",SUMIF(Ambientes!$A:$A,$A5,Ambientes!$C:$C)) | G5: =IF($A5="","",IF($B5="","informe o valor do contrato",IF(ABS($B5-$F5)<1,"OK","difere em "&TEXT($B5-$F5,"R$ #,##0")))) | H5: =IF($C5="","",IFERROR(MATCH($C5,Listas!$A$4:$A$15,0),""))
F6: =IF($A6="","",SUMIF(Ambientes!$A:$A,$A6,Ambientes!$C:$C)) | G6: =IF($A6="","",IF($B6="","informe o valor do contrato",IF(ABS($B6-$F6)<1,"OK","difere em "&TEXT($B6-$F6,"R$ #,##0")))) | H6: =IF($C6="","",IFERROR(MATCH($C6,Listas!$A$4:$A$15,0),""))
F7: =IF($A7="","",SUMIF(Ambientes!$A:$A,$A7,Ambientes!$C:$C)) | G7: =IF($A7="","",IF($B7="","informe o valor do contrato",IF(ABS($B7-$F7)<1,"OK","difere em "&TEXT($B7-$F7,"R$ #,##0")))) | H7: =IF($C7="","",IFERROR(MATCH($C7,Listas!$A$4:$A$15,0),""))
F8: =IF($A8="","",SUMIF(Ambientes!$A:$A,$A8,Ambientes!$C:$C)) | G8: =IF($A8="","",IF($B8="","informe o valor do contrato",IF(ABS($B8-$F8)<1,"OK","difere em "&TEXT($B8-$F8,"R$ #,##0")))) | H8: =IF($C8="","",IFERROR(MATCH($C8,Listas!$A$4:$A$15,0),""))
F9: =IF($A9="","",SUMIF(Ambientes!$A:$A,$A9,Ambientes!$C:$C)) | G9: =IF($A9="","",IF($B9="","informe o valor do contrato",IF(ABS($B9-$F9)<1,"OK","difere em "&TEXT($B9-$F9,"R$ #,##0")))) | H9: =IF($C9="","",IFERROR(MATCH($C9,Listas!$A$4:$A$15,0),""))
F10: =IF($A10="","",SUMIF(Ambientes!$A:$A,$A10,Ambientes!$C:$C)) | G10: =IF($A10="","",IF($B10="","informe o valor do contrato",IF(ABS($B10-$F10)<1,"OK","difere em "&TEXT($B10-$F10,"R$ #,##0")))) | H10: =IF($C10="","",IFERROR(MATCH($C10,Listas!$A$4:$A$15,0),""))
F11: =IF($A11="","",SUMIF(Ambientes!$A:$A,$A11,Ambientes!$C:$C)) | G11: =IF($A11="","",IF($B11="","informe o valor do contrato",IF(ABS($B11-$F11)<1,"OK","difere em "&TEXT($B11-$F11,"R$ #,##0")))) | H11: =IF($C11="","",IFERROR(MATCH($C11,Listas!$A$4:$A$15,0),""))
F12: =IF($A12="","",SUMIF(Ambientes!$A:$A,$A12,Ambientes!$C:$C)) | G12: =IF($A12="","",IF($B12="","informe o valor do contrato",IF(ABS($B12-$F12)<1,"OK","difere em "&TEXT($B12-$F12,"R$ #,##0")))) | H12: =IF($C12="","",IFERROR(MATCH($C12,Listas!$A$4:$A$15,0),""))
F13: =IF($A13="","",SUMIF(Ambientes!$A:$A,$A13,Ambientes!$C:$C)) | G13: =IF($A13="","",IF($B13="","informe o valor do contrato",IF(ABS($B13-$F13)<1,"OK","difere em "&TEXT($B13-$F13,"R$ #,##0")))) | H13: =IF($C13="","",IFERROR(MATCH($C13,Listas!$A$4:$A$15,0),""))
F14: =IF($A14="","",SUMIF(Ambientes!$A:$A,$A14,Ambientes!$C:$C)) | G14: =IF($A14="","",IF($B14="","informe o valor do contrato",IF(ABS($B14-$F14)<1,"OK","difere em "&TEXT($B14-$F14,"R$ #,##0")))) | H14: =IF($C14="","",IFERROR(MATCH($C14,Listas!$A$4:$A$15,0),""))
F15: =IF($A15="","",SUMIF(Ambientes!$A:$A,$A15,Ambientes!$C:$C)) | G15: =IF($A15="","",IF($B15="","informe o valor do contrato",IF(ABS($B15-$F15)<1,"OK","difere em "&TEXT($B15-$F15,"R$ #,##0")))) | H15: =IF($C15="","",IFERROR(MATCH($C15,Listas!$A$4:$A$15,0),""))
... F43: =IF($A43="","",SUMIF(Ambientes!$A:$A,$A43,Ambientes!$C:$C)) | G43: =IF($A43="","",IF($B43="","informe o valor do contrato",IF(ABS($B43-$F43)<1,"OK","difere em "&TEXT($B43-$F43,"R$ #,##0")))) | H43: =IF($C43="","",IFERROR(MATCH($C43,Listas!$A$4:$A$15,0),""))

Sheet Ambientes
A1: VALVIC MARCENARIA · AMBIENTES — o coração da planilha
A2: Um ambiente por linha. É o Mês fabricado e o Mês instalado que movem quase todos os números.
A3: Projeto | B3: Ambiente | C3: Valor do ambiente | D3: Mês fabricado | E3: Mês instalado | F3: Situação | G3: Material apurado (opcional) | H3: Material do ambiente | I3: Aviso | J3: nº mês
F4: =IF($A4="","",IF($E4<>"","Instalado",IF($D4<>"","Fabricado","A produzir"))) | H4: =IF($A4="","",IF($G4>0,$G4,IF((SUMIF($A$4:$A$253,$A4,$C$4:$C$253)-SUMIFS($C$4:$C$253,$A$4:$A$253,$A4,$G$4:$G$253,">0"))<=0,0,MAX(0,(SUMIF(Compras!$A:$A,$A4,Compras!$D:$D)-SUMIFS($G$4:$G$253,$A$4:$A$253,$A4,$G$4:$G$253,">0")))*$C4/(SUMIF($A$4:$A$253,$A4,$C$4:$C$253)-SUMIFS($C$4:$C$253,$A$4:$A$253,$A4,$G$4:$G$253,">0"))))) | I4: =IF($A4="","",IF(COUNTIF(Projetos!$A:$A,$A4)=0,"projeto não cadastrado","")) | J4: =IF($D4="","",IFERROR(MATCH($D4,Listas!$A$4:$A$15,0),""))
F5: =IF($A5="","",IF($E5<>"","Instalado",IF($D5<>"","Fabricado","A produzir"))) | H5: =IF($A5="","",IF($G5>0,$G5,IF((SUMIF($A$4:$A$253,$A5,$C$4:$C$253)-SUMIFS($C$4:$C$253,$A$4:$A$253,$A5,$G$4:$G$253,">0"))<=0,0,MAX(0,(SUMIF(Compras!$A:$A,$A5,Compras!$D:$D)-SUMIFS($G$4:$G$253,$A$4:$A$253,$A5,$G$4:$G$253,">0")))*$C5/(SUMIF($A$4:$A$253,$A5,$C$4:$C$253)-SUMIFS($C$4:$C$253,$A$4:$A$253,$A5,$G$4:$G$253,">0"))))) | I5: =IF($A5="","",IF(COUNTIF(Projetos!$A:$A,$A5)=0,"projeto não cadastrado","")) | J5: =IF($D5="","",IFERROR(MATCH($D5,Listas!$A$4:$A$15,0),""))
F6: =IF($A6="","",IF($E6<>"","Instalado",IF($D6<>"","Fabricado","A produzir"))) | H6: =IF($A6="","",IF($G6>0,$G6,IF((SUMIF($A$4:$A$253,$A6,$C$4:$C$253)-SUMIFS($C$4:$C$253,$A$4:$A$253,$A6,$G$4:$G$253,">0"))<=0,0,MAX(0,(SUMIF(Compras!$A:$A,$A6,Compras!$D:$D)-SUMIFS($G$4:$G$253,$A$4:$A$253,$A6,$G$4:$G$253,">0")))*$C6/(SUMIF($A$4:$A$253,$A6,$C$4:$C$253)-SUMIFS($C$4:$C$253,$A$4:$A$253,$A6,$G$4:$G$253,">0"))))) | I6: =IF($A6="","",IF(COUNTIF(Projetos!$A:$A,$A6)=0,"projeto não cadastrado","")) | J6: =IF($D6="","",IFERROR(MATCH($D6,Listas!$A$4:$A$15,0),""))
F7: =IF($A7="","",IF($E7<>"","Instalado",IF($D7<>"","Fabricado","A produzir"))) | H7: =IF($A7="","",IF($G7>0,$G7,IF((SUMIF($A$4:$A$253,$A7,$C$4:$C$253)-SUMIFS($C$4:$C$253,$A$4:$A$253,$A7,$G$4:$G$253,">0"))<=0,0,MAX(0,(SUMIF(Compras!$A:$A,$A7,Compras!$D:$D)-SUMIFS($G$4:$G$253,$A$4:$A$253,$A7,$G$4:$G$253,">0")))*$C7/(SUMIF($A$4:$A$253,$A7,$C$4:$C$253)-SUMIFS($C$4:$C$253,$A$4:$A$253,$A7,$G$4:$G$253,">0"))))) | I7: =IF($A7="","",IF(COUNTIF(Projetos!$A:$A,$A7)=0,"projeto não cadastrado","")) | J7: =IF($D7="","",IFERROR(MATCH($D7,Listas!$A$4:$A$15,0),""))
F8: =IF($A8="","",IF($E8<>"","Instalado",IF($D8<>"","Fabricado","A produzir"))) | H8: =IF($A8="","",IF($G8>0,$G8,IF((SUMIF($A$4:$A$253,$A8,$C$4:$C$253)-SUMIFS($C$4:$C$253,$A$4:$A$253,$A8,$G$4:$G$253,">0"))<=0,0,MAX(0,(SUMIF(Compras!$A:$A,$A8,Compras!$D:$D)-SUMIFS($G$4:$G$253,$A$4:$A$253,$A8,$G$4:$G$253,">0")))*$C8/(SUMIF($A$4:$A$253,$A8,$C$4:$C$253)-SUMIFS($C$4:$C$253,$A$4:$A$253,$A8,$G$4:$G$253,">0"))))) | I8: =IF($A8="","",IF(COUNTIF(Projetos!$A:$A,$A8)=0,"projeto não cadastrado","")) | J8: =IF($D8="","",IFERROR(MATCH($D8,Listas!$A$4:$A$15,0),""))
F9: =IF($A9="","",IF($E9<>"","Instalado",IF($D9<>"","Fabricado","A produzir"))) | H9: =IF($A9="","",IF($G9>0,$G9,IF((SUMIF($A$4:$A$253,$A9,$C$4:$C$253)-SUMIFS($C$4:$C$253,$A$4:$A$253,$A9,$G$4:$G$253,">0"))<=0,0,MAX(0,(SUMIF(Compras!$A:$A,$A9,Compras!$D:$D)-SUMIFS($G$4:$G$253,$A$4:$A$253,$A9,$G$4:$G$253,">0")))*$C9/(SUMIF($A$4:$A$253,$A9,$C$4:$C$253)-SUMIFS($C$4:$C$253,$A$4:$A$253,$A9,$G$4:$G$253,">0"))))) | I9: =IF($A9="","",IF(COUNTIF(Projetos!$A:$A,$A9)=0,"projeto não cadastrado","")) | J9: =IF($D9="","",IFERROR(MATCH($D9,Listas!$A$4:$A$15,0),""))
F10: =IF($A10="","",IF($E10<>"","Instalado",IF($D10<>"","Fabricado","A produzir"))) | H10: =IF($A10="","",IF($G10>0,$G10,IF((SUMIF($A$4:$A$253,$A10,$C$4:$C$253)-SUMIFS($C$4:$C$253,$A$4:$A$253,$A10,$G$4:$G$253,">0"))<=0,0,MAX(0,(SUMIF(Compras!$A:$A,$A10,Compras!$D:$D)-SUMIFS($G$4:$G$253,$A$4:$A$253,$A10,$G$4:$G$253,">0")))*$C10/(SUMIF($A$4:$A$253,$A10,$C$4:$C$253)-SUMIFS($C$4:$C$253,$A$4:$A$253,$A10,$G$4:$G$253,">0"))))) | I10: =IF($A10="","",IF(COUNTIF(Projetos!$A:$A,$A10)=0,"projeto não cadastrado","")) | J10: =IF($D10="","",IFERROR(MATCH($D10,Listas!$A$4:$A$15,0),""))
F11: =IF($A11="","",IF($E11<>"","Instalado",IF($D11<>"","Fabricado","A produzir"))) | H11: =IF($A11="","",IF($G11>0,$G11,IF((SUMIF($A$4:$A$253,$A11,$C$4:$C$253)-SUMIFS($C$4:$C$253,$A$4:$A$253,$A11,$G$4:$G$253,">0"))<=0,0,MAX(0,(SUMIF(Compras!$A:$A,$A11,Compras!$D:$D)-SUMIFS($G$4:$G$253,$A$4:$A$253,$A11,$G$4:$G$253,">0")))*$C11/(SUMIF($A$4:$A$253,$A11,$C$4:$C$253)-SUMIFS($C$4:$C$253,$A$4:$A$253,$A11,$G$4:$G$253,">0"))))) | I11: =IF($A11="","",IF(COUNTIF(Projetos!$A:$A,$A11)=0,"projeto não cadastrado","")) | J11: =IF($D11="","",IFERROR(MATCH($D11,Listas!$A$4:$A$15,0),""))
F12: =IF($A12="","",IF($E12<>"","Instalado",IF($D12<>"","Fabricado","A produzir"))) | H12: =IF($A12="","",IF($G12>0,$G12,IF((SUMIF($A$4:$A$253,$A12,$C$4:$C$253)-SUMIFS($C$4:$C$253,$A$4:$A$253,$A12,$G$4:$G$253,">0"))<=0,0,MAX(0,(SUMIF(Compras!$A:$A,$A12,Compras!$D:$D)-SUMIFS($G$4:$G$253,$A$4:$A$253,$A12,$G$4:$G$253,">0")))*$C12/(SUMIF($A$4:$A$253,$A12,$C$4:$C$253)-SUMIFS($C$4:$C$253,$A$4:$A$253,$A12,$G$4:$G$253,">0"))))) | I12: =IF($A12="","",IF(COUNTIF(Projetos!$A:$A,$A12)=0,"projeto não cadastrado","")) | J12: =IF($D12="","",IFERROR(MATCH($D12,Listas!$A$4:$A$15,0),""))
F13: =IF($A13="","",IF($E13<>"","Instalado",IF($D13<>"","Fabricado","A produzir"))) | H13: =IF($A13="","",IF($G13>0,$G13,IF((SUMIF($A$4:$A$253,$A13,$C$4:$C$253)-SUMIFS($C$4:$C$253,$A$4:$A$253,$A13,$G$4:$G$253,">0"))<=0,0,MAX(0,(SUMIF(Compras!$A:$A,$A13,Compras!$D:$D)-SUMIFS($G$4:$G$253,$A$4:$A$253,$A13,$G$4:$G$253,">0")))*$C13/(SUMIF($A$4:$A$253,$A13,$C$4:$C$253)-SUMIFS($C$4:$C$253,$A$4:$A$253,$A13,$G$4:$G$253,">0"))))) | I13: =IF($A13="","",IF(COUNTIF(Projetos!$A:$A,$A13)=0,"projeto não cadastrado","")) | J13: =IF($D13="","",IFERROR(MATCH($D13,Listas!$A$4:$A$15,0),""))
F14: =IF($A14="","",IF($E14<>"","Instalado",IF($D14<>"","Fabricado","A produzir"))) | H14: =IF($A14="","",IF($G14>0,$G14,IF((SUMIF($A$4:$A$253,$A14,$C$4:$C$253)-SUMIFS($C$4:$C$253,$A$4:$A$253,$A14,$G$4:$G$253,">0"))<=0,0,MAX(0,(SUMIF(Compras!$A:$A,$A14,Compras!$D:$D)-SUMIFS($G$4:$G$253,$A$4:$A$253,$A14,$G$4:$G$253,">0")))*$C14/(SUMIF($A$4:$A$253,$A14,$C$4:$C$253)-SUMIFS($C$4:$C$253,$A$4:$A$253,$A14,$G$4:$G$253,">0"))))) | I14: =IF($A14="","",IF(COUNTIF(Projetos!$A:$A,$A14)=0,"projeto não cadastrado","")) | J14: =IF($D14="","",IFERROR(MATCH($D14,Listas!$A$4:$A$15,0),""))
F15: =IF($A15="","",IF($E15<>"","Instalado",IF($D15<>"","Fabricado","A produzir"))) | H15: =IF($A15="","",IF($G15>0,$G15,IF((SUMIF($A$4:$A$253,$A15,$C$4:$C$253)-SUMIFS($C$4:$C$253,$A$4:$A$253,$A15,$G$4:$G$253,">0"))<=0,0,MAX(0,(SUMIF(Compras!$A:$A,$A15,Compras!$D:$D)-SUMIFS($G$4:$G$253,$A$4:$A$253,$A15,$G$4:$G$253,">0")))*$C15/(SUMIF($A$4:$A$253,$A15,$C$4:$C$253)-SUMIFS($C$4:$C$253,$A$4:$A$253,$A15,$G$4:$G$253,">0"))))) | I15: =IF($A15="","",IF(COUNTIF(Projetos!$A:$A,$A15)=0,"projeto não cadastrado","")) | J15: =IF($D15="","",IFERROR(MATCH($D15,Listas!$A$4:$A$15,0),""))
... F253: =IF($A253="","",IF($E253<>"","Instalado",IF($D253<>"","Fabricado","A produzir"))) | H253: =IF($A253="","",IF($G253>0,$G253,IF((SUMIF($A$4:$A$253,$A253,$C$4:$C$253)-SUMIFS($C$4:$C$253,$A$4:$A$253,$A253,$G$4:$G$253,">0"))<=0,0,MAX(0,(SUMIF(Compras!$A:$A,$A253,Compras!$D:$D)-SUMIFS($G$4:$G$253,$A$4:$A$253,$A253,$G$4:$G$253,">0")))*$C253/(SUMIF($A$4:$A$253,$A253,$C$4:$C$253)-SUMIFS($C$4:$C$253,$A$4:$A$253,$A253,$G$4:$G$253,">0"))))) | I253: =IF($A253="","",IF(COUNTIF(Projetos!$A:$A,$A253)=0,"projeto não cadastrado","")) | J253: =IF($D253="","",IFERROR(MATCH($D253,Listas!$A$4:$A$15,0),""))

Sheet Faturamento
A1: VALVIC MARCENARIA · FATURAMENTO — uma nota por linha
A2: O mês da emissão é o que conta na competência. O do recebimento fica guardado para a visão de caixa.
A3: Projeto | B3: Nº da nota | C3: Valor | D3: Mês da emissão | E3: Mês do recebimento (para caixa) | F3: Observação

Sheet Compras
A1: VALVIC MARCENARIA · COMPRAS — uma nota por linha
A2: Valor cheio, mesmo parcelado. Sem projeto = material de uso geral (fita, cola, parafuso, ferramenta).
A3: Projeto (em branco = uso geral) | B3: Fornecedor | C3: Categoria | D3: Valor | E3: Mês da compra | F3: Parcelas (para caixa) | G3: Observação | H3: nº mês
H4: =IF($E4="","",IFERROR(MATCH($E4,Listas!$A$4:$A$15,0),""))
H5: =IF($E5="","",IFERROR(MATCH($E5,Listas!$A$4:$A$15,0),""))
H6: =IF($E6="","",IFERROR(MATCH($E6,Listas!$A$4:$A$15,0),""))
H7: =IF($E7="","",IFERROR(MATCH($E7,Listas!$A$4:$A$15,0),""))
H8: =IF($E8="","",IFERROR(MATCH($E8,Listas!$A$4:$A$15,0),""))
H9: =IF($E9="","",IFERROR(MATCH($E9,Listas!$A$4:$A$15,0),""))
H10: =IF($E10="","",IFERROR(MATCH($E10,Listas!$A$4:$A$15,0),""))
H11: =IF($E11="","",IFERROR(MATCH($E11,Listas!$A$4:$A$15,0),""))
H12: =IF($E12="","",IFERROR(MATCH($E12,Listas!$A$4:$A$15,0),""))
H13: =IF($E13="","",IFERROR(MATCH($E13,Listas!$A$4:$A$15,0),""))
H14: =IF($E14="","",IFERROR(MATCH($E14,Listas!$A$4:$A$15,0),""))
H15: =IF($E15="","",IFERROR(MATCH($E15,Listas!$A$4:$A$15,0),""))
... H303: =IF($E303="","",IFERROR(MATCH($E303,Listas!$A$4:$A$15,0),""))

Sheet Custo Fixo
A1: VALVIC MARCENARIA · CUSTO FIXO — um mês por linha
A2: As mesmas três rubricas que já apresentamos ao Walton em agosto, para os números baterem entre os documentos.
A3: Mês | B3: Folha | C3: Estrutura | D3: Frota | E3: Total | F3: Observação
A4: Jan | E4: =IF(COUNT($B4:$D4)=0,"",SUM($B4:$D4))
A5: Fev | E5: =IF(COUNT($B5:$D5)=0,"",SUM($B5:$D5))
A6: Mar | E6: =IF(COUNT($B6:$D6)=0,"",SUM($B6:$D6))
A7: Abr | E7: =IF(COUNT($B7:$D7)=0,"",SUM($B7:$D7))
A8: Mai | E8: =IF(COUNT($B8:$D8)=0,"",SUM($B8:$D8))
A9: Jun | E9: =IF(COUNT($B9:$D9)=0,"",SUM($B9:$D9))
A10: Jul | E10: =IF(COUNT($B10:$D10)=0,"",SUM($B10:$D10))
A11: Ago | E11: =IF(COUNT($B11:$D11)=0,"",SUM($B11:$D11))
A12: Set | E12: =IF(COUNT($B12:$D12)=0,"",SUM($B12:$D12))
A13: Out | E13: =IF(COUNT($B13:$D13)=0,"",SUM($B13:$D13))
A14: Nov | E14: =IF(COUNT($B14:$D14)=0,"",SUM($B14:$D14))
A15: Dez | E15: =IF(COUNT($B15:$D15)=0,"",SUM($B15:$D15))

Sheet Jan
A1: VALVIC MARCENARIA · JANEIRO / 2026
A2: Tudo calculado. Não digite nada nesta aba — os números vêm das abas de lançamento.
B4: OS NÚMEROS DO MÊS · competência
B5: CUSTO FIXO | C5: R$ VENDIDO | D5: MATERIAL APLICADO | E5: R$ FABRICADO | F5: R$ INSTALADO | G5: R$ FATURADO
B6: =SUMIF('Custo Fixo'!$A:$A,"Jan",'Custo Fixo'!$E:$E) | C6: =SUMIF(Projetos!$C:$C,"Jan",Projetos!$B:$B) | D6: =SUMIF(Ambientes!$D:$D,"Jan",Ambientes!$H:$H) | E6: =SUMIF(Ambientes!$D:$D,"Jan",Ambientes!$C:$C) | F6: =SUMIF(Ambientes!$E:$E,"Jan",Ambientes!$C:$C) | G6: =SUMIF(Faturamento!$D:$D,"Jan",Faturamento!$C:$C)
B7: folha · estrutura · frota | C7: contratos assinados | D7: dos ambientes fabricados | E7: ambientes liberados | F7: ambientes aceitos | G7: notas emitidas
B9: LEITURAS DO MÊS
B10: Material comprado | C10: Material em estoque | D10: Material sobre o fabricado | E10: Parado na fábrica | F10: A faturar | G10: Carteira a produzir
B11: compras do mês | C11: comprado de projeto − aplicado, acumulado | D11: aplicado ÷ fabricado | E11: fabricado − instalado | F11: instalado − faturado | G11: vendido acum. − fabricado acum.
B12: =SUMIF(Compras!$E:$E,"Jan",Compras!$D:$D) | C12: =SUMIFS(Compras!$D:$D,Compras!$H:$H,"<=1",Compras!$A:$A,"<>")-SUMIF(Ambientes!$J:$J,"<=1",Ambientes!$H:$H) | D12: =IF($E$6=0,"",$D$6/$E$6) | E12: =$E$6-$F$6 | F12: =$F$6-$G$6 | G12: =SUMIF(Projetos!$H:$H,"<=1",Projetos!$B:$B)-SUMIF(Ambientes!$J:$J,"<=1",Ambientes!$C:$C)
B13: ==IF(SUMIF(Compras!$E:$E,"Jan",Compras!$D:$D)-SUMIFS(Compras!$D:$D,Compras!$E:$E,"Jan",Compras!$A:$A,"<>")=0,"tudo vinculado a projeto","dos quais "&TEXT(SUMIF(Compras!$E:$E,"Jan",Compras!$D:$D)-SUMIFS(Compras!$D:$D,Compras!$E:$E,"Jan",Compras!$A:$A,"<>"),"R$ #,##0")&" de uso geral") | C13: ="explica caixa curto com resultado bom" | D13: ="o termômetro da margem bruta" | E13: ="móvel pronto esperando obra" | F13: ="entregue e ainda sem nota" | G13: ="trabalho que a fábrica já tem contratado"
B15: ONDE ESTE MÊS ACONTECEU · por projeto
B16: Projeto | C16: Fabricado no mês | D16: Instalado no mês | E16: Material aplicado | F16: Faturado no mês | G16: Vendido no mês
B17: =IF(Projetos!$A4="","",Projetos!$A4) | C17: =IF($B17="","",SUMIFS(Ambientes!$C:$C,Ambientes!$A:$A,$B17,Ambientes!$D:$D,"Jan")) | D17: =IF($B17="","",SUMIFS(Ambientes!$C:$C,Ambientes!$A:$A,$B17,Ambientes!$E:$E,"Jan")) | E17: =IF($B17="","",SUMIFS(Ambientes!$H:$H,Ambientes!$A:$A,$B17,Ambientes!$D:$D,"Jan")) | F17: =IF($B17="","",SUMIFS(Faturamento!$C:$C,Faturamento!$A:$A,$B17,Faturamento!$D:$D,"Jan")) | G17: =IF($B17="","",SUMIFS(Projetos!$B:$B,Projetos!$A:$A,$B17,Projetos!$C:$C,"Jan"))
B18: =IF(Projetos!$A5="","",Projetos!$A5) | C18: =IF($B18="","",SUMIFS(Ambientes!$C:$C,Ambientes!$A:$A,$B18,Ambientes!$D:$D,"Jan")) | D18: =IF($B18="","",SUMIFS(Ambientes!$C:$C,Ambientes!$A:$A,$B18,Ambientes!$E:$E,"Jan")) | E18: =IF($B18="","",SUMIFS(Ambientes!$H:$H,Ambientes!$A:$A,$B18,Ambientes!$D:$D,"Jan")) | F18: =IF($B18="","",SUMIFS(Faturamento!$C:$C,Faturamento!$A:$A,$B18,Faturamento!$D:$D,"Jan")) | G18: =IF($B18="","",SUMIFS(Projetos!$B:$B,Projetos!$A:$A,$B18,Projetos!$C:$C,"Jan"))
B19: =IF(Projetos!$A6="","",Projetos!$A6) | C19: =IF($B19="","",SUMIFS(Ambientes!$C:$C,Ambientes!$A:$A,$B19,Ambientes!$D:$D,"Jan")) | D19: =IF($B19="","",SUMIFS(Ambientes!$C:$C,Ambientes!$A:$A,$B19,Ambientes!$E:$E,"Jan")) | E19: =IF($B19="","",SUMIFS(Ambientes!$H:$H,Ambientes!$A:$A,$B19,Ambientes!$D:$D,"Jan")) | F19: =IF($B19="","",SUMIFS(Faturamento!$C:$C,Faturamento!$A:$A,$B19,Faturamento!$D:$D,"Jan")) | G19: =IF($B19="","",SUMIFS(Projetos!$B:$B,Projetos!$A:$A,$B19,Projetos!$C:$C,"Jan"))
B20: =IF(Projetos!$A7="","",Projetos!$A7) | C20: =IF($B20="","",SUMIFS(Ambientes!$C:$C,Ambientes!$A:$A,$B20,Ambientes!$D:$D,"Jan")) | D20: =IF($B20="","",SUMIFS(Ambientes!$C:$C,Ambientes!$A:$A,$B20,Ambientes!$E:$E,"Jan")) | E20: =IF($B20="","",SUMIFS(Ambientes!$H:$H,Ambientes!$A:$A,$B20,Ambientes!$D:$D,"Jan")) | F20: =IF($B20="","",SUMIFS(Faturamento!$C:$C,Faturamento!$A:$A,$B20,Faturamento!$D:$D,"Jan")) | G20: =IF($B20="","",SUMIFS(Projetos!$B:$B,Projetos!$A:$A,$B20,Projetos!$C:$C,"Jan"))
B21: =IF(Projetos!$A8="","",Projetos!$A8) | C21: =IF($B21="","",SUMIFS(Ambientes!$C:$C,Ambientes!$A:$A,$B21,Ambientes!$D:$D,"Jan")) | D21: =IF($B21="","",SUMIFS(Ambientes!$C:$C,Ambientes!$A:$A,$B21,Ambientes!$E:$E,"Jan")) | E21: =IF($B21="","",SUMIFS(Ambientes!$H:$H,Ambientes!$A:$A,$B21,Ambientes!$D:$D,"Jan")) | F21: =IF($B21="","",SUMIFS(Faturamento!$C:$C,Faturamento!$A:$A,$B21,Faturamento!$D:$D,"Jan")) | G21: =IF($B21="","",SUMIFS(Projetos!$B:$B,Projetos!$A:$A,$B21,Projetos!$C:$C,"Jan"))
B22: =IF(Projetos!$A9="","",Projetos!$A9) | C22: =IF($B22="","",SUMIFS(Ambientes!$C:$C,Ambientes!$A:$A,$B22,Ambientes!$D:$D,"Jan")) | D22: =IF($B22="","",SUMIFS(Ambientes!$C:$C,Ambientes!$A:$A,$B22,Ambientes!$E:$E,"Jan")) | E22: =IF($B22="","",SUMIFS(Ambientes!$H:$H,Ambientes!$A:$A,$B22,Ambientes!$D:$D,"Jan")) | F22: =IF($B22="","",SUMIFS(Faturamento!$C:$C,Faturamento!$A:$A,$B22,Faturamento!$D:$D,"Jan")) | G22: =IF($B22="","",SUMIFS(Projetos!$B:$B,Projetos!$A:$A,$B22,Projetos!$C:$C,"Jan"))
B23: =IF(Projetos!$A10="","",Projetos!$A10) | C23: =IF($B23="","",SUMIFS(Ambientes!$C:$C,Ambientes!$A:$A,$B23,Ambientes!$D:$D,"Jan")) | D23: =IF($B23="","",SUMIFS(Ambientes!$C:$C,Ambientes!$A:$A,$B23,Ambientes!$E:$E,"Jan")) | E23: =IF($B23="","",SUMIFS(Ambientes!$H:$H,Ambientes!$A:$A,$B23,Ambientes!$D:$D,"Jan")) | F23: =IF($B23="","",SUMIFS(Faturamento!$C:$C,Faturamento!$A:$A,$B23,Faturamento!$D:$D,"Jan")) | G23: =IF($B23="","",SUMIFS(Projetos!$B:$B,Projetos!$A:$A,$B23,Projetos!$C:$C,"Jan"))
B24: =IF(Projetos!$A11="","",Projetos!$A11) | C24: =IF($B24="","",SUMIFS(Ambientes!$C:$C,Ambientes!$A:$A,$B24,Ambientes!$D:$D,"Jan")) | D24: =IF($B24="","",SUMIFS(Ambientes!$C:$C,Ambientes!$A:$A,$B24,Ambientes!$E:$E,"Jan")) | E24: =IF($B24="","",SUMIFS(Ambientes!$H:$H,Ambientes!$A:$A,$B24,Ambientes!$D:$D,"Jan")) | F24: =IF($B24="","",SUMIFS(Faturamento!$C:$C,Faturamento!$A:$A,$B24,Faturamento!$D:$D,"Jan")) | G24: =IF($B24="","",SUMIFS(Projetos!$B:$B,Projetos!$A:$A,$B24,Projetos!$C:$C,"Jan"))
B25: =IF(Projetos!$A12="","",Projetos!$A12) | C25: =IF($B25="","",SUMIFS(Ambientes!$C:$C,Ambientes!$A:$A,$B25,Ambientes!$D:$D,"Jan")) | D25: =IF($B25="","",SUMIFS(Ambientes!$C:$C,Ambientes!$A:$A,$B25,Ambientes!$E:$E,"Jan")) | E25: =IF($B25="","",SUMIFS(Ambientes!$H:$H,Ambientes!$A:$A,$B25,Ambientes!$D:$D,"Jan")) | F25: =IF($B25="","",SUMIFS(Faturamento!$C:$C,Faturamento!$A:$A,$B25,Faturamento!$D:$D,"Jan")) | G25: =IF($B25="","",SUMIFS(Projetos!$B:$B,Projetos!$A:$A,$B25,Projetos!$C:$C,"Jan"))
B26: =IF(Projetos!$A13="","",Projetos!$A13) | C26: =IF($B26="","",SUMIFS(Ambientes!$C:$C,Ambientes!$A:$A,$B26,Ambientes!$D:$D,"Jan")) | D26: =IF($B26="","",SUMIFS(Ambientes!$C:$C,Ambientes!$A:$A,$B26,Ambientes!$E:$E,"Jan")) | E26: =IF($B26="","",SUMIFS(Ambientes!$H:$H,Ambientes!$A:$A,$B26,Ambientes!$D:$D,"Jan")) | F26: =IF($B26="","",SUMIFS(Faturamento!$C:$C,Faturamento!$A:$A,$B26,Faturamento!$D:$D,"Jan")) | G26: =IF($B26="","",SUMIFS(Projetos!$B:$B,Projetos!$A:$A,$B26,Projetos!$C:$C,"Jan"))
B27: =IF(Projetos!$A14="","",Projetos!$A14) | C27: =IF($B27="","",SUMIFS(Ambientes!$C:$C,Ambientes!$A:$A,$B27,Ambientes!$D:$D,"Jan")) | D27: =IF($B27="","",SUMIFS(Ambientes!$C:$C,Ambientes!$A:$A,$B27,Ambientes!$E:$E,"Jan")) | E27: =IF($B27="","",SUMIFS(Ambientes!$H:$H,Ambientes!$A:$A,$B27,Ambientes!$D:$D,"Jan")) | F27: =IF($B27="","",SUMIFS(Faturamento!$C:$C,Faturamento!$A:$A,$B27,Faturamento!$D:$D,"Jan")) | G27: =IF($B27="","",SUMIFS(Projetos!$B:$B,Projetos!$A:$A,$B27,Projetos!$C:$C,"Jan"))
B28: =IF(Projetos!$A15="","",Projetos!$A15) | C28: =IF($B28="","",SUMIFS(Ambientes!$C:$C,Ambientes!$A:$A,$B28,Ambientes!$D:$D,"Jan")) | D28: =IF($B28="","",SUMIFS(Ambientes!$C:$C,Ambientes!$A:$A,$B28,Ambientes!$E:$E,"Jan")) | E28: =IF($B28="","",SUMIFS(Ambientes!$H:$H,Ambientes!$A:$A,$B28,Ambientes!$D:$D,"Jan")) | F28: =IF($B28="","",SUMIFS(Faturamento!$C:$C,Faturamento!$A:$A,$B28,Faturamento!$D:$D,"Jan")) | G28: =IF($B28="","",SUMIFS(Projetos!$B:$B,Projetos!$A:$A,$B28,Projetos!$C:$C,"Jan"))
... B56: =IF(Projetos!$A43="","",Projetos!$A43) | C56: =IF($B56="","",SUMIFS(Ambientes!$C:$C,Ambientes!$A:$A,$B56,Ambientes!$D:$D,"Jan")) | D56: =IF($B56="","",SUMIFS(Ambientes!$C:$C,Ambientes!$A:$A,$B56,Ambientes!$E:$E,"Jan")) | E56: =IF($B56="","",SUMIFS(Ambientes!$H:$H,Ambientes!$A:$A,$B56,Ambientes!$D:$D,"Jan")) | F56: =IF($B56="","",SUMIFS(Faturamento!$C:$C,Faturamento!$A:$A,$B56,Faturamento!$D:$D,"Jan")) | G56: =IF($B56="","",SUMIFS(Projetos!$B:$B,Projetos!$A:$A,$B56,Projetos!$C:$C,"Jan"))

Sheet Fev
A1: VALVIC MARCENARIA · FEVEREIRO / 2026
A2: Tudo calculado. Não digite nada nesta aba — os números vêm das abas de lançamento.
B4: OS NÚMEROS DO MÊS · competência
B5: CUSTO FIXO | C5: R$ VENDIDO | D5: MATERIAL APLICADO | E5: R$ FABRICADO | F5: R$ INSTALADO | G5: R$ FATURADO
B6: =SUMIF('Custo Fixo'!$A:$A,"Fev",'Custo Fixo'!$E:$E) | C6: =SUMIF(Projetos!$C:$C,"Fev",Projetos!$B:$B) | D6: =SUMIF(Ambientes!$D:$D,"Fev",Ambientes!$H:$H) | E6: =SUMIF(Ambientes!$D:$D,"Fev",Ambientes!$C:$C) | F6: =SUMIF(Ambientes!$E:$E,"Fev",Ambientes!$C:$C) | G6: =SUMIF(Faturamento!$D:$D,"Fev",Faturamento!$C:$C)
B7: folha · estrutura · frota | C7: contratos assinados | D7: dos ambientes fabricados | E7: ambientes liberados | F7: ambientes aceitos | G7: notas emitidas
B9: LEITURAS DO MÊS
B10: Material comprado | C10: Material em estoque | D10: Material sobre o fabricado | E10: Parado na fábrica | F10: A faturar | G10: Carteira a produzir
B11: compras do mês | C11: comprado de projeto − aplicado, acumulado | D11: aplicado ÷ fabricado | E11: fabricado − instalado | F11: instalado − faturado | G11: vendido acum. − fabricado acum.
B12: =SUMIF(Compras!$E:$E,"Fev",Compras!$D:$D) | C12: =SUMIFS(Compras!$D:$D,Compras!$H:$H,"<=2",Compras!$A:$A,"<>")-SUMIF(Ambientes!$J:$J,"<=2",Ambientes!$H:$H) | D12: =IF($E$6=0,"",$D$6/$E$6) | E12: =$E$6-$F$6 | F12: =$F$6-$G$6 | G12: =SUMIF(Projetos!$H:$H,"<=2",Projetos!$B:$B)-SUMIF(Ambientes!$J:$J,"<=2",Ambientes!$C:$C)
B13: ==IF(SUMIF(Compras!$E:$E,"Fev",Compras!$D:$D)-SUMIFS(Compras!$D:$D,Compras!$E:$E,"Fev",Compras!$A:$A,"<>")=0,"tudo vinculado a projeto","dos quais "&TEXT(SUMIF(Compras!$E:$E,"Fev",Compras!$D:$D)-SUMIFS(Compras!$D:$D,Compras!$E:$E,"Fev",Compras!$A:$A,"<>"),"R$ #,##0")&" de uso geral") | C13: ="explica caixa curto com resultado bom" | D13: ="o termômetro da margem bruta" | E13: ="móvel pronto esperando obra" | F13: ="entregue e ainda sem nota" | G13: ="trabalho que a fábrica já tem contratado"
B15: ONDE ESTE MÊS ACONTECEU · por projeto
B16: Projeto | C16: Fabricado no mês | D16: Instalado no mês | E16: Material aplicado | F16: Faturado no mês | G16: Vendido no mês
B17: =IF(Projetos!$A4="","",Projetos!$A4) | C17: =IF($B17="","",SUMIFS(Ambientes!$C:$C,Ambientes!$A:$A,$B17,Ambientes!$D:$D,"Fev")) | D17: =IF($B17="","",SUMIFS(Ambientes!$C:$C,Ambientes!$A:$A,$B17,Ambientes!$E:$E,"Fev")) | E17: =IF($B17="","",SUMIFS(Ambientes!$H:$H,Ambientes!$A:$A,$B17,Ambientes!$D:$D,"Fev")) | F17: =IF($B17="","",SUMIFS(Faturamento!$C:$C,Faturamento!$A:$A,$B17,Faturamento!$D:$D,"Fev")) | G17: =IF($B17="","",SUMIFS(Projetos!$B:$B,Projetos!$A:$A,$B17,Projetos!$C:$C,"Fev"))
B18: =IF(Projetos!$A5="","",Projetos!$A5) | C18: =IF($B18="","",SUMIFS(Ambientes!$C:$C,Ambientes!$A:$A,$B18,Ambientes!$D:$D,"Fev")) | D18: =IF($B18="","",SUMIFS(Ambientes!$C:$C,Ambientes!$A:$A,$B18,Ambientes!$E:$E,"Fev")) | E18: =IF($B18="","",SUMIFS(Ambientes!$H:$H,Ambientes!$A:$A,$B18,Ambientes!$D:$D,"Fev")) | F18: =IF($B18="","",SUMIFS(Faturamento!$C:$C,Faturamento!$A:$A,$B18,Faturamento!$D:$D,"Fev")) | G18: =IF($B18="","",SUMIFS(Projetos!$B:$B,Projetos!$A:$A,$B18,Projetos!$C:$C,"Fev"))
B19: =IF(Projetos!$A6="","",Projetos!$A6) | C19: =IF($B19="","",SUMIFS(Ambientes!$C:$C,Ambientes!$A:$A,$B19,Ambientes!$D:$D,"Fev")) | D19: =IF($B19="","",SUMIFS(Ambientes!$C:$C,Ambientes!$A:$A,$B19,Ambientes!$E:$E,"Fev")) | E19: =IF($B19="","",SUMIFS(Ambientes!$H:$H,Ambientes!$A:$A,$B19,Ambientes!$D:$D,"Fev")) | F19: =IF($B19="","",SUMIFS(Faturamento!$C:$C,Faturamento!$A:$A,$B19,Faturamento!$D:$D,"Fev")) | G19: =IF($B19="","",SUMIFS(Projetos!$B:$B,Projetos!$A:$A,$B19,Projetos!$C:$C,"Fev"))
B20: =IF(Projetos!$A7="","",Projetos!$A7) | C20: =IF($B20="","",SUMIFS(Ambientes!$C:$C,Ambientes!$A:$A,$B20,Ambientes!$D:$D,"Fev")) | D20: =IF($B20="","",SUMIFS(Ambientes!$C:$C,Ambientes!$A:$A,$B20,Ambientes!$E:$E,"Fev")) | E20: =IF($B20="","",SUMIFS(Ambientes!$H:$H,Ambientes!$A:$A,$B20,Ambientes!$D:$D,"Fev")) | F20: =IF($B20="","",SUMIFS(Faturamento!$C:$C,Faturamento!$A:$A,$B20,Faturamento!$D:$D,"Fev")) | G20: =IF($B20="","",SUMIFS(Projetos!$B:$B,Projetos!$A:$A,$B20,Projetos!$C:$C,"Fev"))
B21: =IF(Projetos!$A8="","",Projetos!$A8) | C21: =IF($B21="","",SUMIFS(Ambientes!$C:$C,Ambientes!$A:$A,$B21,Ambientes!$D:$D,"Fev")) | D21: =IF($B21="","",SUMIFS(Ambientes!$C:$C,Ambientes!$A:$A,$B21,Ambientes!$E:$E,"Fev")) | E21: =IF($B21="","",SUMIFS(Ambientes!$H:$H,Ambientes!$A:$A,$B21,Ambientes!$D:$D,"Fev")) | F21: =IF($B21="","",SUMIFS(Faturamento!$C:$C,Faturamento!$A:$A,$B21,Faturamento!$D:$D,"Fev")) | G21: =IF($B21="","",SUMIFS(Projetos!$B:$B,Projetos!$A:$A,$B21,Projetos!$C:$C,"Fev"))
B22: =IF(Projetos!$A9="","",Projetos!$A9) | C22: =IF($B22="","",SUMIFS(Ambientes!$C:$C,Ambientes!$A:$A,$B22,Ambientes!$D:$D,"Fev")) | D22: =IF($B22="","",SUMIFS(Ambientes!$C:$C,Ambientes!$A:$A,$B22,Ambientes!$E:$E,"Fev")) | E22: =IF($B22="","",SUMIFS(Ambientes!$H:$H,Ambientes!$A:$A,$B22,Ambientes!$D:$D,"Fev")) | F22: =IF($B22="","",SUMIFS(Faturamento!$C:$C,Faturamento!$A:$A,$B22,Faturamento!$D:$D,"Fev")) | G22: =IF($B22="","",SUMIFS(Projetos!$B:$B,Projetos!$A:$A,$B22,Projetos!$C:$C,"Fev"))
B23: =IF(Projetos!$A10="","",Projetos!$A10) | C23: =IF($B23="","",SUMIFS(Ambientes!$C:$C,Ambientes!$A:$A,$B23,Ambientes!$D:$D,"Fev")) | D23: =IF($B23="","",SUMIFS(Ambientes!$C:$C,Ambientes!$A:$A,$B23,Ambientes!$E:$E,"Fev")) | E23: =IF($B23="","",SUMIFS(Ambientes!$H:$H,Ambientes!$A:$A,$B23,Ambientes!$D:$D,"Fev")) | F23: =IF($B23="","",SUMIFS(Faturamento!$C:$C,Faturamento!$A:$A,$B23,Faturamento!$D:$D,"Fev")) | G23: =IF($B23="","",SUMIFS(Projetos!$B:$B,Projetos!$A:$A,$B23,Projetos!$C:$C,"Fev"))
B24: =IF(Projetos!$A11="","",Projetos!$A11) | C24: =IF($B24="","",SUMIFS(Ambientes!$C:$C,Ambientes!$A:$A,$B24,Ambientes!$D:$D,"Fev")) | D24: =IF($B24="","",SUMIFS(Ambientes!$C:$C,Ambientes!$A:$A,$B24,Ambientes!$E:$E,"Fev")) | E24: =IF($B24="","",SUMIFS(Ambientes!$H:$H,Ambientes!$A:$A,$B24,Ambientes!$D:$D,"Fev")) | F24: =IF($B24="","",SUMIFS(Faturamento!$C:$C,Faturamento!$A:$A,$B24,Faturamento!$D:$D,"Fev")) | G24: =IF($B24="","",SUMIFS(Projetos!$B:$B,Projetos!$A:$A,$B24,Projetos!$C:$C,"Fev"))
B25: =IF(Projetos!$A12="","",Projetos!$A12) | C25: =IF($B25="","",SUMIFS(Ambientes!$C:$C,Ambientes!$A:$A,$B25,Ambientes!$D:$D,"Fev")) | D25: =IF($B25="","",SUMIFS(Ambientes!$C:$C,Ambientes!$A:$A,$B25,Ambientes!$E:$E,"Fev")) | E25: =IF($B25="","",SUMIFS(Ambientes!$H:$H,Ambientes!$A:$A,$B25,Ambientes!$D:$D,"Fev")) | F25: =IF($B25="","",SUMIFS(Faturamento!$C:$C,Faturamento!$A:$A,$B25,Faturamento!$D:$D,"Fev")) | G25: =IF($B25="","",SUMIFS(Projetos!$B:$B,Projetos!$A:$A,$B25,Projetos!$C:$C,"Fev"))
B26: =IF(Projetos!$A13="","",Projetos!$A13) | C26: =IF($B26="","",SUMIFS(Ambientes!$C:$C,Ambientes!$A:$A,$B26,Ambientes!$D:$D,"Fev")) | D26: =IF($B26="","",SUMIFS(Ambientes!$C:$C,Ambientes!$A:$A,$B26,Ambientes!$E:$E,"Fev")) | E26: =IF($B26="","",SUMIFS(Ambientes!$H:$H,Ambientes!$A:$A,$B26,Ambientes!$D:$D,"Fev")) | F26: =IF($B26="","",SUMIFS(Faturamento!$C:$C,Faturamento!$A:$A,$B26,Faturamento!$D:$D,"Fev")) | G26: =IF($B26="","",SUMIFS(Projetos!$B:$B,Projetos!$A:$A,$B26,Projetos!$C:$C,"Fev"))
B27: =IF(Projetos!$A14="","",Projetos!$A14) | C27: =IF($B27="","",SUMIFS(Ambientes!$C:$C,Ambientes!$A:$A,$B27,Ambientes!$D:$D,"Fev")) | D27: =IF($B27="","",SUMIFS(Ambientes!$C:$C,Ambientes!$A:$A,$B27,Ambientes!$E:$E,"Fev")) | E27: =IF($B27="","",SUMIFS(Ambientes!$H:$H,Ambientes!$A:$A,$B27,Ambientes!$D:$D,"Fev")) | F27: =IF($B27="","",SUMIFS(Faturamento!$C:$C,Faturamento!$A:$A,$B27,Faturamento!$D:$D,"Fev")) | G27: =IF($B27="","",SUMIFS(Projetos!$B:$B,Projetos!$A:$A,$B27,Projetos!$C:$C,"Fev"))
B28: =IF(Projetos!$A15="","",Projetos!$A15) | C28: =IF($B28="","",SUMIFS(Ambientes!$C:$C,Ambientes!$A:$A,$B28,Ambientes!$D:$D,"Fev")) | D28: =IF($B28="","",SUMIFS(Ambientes!$C:$C,Ambientes!$A:$A,$B28,Ambientes!$E:$E,"Fev")) | E28: =IF($B28="","",SUMIFS(Ambientes!$H:$H,Ambientes!$A:$A,$B28,Ambientes!$D:$D,"Fev")) | F28: =IF($B28="","",SUMIFS(Faturamento!$C:$C,Faturamento!$A:$A,$B28,Faturamento!$D:$D,"Fev")) | G28: =IF($B28="","",SUMIFS(Projetos!$B:$B,Projetos!$A:$A,$B28,Projetos!$C:$C,"Fev"))
... B56: =IF(Projetos!$A43="","",Projetos!$A43) | C56: =IF($B56="","",SUMIFS(Ambientes!$C:$C,Ambientes!$A:$A,$B56,Ambientes!$D:$D,"Fev")) | D56: =IF($B56="","",SUMIFS(Ambientes!$C:$C,Ambientes!$A:$A,$B56,Ambientes!$E:$E,"Fev")) | E56: =IF($B56="","",SUMIFS(Ambientes!$H:$H,Ambientes!$A:$A,$B56,Ambientes!$D:$D,"Fev")) | F56: =IF($B56="","",SUMIFS(Faturamento!$C:$C,Faturamento!$A:$A,$B56,Faturamento!$D:$D,"Fev")) | G56: =IF($B56="","",SUMIFS(Projetos!$B:$B,Projetos!$A:$A,$B56,Projetos!$C:$C,"Fev"))

Sheet Mar
A1: VALVIC MARCENARIA · MARÇO / 2026
A2: Tudo calculado. Não digite nada nesta aba — os números vêm das abas de lançamento.
B4: OS NÚMEROS DO MÊS · competência
B5: CUSTO FIXO | C5: R$ VENDIDO | D5: MATERIAL APLICADO | E5: R$ FABRICADO | F5: R$ INSTALADO | G5: R$ FATURADO
B6: =SUMIF('Custo Fixo'!$A:$A,"Mar",'Custo Fixo'!$E:$E) | C6: =SUMIF(Projetos!$C:$C,"Mar",Projetos!$B:$B) | D6: =SUMIF(Ambientes!$D:$D,"Mar",Ambientes!$H:$H) | E6: =SUMIF(Ambientes!$D:$D,"Mar",Ambientes!$C:$C) | F6: =SUMIF(Ambientes!$E:$E,"Mar",Ambientes!$C:$C) | G6: =SUMIF(Faturamento!$D:$D,"Mar",Faturamento!$C:$C)
B7: folha · estrutura · frota | C7: contratos assinados | D7: dos ambientes fabricados | E7: ambientes liberados | F7: ambientes aceitos | G7: notas emitidas
B9: LEITURAS DO MÊS
B10: Material comprado | C10: Material em estoque | D10: Material sobre o fabricado | E10: Parado na fábrica | F10: A faturar | G10: Carteira a produzir
B11: compras do mês | C11: comprado de projeto − aplicado, acumulado | D11: aplicado ÷ fabricado | E11: fabricado − instalado | F11: instalado − faturado | G11: vendido acum. − fabricado acum.
B12: =SUMIF(Compras!$E:$E,"Mar",Compras!$D:$D) | C12: =SUMIFS(Compras!$D:$D,Compras!$H:$H,"<=3",Compras!$A:$A,"<>")-SUMIF(Ambientes!$J:$J,"<=3",Ambientes!$H:$H) | D12: =IF($E$6=0,"",$D$6/$E$6) | E12: =$E$6-$F$6 | F12: =$F$6-$G$6 | G12: =SUMIF(Projetos!$H:$H,"<=3",Projetos!$B:$B)-SUMIF(Ambientes!$J:$J,"<=3",Ambientes!$C:$C)
B13: ==IF(SUMIF(Compras!$E:$E,"Mar",Compras!$D:$D)-SUMIFS(Compras!$D:$D,Compras!$E:$E,"Mar",Compras!$A:$A,"<>")=0,"tudo vinculado a projeto","dos quais "&TEXT(SUMIF(Compras!$E:$E,"Mar",Compras!$D:$D)-SUMIFS(Compras!$D:$D,Compras!$E:$E,"Mar",Compras!$A:$A,"<>"),"R$ #,##0")&" de uso geral") | C13: ="explica caixa curto com resultado bom" | D13: ="o termômetro da margem bruta" | E13: ="móvel pronto esperando obra" | F13: ="entregue e ainda sem nota" | G13: ="trabalho que a fábrica já tem contratado"
B15: ONDE ESTE MÊS ACONTECEU · por projeto
B16: Projeto | C16: Fabricado no mês | D16: Instalado no mês | E16: Material aplicado | F16: Faturado no mês | G16: Vendido no mês
B17: =IF(Projetos!$A4="","",Projetos!$A4) | C17: =IF($B17="","",SUMIFS(Ambientes!$C:$C,Ambientes!$A:$A,$B17,Ambientes!$D:$D,"Mar")) | D17: =IF($B17="","",SUMIFS(Ambientes!$C:$C,Ambientes!$A:$A,$B17,Ambientes!$E:$E,"Mar")) | E17: =IF($B17="","",SUMIFS(Ambientes!$H:$H,Ambientes!$A:$A,$B17,Ambientes!$D:$D,"Mar")) | F17: =IF($B17="","",SUMIFS(Faturamento!$C:$C,Faturamento!$A:$A,$B17,Faturamento!$D:$D,"Mar")) | G17: =IF($B17="","",SUMIFS(Projetos!$B:$B,Projetos!$A:$A,$B17,Projetos!$C:$C,"Mar"))
B18: =IF(Projetos!$A5="","",Projetos!$A5) | C18: =IF($B18="","",SUMIFS(Ambientes!$C:$C,Ambientes!$A:$A,$B18,Ambientes!$D:$D,"Mar")) | D18: =IF($B18="","",SUMIFS(Ambientes!$C:$C,Ambientes!$A:$A,$B18,Ambientes!$E:$E,"Mar")) | E18: =IF($B18="","",SUMIFS(Ambientes!$H:$H,Ambientes!$A:$A,$B18,Ambientes!$D:$D,"Mar")) | F18: =IF($B18="","",SUMIFS(Faturamento!$C:$C,Faturamento!$A:$A,$B18,Faturamento!$D:$D,"Mar")) | G18: =IF($B18="","",SUMIFS(Projetos!$B:$B,Projetos!$A:$A,$B18,Projetos!$C:$C,"Mar"))
B19: =IF(Projetos!$A6="","",Projetos!$A6) | C19: =IF($B19="","",SUMIFS(Ambientes!$C:$C,Ambientes!$A:$A,$B19,Ambientes!$D:$D,"Mar")) | D19: =IF($B19="","",SUMIFS(Ambientes!$C:$C,Ambientes!$A:$A,$B19,Ambientes!$E:$E,"Mar")) | E19: =IF($B19="","",SUMIFS(Ambientes!$H:$H,Ambientes!$A:$A,$B19,Ambientes!$D:$D,"Mar")) | F19: =IF($B19="","",SUMIFS(Faturamento!$C:$C,Faturamento!$A:$A,$B19,Faturamento!$D:$D,"Mar")) | G19: =IF($B19="","",SUMIFS(Projetos!$B:$B,Projetos!$A:$A,$B19,Projetos!$C:$C,"Mar"))
B20: =IF(Projetos!$A7="","",Projetos!$A7) | C20: =IF($B20="","",SUMIFS(Ambientes!$C:$C,Ambientes!$A:$A,$B20,Ambientes!$D:$D,"Mar")) | D20: =IF($B20="","",SUMIFS(Ambientes!$C:$C,Ambientes!$A:$A,$B20,Ambientes!$E:$E,"Mar")) | E20: =IF($B20="","",SUMIFS(Ambientes!$H:$H,Ambientes!$A:$A,$B20,Ambientes!$D:$D,"Mar")) | F20: =IF($B20="","",SUMIFS(Faturamento!$C:$C,Faturamento!$A:$A,$B20,Faturamento!$D:$D,"Mar")) | G20: =IF($B20="","",SUMIFS(Projetos!$B:$B,Projetos!$A:$A,$B20,Projetos!$C:$C,"Mar"))
B21: =IF(Projetos!$A8="","",Projetos!$A8) | C21: =IF($B21="","",SUMIFS(Ambientes!$C:$C,Ambientes!$A:$A,$B21,Ambientes!$D:$D,"Mar")) | D21: =IF($B21="","",SUMIFS(Ambientes!$C:$C,Ambientes!$A:$A,$B21,Ambientes!$E:$E,"Mar")) | E21: =IF($B21="","",SUMIFS(Ambientes!$H:$H,Ambientes!$A:$A,$B21,Ambientes!$D:$D,"Mar")) | F21: =IF($B21="","",SUMIFS(Faturamento!$C:$C,Faturamento!$A:$A,$B21,Faturamento!$D:$D,"Mar")) | G21: =IF($B21="","",SUMIFS(Projetos!$B:$B,Projetos!$A:$A,$B21,Projetos!$C:$C,"Mar"))
B22: =IF(Projetos!$A9="","",Projetos!$A9) | C22: =IF($B22="","",SUMIFS(Ambientes!$C:$C,Ambientes!$A:$A,$B22,Ambientes!$D:$D,"Mar")) | D22: =IF($B22="","",SUMIFS(Ambientes!$C:$C,Ambientes!$A:$A,$B22,Ambientes!$E:$E,"Mar")) | E22: =IF($B22="","",SUMIFS(Ambientes!$H:$H,Ambientes!$A:$A,$B22,Ambientes!$D:$D,"Mar")) | F22: =IF($B22="","",SUMIFS(Faturamento!$C:$C,Faturamento!$A:$A,$B22,Faturamento!$D:$D,"Mar")) | G22: =IF($B22="","",SUMIFS(Projetos!$B:$B,Projetos!$A:$A,$B22,Projetos!$C:$C,"Mar"))
B23: =IF(Projetos!$A10="","",Projetos!$A10) | C23: =IF($B23="","",SUMIFS(Ambientes!$C:$C,Ambientes!$A:$A,$B23,Ambientes!$D:$D,"Mar")) | D23: =IF($B23="","",SUMIFS(Ambientes!$C:$C,Ambientes!$A:$A,$B23,Ambientes!$E:$E,"Mar")) | E23: =IF($B23="","",SUMIFS(Ambientes!$H:$H,Ambientes!$A:$A,$B23,Ambientes!$D:$D,"Mar")) | F23: =IF($B23="","",SUMIFS(Faturamento!$C:$C,Faturamento!$A:$A,$B23,Faturamento!$D:$D,"Mar")) | G23: =IF($B23="","",SUMIFS(Projetos!$B:$B,Projetos!$A:$A,$B23,Projetos!$C:$C,"Mar"))
B24: =IF(Projetos!$A11="","",Projetos!$A11) | C24: =IF($B24="","",SUMIFS(Ambientes!$C:$C,Ambientes!$A:$A,$B24,Ambientes!$D:$D,"Mar")) | D24: =IF($B24="","",SUMIFS(Ambientes!$C:$C,Ambientes!$A:$A,$B24,Ambientes!$E:$E,"Mar")) | E24: =IF($B24="","",SUMIFS(Ambientes!$H:$H,Ambientes!$A:$A,$B24,Ambientes!$D:$D,"Mar")) | F24: =IF($B24="","",SUMIFS(Faturamento!$C:$C,Faturamento!$A:$A,$B24,Faturamento!$D:$D,"Mar")) | G24: =IF($B24="","",SUMIFS(Projetos!$B:$B,Projetos!$A:$A,$B24,Projetos!$C:$C,"Mar"))
B25: =IF(Projetos!$A12="","",Projetos!$A12) | C25: =IF($B25="","",SUMIFS(Ambientes!$C:$C,Ambientes!$A:$A,$B25,Ambientes!$D:$D,"Mar")) | D25: =IF($B25="","",SUMIFS(Ambientes!$C:$C,Ambientes!$A:$A,$B25,Ambientes!$E:$E,"Mar")) | E25: =IF($B25="","",SUMIFS(Ambientes!$H:$H,Ambientes!$A:$A,$B25,Ambientes!$D:$D,"Mar")) | F25: =IF($B25="","",SUMIFS(Faturamento!$C:$C,Faturamento!$A:$A,$B25,Faturamento!$D:$D,"Mar")) | G25: =IF($B25="","",SUMIFS(Projetos!$B:$B,Projetos!$A:$A,$B25,Projetos!$C:$C,"Mar"))
B26: =IF(Projetos!$A13="","",Projetos!$A13) | C26: =IF($B26="","",SUMIFS(Ambientes!$C:$C,Ambientes!$A:$A,$B26,Ambientes!$D:$D,"Mar")) | D26: =IF($B26="","",SUMIFS(Ambientes!$C:$C,Ambientes!$A:$A,$B26,Ambientes!$E:$E,"Mar")) | E26: =IF($B26="","",SUMIFS(Ambientes!$H:$H,Ambientes!$A:$A,$B26,Ambientes!$D:$D,"Mar")) | F26: =IF($B26="","",SUMIFS(Faturamento!$C:$C,Faturamento!$A:$A,$B26,Faturamento!$D:$D,"Mar")) | G26: =IF($B26="","",SUMIFS(Projetos!$B:$B,Projetos!$A:$A,$B26,Projetos!$C:$C,"Mar"))
B27: =IF(Projetos!$A14="","",Projetos!$A14) | C27: =IF($B27="","",SUMIFS(Ambientes!$C:$C,Ambientes!$A:$A,$B27,Ambientes!$D:$D,"Mar")) | D27: =IF($B27="","",SUMIFS(Ambientes!$C:$C,Ambientes!$A:$A,$B27,Ambientes!$E:$E,"Mar")) | E27: =IF($B27="","",SUMIFS(Ambientes!$H:$H,Ambientes!$A:$A,$B27,Ambientes!$D:$D,"Mar")) | F27: =IF($B27="","",SUMIFS(Faturamento!$C:$C,Faturamento!$A:$A,$B27,Faturamento!$D:$D,"Mar")) | G27: =IF($B27="","",SUMIFS(Projetos!$B:$B,Projetos!$A:$A,$B27,Projetos!$C:$C,"Mar"))
B28: =IF(Projetos!$A15="","",Projetos!$A15) | C28: =IF($B28="","",SUMIFS(Ambientes!$C:$C,Ambientes!$A:$A,$B28,Ambientes!$D:$D,"Mar")) | D28: =IF($B28="","",SUMIFS(Ambientes!$C:$C,Ambientes!$A:$A,$B28,Ambientes!$E:$E,"Mar")) | E28: =IF($B28="","",SUMIFS(Ambientes!$H:$H,Ambientes!$A:$A,$B28,Ambientes!$D:$D,"Mar")) | F28: =IF($B28="","",SUMIFS(Faturamento!$C:$C,Faturamento!$A:$A,$B28,Faturamento!$D:$D,"Mar")) | G28: =IF($B28="","",SUMIFS(Projetos!$B:$B,Projetos!$A:$A,$B28,Projetos!$C:$C,"Mar"))
... B56: =IF(Projetos!$A43="","",Projetos!$A43) | C56: =IF($B56="","",SUMIFS(Ambientes!$C:$C,Ambientes!$A:$A,$B56,Ambientes!$D:$D,"Mar")) | D56: =IF($B56="","",SUMIFS(Ambientes!$C:$C,Ambientes!$A:$A,$B56,Ambientes!$E:$E,"Mar")) | E56: =IF($B56="","",SUMIFS(Ambientes!$H:$H,Ambientes!$A:$A,$B56,Ambientes!$D:$D,"Mar")) | F56: =IF($B56="","",SUMIFS(Faturamento!$C:$C,Faturamento!$A:$A,$B56,Faturamento!$D:$D,"Mar")) | G56: =IF($B56="","",SUMIFS(Projetos!$B:$B,Projetos!$A:$A,$B56,Projetos!$C:$C,"Mar"))

Sheet Abr
A1: VALVIC MARCENARIA · ABRIL / 2026
A2: Tudo calculado. Não digite nada nesta aba — os números vêm das abas de lançamento.
B4: OS NÚMEROS DO MÊS · competência
B5: CUSTO FIXO | C5: R$ VENDIDO | D5: MATERIAL APLICADO | E5: R$ FABRICADO | F5: R$ INSTALADO | G5: R$ FATURADO
B6: =SUMIF('Custo Fixo'!$A:$A,"Abr",'Custo Fixo'!$E:$E) | C6: =SUMIF(Projetos!$C:$C,"Abr",Projetos!$B:$B) | D6: =SUMIF(Ambientes!$D:$D,"Abr",Ambientes!$H:$H) | E6: =SUMIF(Ambientes!$D:$D,"Abr",Ambientes!$C:$C) | F6: =SUMIF(Ambientes!$E:$E,"Abr",Ambientes!$C:$C) | G6: =SUMIF(Faturamento!$D:$D,"Abr",Faturamento!$C:$C)
B7: folha · estrutura · frota | C7: contratos assinados | D7: dos ambientes fabricados | E7: ambientes liberados | F7: ambientes aceitos | G7: notas emitidas
B9: LEITURAS DO MÊS
B10: Material comprado | C10: Material em estoque | D10: Material sobre o fabricado | E10: Parado na fábrica | F10: A faturar | G10: Carteira a produzir
B11: compras do mês | C11: comprado de projeto − aplicado, acumulado | D11: aplicado ÷ fabricado | E11: fabricado − instalado | F11: instalado − faturado | G11: vendido acum. − fabricado acum.
B12: =SUMIF(Compras!$E:$E,"Abr",Compras!$D:$D) | C12: =SUMIFS(Compras!$D:$D,Compras!$H:$H,"<=4",Compras!$A:$A,"<>")-SUMIF(Ambientes!$J:$J,"<=4",Ambientes!$H:$H) | D12: =IF($E$6=0,"",$D$6/$E$6) | E12: =$E$6-$F$6 | F12: =$F$6-$G$6 | G12: =SUMIF(Projetos!$H:$H,"<=4",Projetos!$B:$B)-SUMIF(Ambientes!$J:$J,"<=4",Ambientes!$C:$C)
B13: ==IF(SUMIF(Compras!$E:$E,"Abr",Compras!$D:$D)-SUMIFS(Compras!$D:$D,Compras!$E:$E,"Abr",Compras!$A:$A,"<>")=0,"tudo vinculado a projeto","dos quais "&TEXT(SUMIF(Compras!$E:$E,"Abr",Compras!$D:$D)-SUMIFS(Compras!$D:$D,Compras!$E:$E,"Abr",Compras!$A:$A,"<>"),"R$ #,##0")&" de uso geral") | C13: ="explica caixa curto com resultado bom" | D13: ="o termômetro da margem bruta" | E13: ="móvel pronto esperando obra" | F13: ="entregue e ainda sem nota" | G13: ="trabalho que a fábrica já tem contratado"
B15: ONDE ESTE MÊS ACONTECEU · por projeto
B16: Projeto | C16: Fabricado no mês | D16: Instalado no mês | E16: Material aplicado | F16: Faturado no mês | G16: Vendido no mês
B17: =IF(Projetos!$A4="","",Projetos!$A4) | C17: =IF($B17="","",SUMIFS(Ambientes!$C:$C,Ambientes!$A:$A,$B17,Ambientes!$D:$D,"Abr")) | D17: =IF($B17="","",SUMIFS(Ambientes!$C:$C,Ambientes!$A:$A,$B17,Ambientes!$E:$E,"Abr")) | E17: =IF($B17="","",SUMIFS(Ambientes!$H:$H,Ambientes!$A:$A,$B17,Ambientes!$D:$D,"Abr")) | F17: =IF($B17="","",SUMIFS(Faturamento!$C:$C,Faturamento!$A:$A,$B17,Faturamento!$D:$D,"Abr")) | G17: =IF($B17="","",SUMIFS(Projetos!$B:$B,Projetos!$A:$A,$B17,Projetos!$C:$C,"Abr"))
B18: =IF(Projetos!$A5="","",Projetos!$A5) | C18: =IF($B18="","",SUMIFS(Ambientes!$C:$C,Ambientes!$A:$A,$B18,Ambientes!$D:$D,"Abr")) | D18: =IF($B18="","",SUMIFS(Ambientes!$C:$C,Ambientes!$A:$A,$B18,Ambientes!$E:$E,"Abr")) | E18: =IF($B18="","",SUMIFS(Ambientes!$H:$H,Ambientes!$A:$A,$B18,Ambientes!$D:$D,"Abr")) | F18: =IF($B18="","",SUMIFS(Faturamento!$C:$C,Faturamento!$A:$A,$B18,Faturamento!$D:$D,"Abr")) | G18: =IF($B18="","",SUMIFS(Projetos!$B:$B,Projetos!$A:$A,$B18,Projetos!$C:$C,"Abr"))
B19: =IF(Projetos!$A6="","",Projetos!$A6) | C19: =IF($B19="","",SUMIFS(Ambientes!$C:$C,Ambientes!$A:$A,$B19,Ambientes!$D:$D,"Abr")) | D19: =IF($B19="","",SUMIFS(Ambientes!$C:$C,Ambientes!$A:$A,$B19,Ambientes!$E:$E,"Abr")) | E19: =IF($B19="","",SUMIFS(Ambientes!$H:$H,Ambientes!$A:$A,$B19,Ambientes!$D:$D,"Abr")) | F19: =IF($B19="","",SUMIFS(Faturamento!$C:$C,Faturamento!$A:$A,$B19,Faturamento!$D:$D,"Abr")) | G19: =IF($B19="","",SUMIFS(Projetos!$B:$B,Projetos!$A:$A,$B19,Projetos!$C:$C,"Abr"))
B20: =IF(Projetos!$A7="","",Projetos!$A7) | C20: =IF($B20="","",SUMIFS(Ambientes!$C:$C,Ambientes!$A:$A,$B20,Ambientes!$D:$D,"Abr")) | D20: =IF($B20="","",SUMIFS(Ambientes!$C:$C,Ambientes!$A:$A,$B20,Ambientes!$E:$E,"Abr")) | E20: =IF($B20="","",SUMIFS(Ambientes!$H:$H,Ambientes!$A:$A,$B20,Ambientes!$D:$D,"Abr")) | F20: =IF($B20="","",SUMIFS(Faturamento!$C:$C,Faturamento!$A:$A,$B20,Faturamento!$D:$D,"Abr")) | G20: =IF($B20="","",SUMIFS(Projetos!$B:$B,Projetos!$A:$A,$B20,Projetos!$C:$C,"Abr"))
B21: =IF(Projetos!$A8="","",Projetos!$A8) | C21: =IF($B21="","",SUMIFS(Ambientes!$C:$C,Ambientes!$A:$A,$B21,Ambientes!$D:$D,"Abr")) | D21: =IF($B21="","",SUMIFS(Ambientes!$C:$C,Ambientes!$A:$A,$B21,Ambientes!$E:$E,"Abr")) | E21: =IF($B21="","",SUMIFS(Ambientes!$H:$H,Ambientes!$A:$A,$B21,Ambientes!$D:$D,"Abr")) | F21: =IF($B21="","",SUMIFS(Faturamento!$C:$C,Faturamento!$A:$A,$B21,Faturamento!$D:$D,"Abr")) | G21: =IF($B21="","",SUMIFS(Projetos!$B:$B,Projetos!$A:$A,$B21,Projetos!$C:$C,"Abr"))
B22: =IF(Projetos!$A9="","",Projetos!$A9) | C22: =IF($B22="","",SUMIFS(Ambientes!$C:$C,Ambientes!$A:$A,$B22,Ambientes!$D:$D,"Abr")) | D22: =IF($B22="","",SUMIFS(Ambientes!$C:$C,Ambientes!$A:$A,$B22,Ambientes!$E:$E,"Abr")) | E22: =IF($B22="","",SUMIFS(Ambientes!$H:$H,Ambientes!$A:$A,$B22,Ambientes!$D:$D,"Abr")) | F22: =IF($B22="","",SUMIFS(Faturamento!$C:$C,Faturamento!$A:$A,$B22,Faturamento!$D:$D,"Abr")) | G22: =IF($B22="","",SUMIFS(Projetos!$B:$B,Projetos!$A:$A,$B22,Projetos!$C:$C,"Abr"))
B23: =IF(Projetos!$A10="","",Projetos!$A10) | C23: =IF($B23="","",SUMIFS(Ambientes!$C:$C,Ambientes!$A:$A,$B23,Ambientes!$D:$D,"Abr")) | D23: =IF($B23="","",SUMIFS(Ambientes!$C:$C,Ambientes!$A:$A,$B23,Ambientes!$E:$E,"Abr")) | E23: =IF($B23="","",SUMIFS(Ambientes!$H:$H,Ambientes!$A:$A,$B23,Ambientes!$D:$D,"Abr")) | F23: =IF($B23="","",SUMIFS(Faturamento!$C:$C,Faturamento!$A:$A,$B23,Faturamento!$D:$D,"Abr")) | G23: =IF($B23="","",SUMIFS(Projetos!$B:$B,Projetos!$A:$A,$B23,Projetos!$C:$C,"Abr"))
B24: =IF(Projetos!$A11="","",Projetos!$A11) | C24: =IF($B24="","",SUMIFS(Ambientes!$C:$C,Ambientes!$A:$A,$B24,Ambientes!$D:$D,"Abr")) | D24: =IF($B24="","",SUMIFS(Ambientes!$C:$C,Ambientes!$A:$A,$B24,Ambientes!$E:$E,"Abr")) | E24: =IF($B24="","",SUMIFS(Ambientes!$H:$H,Ambientes!$A:$A,$B24,Ambientes!$D:$D,"Abr")) | F24: =IF($B24="","",SUMIFS(Faturamento!$C:$C,Faturamento!$A:$A,$B24,Faturamento!$D:$D,"Abr")) | G24: =IF($B24="","",SUMIFS(Projetos!$B:$B,Projetos!$A:$A,$B24,Projetos!$C:$C,"Abr"))
B25: =IF(Projetos!$A12="","",Projetos!$A12) | C25: =IF($B25="","",SUMIFS(Ambientes!$C:$C,Ambientes!$A:$A,$B25,Ambientes!$D:$D,"Abr")) | D25: =IF($B25="","",SUMIFS(Ambientes!$C:$C,Ambientes!$A:$A,$B25,Ambientes!$E:$E,"Abr")) | E25: =IF($B25="","",SUMIFS(Ambientes!$H:$H,Ambientes!$A:$A,$B25,Ambientes!$D:$D,"Abr")) | F25: =IF($B25="","",SUMIFS(Faturamento!$C:$C,Faturamento!$A:$A,$B25,Faturamento!$D:$D,"Abr")) | G25: =IF($B25="","",SUMIFS(Projetos!$B:$B,Projetos!$A:$A,$B25,Projetos!$C:$C,"Abr"))
B26: =IF(Projetos!$A13="","",Projetos!$A13) | C26: =IF($B26="","",SUMIFS(Ambientes!$C:$C,Ambientes!$A:$A,$B26,Ambientes!$D:$D,"Abr")) | D26: =IF($B26="","",SUMIFS(Ambientes!$C:$C,Ambientes!$A:$A,$B26,Ambientes!$E:$E,"Abr")) | E26: =IF($B26="","",SUMIFS(Ambientes!$H:$H,Ambientes!$A:$A,$B26,Ambientes!$D:$D,"Abr")) | F26: =IF($B26="","",SUMIFS(Faturamento!$C:$C,Faturamento!$A:$A,$B26,Faturamento!$D:$D,"Abr")) | G26: =IF($B26="","",SUMIFS(Projetos!$B:$B,Projetos!$A:$A,$B26,Projetos!$C:$C,"Abr"))
B27: =IF(Projetos!$A14="","",Projetos!$A14) | C27: =IF($B27="","",SUMIFS(Ambientes!$C:$C,Ambientes!$A:$A,$B27,Ambientes!$D:$D,"Abr")) | D27: =IF($B27="","",SUMIFS(Ambientes!$C:$C,Ambientes!$A:$A,$B27,Ambientes!$E:$E,"Abr")) | E27: =IF($B27="","",SUMIFS(Ambientes!$H:$H,Ambientes!$A:$A,$B27,Ambientes!$D:$D,"Abr")) | F27: =IF($B27="","",SUMIFS(Faturamento!$C:$C,Faturamento!$A:$A,$B27,Faturamento!$D:$D,"Abr")) | G27: =IF($B27="","",SUMIFS(Projetos!$B:$B,Projetos!$A:$A,$B27,Projetos!$C:$C,"Abr"))
B28: =IF(Projetos!$A15="","",Projetos!$A15) | C28: =IF($B28="","",SUMIFS(Ambientes!$C:$C,Ambientes!$A:$A,$B28,Ambientes!$D:$D,"Abr")) | D28: =IF($B28="","",SUMIFS(Ambientes!$C:$C,Ambientes!$A:$A,$B28,Ambientes!$E:$E,"Abr")) | E28: =IF($B28="","",SUMIFS(Ambientes!$H:$H,Ambientes!$A:$A,$B28,Ambientes!$D:$D,"Abr")) | F28: =IF($B28="","",SUMIFS(Faturamento!$C:$C,Faturamento!$A:$A,$B28,Faturamento!$D:$D,"Abr")) | G28: =IF($B28="","",SUMIFS(Projetos!$B:$B,Projetos!$A:$A,$B28,Projetos!$C:$C,"Abr"))
... B56: =IF(Projetos!$A43="","",Projetos!$A43) | C56: =IF($B56="","",SUMIFS(Ambientes!$C:$C,Ambientes!$A:$A,$B56,Ambientes!$D:$D,"Abr")) | D56: =IF($B56="","",SUMIFS(Ambientes!$C:$C,Ambientes!$A:$A,$B56,Ambientes!$E:$E,"Abr")) | E56: =IF($B56="","",SUMIFS(Ambientes!$H:$H,Ambientes!$A:$A,$B56,Ambientes!$D:$D,"Abr")) | F56: =IF($B56="","",SUMIFS(Faturamento!$C:$C,Faturamento!$A:$A,$B56,Faturamento!$D:$D,"Abr")) | G56: =IF($B56="","",SUMIFS(Projetos!$B:$B,Projetos!$A:$A,$B56,Projetos!$C:$C,"Abr"))

Sheet Mai
A1: VALVIC MARCENARIA · MAIO / 2026
A2: Tudo calculado. Não digite nada nesta aba — os números vêm das abas de lançamento.
B4: OS NÚMEROS DO MÊS · competência
B5: CUSTO FIXO | C5: R$ VENDIDO | D5: MATERIAL APLICADO | E5: R$ FABRICADO | F5: R$ INSTALADO | G5: R$ FATURADO
B6: =SUMIF('Custo Fixo'!$A:$A,"Mai",'Custo Fixo'!$E:$E) | C6: =SUMIF(Projetos!$C:$C,"Mai",Projetos!$B:$B) | D6: =SUMIF(Ambientes!$D:$D,"Mai",Ambientes!$H:$H) | E6: =SUMIF(Ambientes!$D:$D,"Mai",Ambientes!$C:$C) | F6: =SUMIF(Ambientes!$E:$E,"Mai",Ambientes!$C:$C) | G6: =SUMIF(Faturamento!$D:$D,"Mai",Faturamento!$C:$C)
B7: folha · estrutura · frota | C7: contratos assinados | D7: dos ambientes fabricados | E7: ambientes liberados | F7: ambientes aceitos | G7: notas emitidas
B9: LEITURAS DO MÊS
B10: Material comprado | C10: Material em estoque | D10: Material sobre o fabricado | E10: Parado na fábrica | F10: A faturar | G10: Carteira a produzir
B11: compras do mês | C11: comprado de projeto − aplicado, acumulado | D11: aplicado ÷ fabricado | E11: fabricado − instalado | F11: instalado − faturado | G11: vendido acum. − fabricado acum.
B12: =SUMIF(Compras!$E:$E,"Mai",Compras!$D:$D) | C12: =SUMIFS(Compras!$D:$D,Compras!$H:$H,"<=5",Compras!$A:$A,"<>")-SUMIF(Ambientes!$J:$J,"<=5",Ambientes!$H:$H) | D12: =IF($E$6=0,"",$D$6/$E$6) | E12: =$E$6-$F$6 | F12: =$F$6-$G$6 | G12: =SUMIF(Projetos!$H:$H,"<=5",Projetos!$B:$B)-SUMIF(Ambientes!$J:$J,"<=5",Ambientes!$C:$C)
B13: ==IF(SUMIF(Compras!$E:$E,"Mai",Compras!$D:$D)-SUMIFS(Compras!$D:$D,Compras!$E:$E,"Mai",Compras!$A:$A,"<>")=0,"tudo vinculado a projeto","dos quais "&TEXT(SUMIF(Compras!$E:$E,"Mai",Compras!$D:$D)-SUMIFS(Compras!$D:$D,Compras!$E:$E,"Mai",Compras!$A:$A,"<>"),"R$ #,##0")&" de uso geral") | C13: ="explica caixa curto com resultado bom" | D13: ="o termômetro da margem bruta" | E13: ="móvel pronto esperando obra" | F13: ="entregue e ainda sem nota" | G13: ="trabalho que a fábrica já tem contratado"
B15: ONDE ESTE MÊS ACONTECEU · por projeto
B16: Projeto | C16: Fabricado no mês | D16: Instalado no mês | E16: Material aplicado | F16: Faturado no mês | G16: Vendido no mês
B17: =IF(Projetos!$A4="","",Projetos!$A4) | C17: =IF($B17="","",SUMIFS(Ambientes!$C:$C,Ambientes!$A:$A,$B17,Ambientes!$D:$D,"Mai")) | D17: =IF($B17="","",SUMIFS(Ambientes!$C:$C,Ambientes!$A:$A,$B17,Ambientes!$E:$E,"Mai")) | E17: =IF($B17="","",SUMIFS(Ambientes!$H:$H,Ambientes!$A:$A,$B17,Ambientes!$D:$D,"Mai")) | F17: =IF($B17="","",SUMIFS(Faturamento!$C:$C,Faturamento!$A:$A,$B17,Faturamento!$D:$D,"Mai")) | G17: =IF($B17="","",SUMIFS(Projetos!$B:$B,Projetos!$A:$A,$B17,Projetos!$C:$C,"Mai"))
B18: =IF(Projetos!$A5="","",Projetos!$A5) | C18: =IF($B18="","",SUMIFS(Ambientes!$C:$C,Ambientes!$A:$A,$B18,Ambientes!$D:$D,"Mai")) | D18: =IF($B18="","",SUMIFS(Ambientes!$C:$C,Ambientes!$A:$A,$B18,Ambientes!$E:$E,"Mai")) | E18: =IF($B18="","",SUMIFS(Ambientes!$H:$H,Ambientes!$A:$A,$B18,Ambientes!$D:$D,"Mai")) | F18: =IF($B18="","",SUMIFS(Faturamento!$C:$C,Faturamento!$A:$A,$B18,Faturamento!$D:$D,"Mai")) | G18: =IF($B18="","",SUMIFS(Projetos!$B:$B,Projetos!$A:$A,$B18,Projetos!$C:$C,"Mai"))
B19: =IF(Projetos!$A6="","",Projetos!$A6) | C19: =IF($B19="","",SUMIFS(Ambientes!$C:$C,Ambientes!$A:$A,$B19,Ambientes!$D:$D,"Mai")) | D19: =IF($B19="","",SUMIFS(Ambientes!$C:$C,Ambientes!$A:$A,$B19,Ambientes!$E:$E,"Mai")) | E19: =IF($B19="","",SUMIFS(Ambientes!$H:$H,Ambientes!$A:$A,$B19,Ambientes!$D:$D,"Mai")) | F19: =IF($B19="","",SUMIFS(Faturamento!$C:$C,Faturamento!$A:$A,$B19,Faturamento!$D:$D,"Mai")) | G19: =IF($B19="","",SUMIFS(Projetos!$B:$B,Projetos!$A:$A,$B19,Projetos!$C:$C,"Mai"))
B20: =IF(Projetos!$A7="","",Projetos!$A7) | C20: =IF($B20="","",SUMIFS(Ambientes!$C:$C,Ambientes!$A:$A,$B20,Ambientes!$D:$D,"Mai")) | D20: =IF($B20="","",SUMIFS(Ambientes!$C:$C,Ambientes!$A:$A,$B20,Ambientes!$E:$E,"Mai")) | E20: =IF($B20="","",SUMIFS(Ambientes!$H:$H,Ambientes!$A:$A,$B20,Ambientes!$D:$D,"Mai")) | F20: =IF($B20="","",SUMIFS(Faturamento!$C:$C,Faturamento!$A:$A,$B20,Faturamento!$D:$D,"Mai")) | G20: =IF($B20="","",SUMIFS(Projetos!$B:$B,Projetos!$A:$A,$B20,Projetos!$C:$C,"Mai"))
B21: =IF(Projetos!$A8="","",Projetos!$A8) | C21: =IF($B21="","",SUMIFS(Ambientes!$C:$C,Ambientes!$A:$A,$B21,Ambientes!$D:$D,"Mai")) | D21: =IF($B21="","",SUMIFS(Ambientes!$C:$C,Ambientes!$A:$A,$B21,Ambientes!$E:$E,"Mai")) | E21: =IF($B21="","",SUMIFS(Ambientes!$H:$H,Ambientes!$A:$A,$B21,Ambientes!$D:$D,"Mai")) | F21: =IF($B21="","",SUMIFS(Faturamento!$C:$C,Faturamento!$A:$A,$B21,Faturamento!$D:$D,"Mai")) | G21: =IF($B21="","",SUMIFS(Projetos!$B:$B,Projetos!$A:$A,$B21,Projetos!$C:$C,"Mai"))
B22: =IF(Projetos!$A9="","",Projetos!$A9) | C22: =IF($B22="","",SUMIFS(Ambientes!$C:$C,Ambientes!$A:$A,$B22,Ambientes!$D:$D,"Mai")) | D22: =IF($B22="","",SUMIFS(Ambientes!$C:$C,Ambientes!$A:$A,$B22,Ambientes!$E:$E,"Mai")) | E22: =IF($B22="","",SUMIFS(Ambientes!$H:$H,Ambientes!$A:$A,$B22,Ambientes!$D:$D,"Mai")) | F22: =IF($B22="","",SUMIFS(Faturamento!$C:$C,Faturamento!$A:$A,$B22,Faturamento!$D:$D,"Mai")) | G22: =IF($B22="","",SUMIFS(Projetos!$B:$B,Projetos!$A:$A,$B22,Projetos!$C:$C,"Mai"))
B23: =IF(Projetos!$A10="","",Projetos!$A10) | C23: =IF($B23="","",SUMIFS(Ambientes!$C:$C,Ambientes!$A:$A,$B23,Ambientes!$D:$D,"Mai")) | D23: =IF($B23="","",SUMIFS(Ambientes!$C:$C,Ambientes!$A:$A,$B23,Ambientes!$E:$E,"Mai")) | E23: =IF($B23="","",SUMIFS(Ambientes!$H:$H,Ambientes!$A:$A,$B23,Ambientes!$D:$D,"Mai")) | F23: =IF($B23="","",SUMIFS(Faturamento!$C:$C,Faturamento!$A:$A,$B23,Faturamento!$D:$D,"Mai")) | G23: =IF($B23="","",SUMIFS(Projetos!$B:$B,Projetos!$A:$A,$B23,Projetos!$C:$C,"Mai"))
B24: =IF(Projetos!$A11="","",Projetos!$A11) | C24: =IF($B24="","",SUMIFS(Ambientes!$C:$C,Ambientes!$A:$A,$B24,Ambientes!$D:$D,"Mai")) | D24: =IF($B24="","",SUMIFS(Ambientes!$C:$C,Ambientes!$A:$A,$B24,Ambientes!$E:$E,"Mai")) | E24: =IF($B24="","",SUMIFS(Ambientes!$H:$H,Ambientes!$A:$A,$B24,Ambientes!$D:$D,"Mai")) | F24: =IF($B24="","",SUMIFS(Faturamento!$C:$C,Faturamento!$A:$A,$B24,Faturamento!$D:$D,"Mai")) | G24: =IF($B24="","",SUMIFS(Projetos!$B:$B,Projetos!$A:$A,$B24,Projetos!$C:$C,"Mai"))
B25: =IF(Projetos!$A12="","",Projetos!$A12) | C25: =IF($B25="","",SUMIFS(Ambientes!$C:$C,Ambientes!$A:$A,$B25,Ambientes!$D:$D,"Mai")) | D25: =IF($B25="","",SUMIFS(Ambientes!$C:$C,Ambientes!$A:$A,$B25,Ambientes!$E:$E,"Mai")) | E25: =IF($B25="","",SUMIFS(Ambientes!$H:$H,Ambientes!$A:$A,$B25,Ambientes!$D:$D,"Mai")) | F25: =IF($B25="","",SUMIFS(Faturamento!$C:$C,Faturamento!$A:$A,$B25,Faturamento!$D:$D,"Mai")) | G25: =IF($B25="","",SUMIFS(Projetos!$B:$B,Projetos!$A:$A,$B25,Projetos!$C:$C,"Mai"))
B26: =IF(Projetos!$A13="","",Projetos!$A13) | C26: =IF($B26="","",SUMIFS(Ambientes!$C:$C,Ambientes!$A:$A,$B26,Ambientes!$D:$D,"Mai")) | D26: =IF($B26="","",SUMIFS(Ambientes!$C:$C,Ambientes!$A:$A,$B26,Ambientes!$E:$E,"Mai")) | E26: =IF($B26="","",SUMIFS(Ambientes!$H:$H,Ambientes!$A:$A,$B26,Ambientes!$D:$D,"Mai")) | F26: =IF($B26="","",SUMIFS(Faturamento!$C:$C,Faturamento!$A:$A,$B26,Faturamento!$D:$D,"Mai")) | G26: =IF($B26="","",SUMIFS(Projetos!$B:$B,Projetos!$A:$A,$B26,Projetos!$C:$C,"Mai"))
B27: =IF(Projetos!$A14="","",Projetos!$A14) | C27: =IF($B27="","",SUMIFS(Ambientes!$C:$C,Ambientes!$A:$A,$B27,Ambientes!$D:$D,"Mai")) | D27: =IF($B27="","",SUMIFS(Ambientes!$C:$C,Ambientes!$A:$A,$B27,Ambientes!$E:$E,"Mai")) | E27: =IF($B27="","",SUMIFS(Ambientes!$H:$H,Ambientes!$A:$A,$B27,Ambientes!$D:$D,"Mai")) | F27: =IF($B27="","",SUMIFS(Faturamento!$C:$C,Faturamento!$A:$A,$B27,Faturamento!$D:$D,"Mai")) | G27: =IF($B27="","",SUMIFS(Projetos!$B:$B,Projetos!$A:$A,$B27,Projetos!$C:$C,"Mai"))
B28: =IF(Projetos!$A15="","",Projetos!$A15) | C28: =IF($B28="","",SUMIFS(Ambientes!$C:$C,Ambientes!$A:$A,$B28,Ambientes!$D:$D,"Mai")) | D28: =IF($B28="","",SUMIFS(Ambientes!$C:$C,Ambientes!$A:$A,$B28,Ambientes!$E:$E,"Mai")) | E28: =IF($B28="","",SUMIFS(Ambientes!$H:$H,Ambientes!$A:$A,$B28,Ambientes!$D:$D,"Mai")) | F28: =IF($B28="","",SUMIFS(Faturamento!$C:$C,Faturamento!$A:$A,$B28,Faturamento!$D:$D,"Mai")) | G28: =IF($B28="","",SUMIFS(Projetos!$B:$B,Projetos!$A:$A,$B28,Projetos!$C:$C,"Mai"))
