Workbook

Sheet Dashboard
A1: VALVIC MARCENARIA
A2: Vargas Decor Ltda · CNPJ 17.269.304/0001-51 · Belo Horizonte / MG
A3: PAINEL DE PATRIMÔNIO
A4: Números calculados automaticamente a partir da aba Patrimônio Geral
A6: POSIÇÃO PATRIMONIAL
B8: ITENS CADASTRADOS | F8: VALOR DE AQUISIÇÃO | J8: VALOR CONTÁBIL ATUAL
B9: =COUNTIF('Patrimônio Geral'!$A$7:$A$156,"?*") | F9: =SUM('Patrimônio Geral'!$K$7:$K$156) | J9: =SUM('Patrimônio Geral'!$P$7:$P$156)
B11: DEPRECIAÇÃO ACUMULADA | F11: ITENS CEDIDOS A COLABORADORES | J11: % DO VALOR JÁ DEPRECIADO
B12: =SUM('Patrimônio Geral'!$O$7:$O$156) | F12: =COUNTIF('Patrimônio Geral'!$S$7:$S$156,"?*") | J12: =IF(SUM('Patrimônio Geral'!$K$7:$K$156)=0,0,SUM('Patrimônio Geral'!$O$7:$O$156)/SUM('Patrimônio Geral'!$K$7:$K$156))
A14: TERMOS DE RESPONSABILIDADE
B16: TERMOS ASSINADOS | F16: ITENS CEDIDOS SEM TERMO | J16: ITENS EM MANUTENÇÃO OU EXTRAVIADOS
B17: =COUNTIF('Patrimônio Geral'!$W$7:$W$156,"Sim") | F17: =COUNTIFS('Patrimônio Geral'!$S$7:$S$156,"?*",'Patrimônio Geral'!$W$7:$W$156,"<>Sim") | J17: =COUNTIF('Patrimônio Geral'!$Q$7:$Q$156,"Em manutenção")+COUNTIF('Patrimônio Geral'!$Q$7:$Q$156,"Extraviado")
A19: DISTRIBUIÇÃO DO PATRIMÔNIO
B21: POR CATEGORIA | F21: POR RESPONSÁVEL | J21: POR SITUAÇÃO
C22: Itens | D22: Valor | G22: Itens | H22: Valor | K22: Itens | L22: Valor
B23: Máquina fixa | C23: =COUNTIF('Patrimônio Geral'!$B$7:$B$156,$B23) | D23: =SUMIF('Patrimônio Geral'!$B$7:$B$156,$B23,'Patrimônio Geral'!$K$7:$K$156) | F23: Deivson | G23: =COUNTIF('Patrimônio Geral'!$S$7:$S$156,$F23) | H23: =SUMIF('Patrimônio Geral'!$S$7:$S$156,$F23,'Patrimônio Geral'!$K$7:$K$156) | J23: Em uso | K23: =COUNTIF('Patrimônio Geral'!$Q$7:$Q$156,$J23) | L23: =SUMIF('Patrimônio Geral'!$Q$7:$Q$156,$J23,'Patrimônio Geral'!$K$7:$K$156)
B24: Ferramenta elétrica | C24: =COUNTIF('Patrimônio Geral'!$B$7:$B$156,$B24) | D24: =SUMIF('Patrimônio Geral'!$B$7:$B$156,$B24,'Patrimônio Geral'!$K$7:$K$156) | F24: Samuel | G24: =COUNTIF('Patrimônio Geral'!$S$7:$S$156,$F24) | H24: =SUMIF('Patrimônio Geral'!$S$7:$S$156,$F24,'Patrimônio Geral'!$K$7:$K$156) | J24: Em estoque | K24: =COUNTIF('Patrimônio Geral'!$Q$7:$Q$156,$J24) | L24: =SUMIF('Patrimônio Geral'!$Q$7:$Q$156,$J24,'Patrimônio Geral'!$K$7:$K$156)
B25: Ferramenta manual | C25: =COUNTIF('Patrimônio Geral'!$B$7:$B$156,$B25) | D25: =SUMIF('Patrimônio Geral'!$B$7:$B$156,$B25,'Patrimônio Geral'!$K$7:$K$156) | F25: Jackson | G25: =COUNTIF('Patrimônio Geral'!$S$7:$S$156,$F25) | H25: =SUMIF('Patrimônio Geral'!$S$7:$S$156,$F25,'Patrimônio Geral'!$K$7:$K$156) | J25: Em manutenção | K25: =COUNTIF('Patrimônio Geral'!$Q$7:$Q$156,$J25) | L25: =SUMIF('Patrimônio Geral'!$Q$7:$Q$156,$J25,'Patrimônio Geral'!$K$7:$K$156)
B26: Instrumento de medição | C26: =COUNTIF('Patrimônio Geral'!$B$7:$B$156,$B26) | D26: =SUMIF('Patrimônio Geral'!$B$7:$B$156,$B26,'Patrimônio Geral'!$K$7:$K$156) | F26: Cezar | G26: =COUNTIF('Patrimônio Geral'!$S$7:$S$156,$F26) | H26: =SUMIF('Patrimônio Geral'!$S$7:$S$156,$F26,'Patrimônio Geral'!$K$7:$K$156) | J26: Extraviado | K26: =COUNTIF('Patrimônio Geral'!$Q$7:$Q$156,$J26) | L26: =SUMIF('Patrimônio Geral'!$Q$7:$Q$156,$J26,'Patrimônio Geral'!$K$7:$K$156)
B27: Veículo | C27: =COUNTIF('Patrimônio Geral'!$B$7:$B$156,$B27) | D27: =SUMIF('Patrimônio Geral'!$B$7:$B$156,$B27,'Patrimônio Geral'!$K$7:$K$156) | F27: Jomar | G27: =COUNTIF('Patrimônio Geral'!$S$7:$S$156,$F27) | H27: =SUMIF('Patrimônio Geral'!$S$7:$S$156,$F27,'Patrimônio Geral'!$K$7:$K$156) | J27: Baixado | K27: =COUNTIF('Patrimônio Geral'!$Q$7:$Q$156,$J27) | L27: =SUMIF('Patrimônio Geral'!$Q$7:$Q$156,$J27,'Patrimônio Geral'!$K$7:$K$156)
B28: Informática | C28: =COUNTIF('Patrimônio Geral'!$B$7:$B$156,$B28) | D28: =SUMIF('Patrimônio Geral'!$B$7:$B$156,$B28,'Patrimônio Geral'!$K$7:$K$156) | F28: Davi | G28: =COUNTIF('Patrimônio Geral'!$S$7:$S$156,$F28) | H28: =SUMIF('Patrimônio Geral'!$S$7:$S$156,$F28,'Patrimônio Geral'!$K$7:$K$156)
B29: Mobiliário | C29: =COUNTIF('Patrimônio Geral'!$B$7:$B$156,$B29) | D29: =SUMIF('Patrimônio Geral'!$B$7:$B$156,$B29,'Patrimônio Geral'!$K$7:$K$156) | F29: Jonathan Godoy | G29: =COUNTIF('Patrimônio Geral'!$S$7:$S$156,$F29) | H29: =SUMIF('Patrimônio Geral'!$S$7:$S$156,$F29,'Patrimônio Geral'!$K$7:$K$156)
B30: Infraestrutura | C30: =COUNTIF('Patrimônio Geral'!$B$7:$B$156,$B30) | D30: =SUMIF('Patrimônio Geral'!$B$7:$B$156,$B30,'Patrimônio Geral'!$K$7:$K$156) | F30: Joelson | G30: =COUNTIF('Patrimônio Geral'!$S$7:$S$156,$F30) | H30: =SUMIF('Patrimônio Geral'!$S$7:$S$156,$F30,'Patrimônio Geral'!$K$7:$K$156)
B31: Total | C31: =SUM(C23:C30) | D31: =SUM(D23:D30) | F31: Total | G31: =SUM(G23:G30) | H31: =SUM(H23:H30) | J31: Total | K31: =SUM(K23:K27) | L31: =SUM(L23:L27)
A33: ITENS POR MODELO PADRÃO unidades idênticas agrupadas pelo SKU
B35: MODELO PADRÃO | F35: Unidades | G35: Cedidas | H35: Disponíveis | I35: Valor total
B36: PARAF-MAK-DHP482 | F36: =COUNTIF('Patrimônio Geral'!$F$7:$F$156,$B36) | G36: =COUNTIFS('Patrimônio Geral'!$F$7:$F$156,$B36,'Patrimônio Geral'!$S$7:$S$156,"?*") | H36: =$F36-$G36 | I36: =SUMIF('Patrimônio Geral'!$F$7:$F$156,$B36,'Patrimônio Geral'!$K$7:$K$156)
B37: SERRA-BOS-GKS150 | F37: =COUNTIF('Patrimônio Geral'!$F$7:$F$156,$B37) | G37: =COUNTIFS('Patrimônio Geral'!$F$7:$F$156,$B37,'Patrimônio Geral'!$S$7:$S$156,"?*") | H37: =$F37-$G37 | I37: =SUMIF('Patrimônio Geral'!$F$7:$F$156,$B37,'Patrimônio Geral'!$K$7:$K$156)
B38: TUPIA-MAK-RT0700C | F38: =COUNTIF('Patrimônio Geral'!$F$7:$F$156,$B38) | G38: =COUNTIFS('Patrimônio Geral'!$F$7:$F$156,$B38,'Patrimônio Geral'!$S$7:$S$156,"?*") | H38: =$F38-$G38 | I38: =SUMIF('Patrimônio Geral'!$F$7:$F$156,$B38,'Patrimônio Geral'!$K$7:$K$156)
B39: LIXA-BOS-GSS140 | F39: =COUNTIF('Patrimônio Geral'!$F$7:$F$156,$B39) | G39: =COUNTIFS('Patrimônio Geral'!$F$7:$F$156,$B39,'Patrimônio Geral'!$S$7:$S$156,"?*") | H39: =$F39-$G39 | I39: =SUMIF('Patrimônio Geral'!$F$7:$F$156,$B39,'Patrimônio Geral'!$K$7:$K$156)
B40: FORMAO-TRA-4P | F40: =COUNTIF('Patrimônio Geral'!$F$7:$F$156,$B40) | G40: =COUNTIFS('Patrimônio Geral'!$F$7:$F$156,$B40,'Patrimônio Geral'!$S$7:$S$156,"?*") | H40: =$F40-$G40 | I40: =SUMIF('Patrimônio Geral'!$F$7:$F$156,$B40,'Patrimônio Geral'!$K$7:$K$156)
B41: MARTELO-TRA-27 | F41: =COUNTIF('Patrimônio Geral'!$F$7:$F$156,$B41) | G41: =COUNTIFS('Patrimônio Geral'!$F$7:$F$156,$B41,'Patrimônio Geral'!$S$7:$S$156,"?*") | H41: =$F41-$G41 | I41: =SUMIF('Patrimônio Geral'!$F$7:$F$156,$B41,'Patrimônio Geral'!$K$7:$K$156)
B42: CHAVES-GED-6P | F42: =COUNTIF('Patrimônio Geral'!$F$7:$F$156,$B42) | G42: =COUNTIFS('Patrimônio Geral'!$F$7:$F$156,$B42,'Patrimônio Geral'!$S$7:$S$156,"?*") | H42: =$F42-$G42 | I42: =SUMIF('Patrimônio Geral'!$F$7:$F$156,$B42,'Patrimônio Geral'!$K$7:$K$156)
B43: SARGENTO-VON-300 | F43: =COUNTIF('Patrimônio Geral'!$F$7:$F$156,$B43) | G43: =COUNTIFS('Patrimônio Geral'!$F$7:$F$156,$B43,'Patrimônio Geral'!$S$7:$S$156,"?*") | H43: =$F43-$G43 | I43: =SUMIF('Patrimônio Geral'!$F$7:$F$156,$B43,'Patrimônio Geral'!$K$7:$K$156)
B44: TRENA-STA-5M | F44: =COUNTIF('Patrimônio Geral'!$F$7:$F$156,$B44) | G44: =COUNTIFS('Patrimônio Geral'!$F$7:$F$156,$B44,'Patrimônio Geral'!$S$7:$S$156,"?*") | H44: =$F44-$G44 | I44: =SUMIF('Patrimônio Geral'!$F$7:$F$156,$B44,'Patrimônio Geral'!$K$7:$K$156)
B45: ESQUADRO-STA-300 | F45: =COUNTIF('Patrimônio Geral'!$F$7:$F$156,$B45) | G45: =COUNTIFS('Patrimônio Geral'!$F$7:$F$156,$B45,'Patrimônio Geral'!$S$7:$S$156,"?*") | H45: =$F45-$G45 | I45: =SUMIF('Patrimônio Geral'!$F$7:$F$156,$B45,'Patrimônio Geral'!$K$7:$K$156)
B46: LASER-BOS-GLL210 | F46: =COUNTIF('Patrimônio Geral'!$F$7:$F$156,$B46) | G46: =COUNTIFS('Patrimônio Geral'!$F$7:$F$156,$B46,'Patrimônio Geral'!$S$7:$S$156,"?*") | H46: =$F46-$G46 | I46: =SUMIF('Patrimônio Geral'!$F$7:$F$156,$B46,'Patrimônio Geral'!$K$7:$K$156)
B47: MALETA-TRA-ORG | F47: =COUNTIF('Patrimônio Geral'!$F$7:$F$156,$B47) | G47: =COUNTIFS('Patrimônio Geral'!$F$7:$F$156,$B47,'Patrimônio Geral'!$S$7:$S$156,"?*") | H47: =$F47-$G47 | I47: =SUMIF('Patrimônio Geral'!$F$7:$F$156,$B47,'Patrimônio Geral'!$K$7:$K$156)
B48: Total do kit de referência | F48: =SUM(F36:F47) | G48: =SUM(G36:G47) | H48: =SUM(H36:H47) | I48: =SUM(I36:I47)
A50: COMO ESTE PAINEL FUNCIONA
...

Sheet Patrimônio Geral
A1: VALVIC MARCENARIA
A2: Vargas Decor Ltda · CNPJ 17.269.304/0001-51 · Belo Horizonte / MG
A3: CONTROLE DE PATRIMÔNIO
A4: Cadastro único de todos os bens da empresa · preencha apenas as células de fundo creme
A6: Código | B6: Categoria | C6: Descrição completa do item | D6: Marca | E6: Modelo | F6: Modelo padrão (SKU) | G6: Código de etiqueta / nº de série | H6: Data de aquisição | I6: Fornecedor | J6: Nota fiscal | K6: Valor de aquisição | L6: Vida útil (anos) | M6: Taxa deprec. (% a.a.) | N6: Meses de uso | O6: Depreciação acumulada | P6: Valor contábil atual | Q6: Situação | R6: Localização | S6: Responsável | T6: Vínculo | U6: Estado na entrega | V6: Data de entrega | W6: Termo assinado | X6: Observações
A7: VLV-0001 | B7: Máquina fixa | C7: Centro de usinagem CNC Raizen Solid TAF · 380V · 3 eixos | D7: Raizen | E7: Solid TAF | L7: 10 | M7: =IFERROR(INDEX(Listas!$G$14:$G$21,MATCH($B7,Listas!$F$14:$F$21,0)),"") | N7: =IF(OR($H7="",$L7=""),"",MIN($L7*12,MAX(0,DATEDIF($H7,Listas!$N$2,"m")))) | O7: =IF(OR($K7="",$N7=""),"",MIN($K7,ROUND($K7*($M7/12)*$N7,2))) | P7: =IF($K7="","",$K7-IF($O7="",0,$O7)) | Q7: Em uso | R7: Fábrica | T7: =IFERROR(INDEX(Listas!$B$2:$B$40,MATCH($S7,Listas!$A$2:$A$40,0)),"")
A8: VLV-0002 | B8: Máquina fixa | C8: Coladeira de bordas SCM Minimax ME 25 · fita 0,4 mm · cola EVA | D8: SCM | E8: Minimax ME 25 | L8: 10 | M8: =IFERROR(INDEX(Listas!$G$14:$G$21,MATCH($B8,Listas!$F$14:$F$21,0)),"") | N8: =IF(OR($H8="",$L8=""),"",MIN($L8*12,MAX(0,DATEDIF($H8,Listas!$N$2,"m")))) | O8: =IF(OR($K8="",$N8=""),"",MIN($K8,ROUND($K8*($M8/12)*$N8,2))) | P8: =IF($K8="","",$K8-IF($O8="",0,$O8)) | Q8: Em uso | R8: Fábrica | T8: =IFERROR(INDEX(Listas!$B$2:$B$40,MATCH($S8,Listas!$A$2:$A$40,0)),"")
A9: VLV-0003 | B9: Máquina fixa | C9: Esquadrejadeira Raizen RZN 3200P | D9: Raizen | E9: RZN 3200P | L9: 10 | M9: =IFERROR(INDEX(Listas!$G$14:$G$21,MATCH($B9,Listas!$F$14:$F$21,0)),"") | N9: =IF(OR($H9="",$L9=""),"",MIN($L9*12,MAX(0,DATEDIF($H9,Listas!$N$2,"m")))) | O9: =IF(OR($K9="",$N9=""),"",MIN($K9,ROUND($K9*($M9/12)*$N9,2))) | P9: =IF($K9="","",$K9-IF($O9="",0,$O9)) | Q9: Em uso | R9: Fábrica | T9: =IFERROR(INDEX(Listas!$B$2:$B$40,MATCH($S9,Listas!$A$2:$A$40,0)),"")
A10: VLV-0004 | B10: Máquina fixa | C10: Compressor de ar | L10: 10 | M10: =IFERROR(INDEX(Listas!$G$14:$G$21,MATCH($B10,Listas!$F$14:$F$21,0)),"") | N10: =IF(OR($H10="",$L10=""),"",MIN($L10*12,MAX(0,DATEDIF($H10,Listas!$N$2,"m")))) | O10: =IF(OR($K10="",$N10=""),"",MIN($K10,ROUND($K10*($M10/12)*$N10,2))) | P10: =IF($K10="","",$K10-IF($O10="",0,$O10)) | Q10: Em uso | R10: Fábrica | T10: =IFERROR(INDEX(Listas!$B$2:$B$40,MATCH($S10,Listas!$A$2:$A$40,0)),"")
A11: VLV-0005 | B11: Máquina fixa | C11: Coletor de pó / exaustão | L11: 10 | M11: =IFERROR(INDEX(Listas!$G$14:$G$21,MATCH($B11,Listas!$F$14:$F$21,0)),"") | N11: =IF(OR($H11="",$L11=""),"",MIN($L11*12,MAX(0,DATEDIF($H11,Listas!$N$2,"m")))) | O11: =IF(OR($K11="",$N11=""),"",MIN($K11,ROUND($K11*($M11/12)*$N11,2))) | P11: =IF($K11="","",$K11-IF($O11="",0,$O11)) | Q11: Em uso | R11: Fábrica | T11: =IFERROR(INDEX(Listas!$B$2:$B$40,MATCH($S11,Listas!$A$2:$A$40,0)),"")
A12: VLV-0006 | B12: Veículo | C12: Chevrolet Montana 2020 · placa QUY4166 | D12: Chevrolet | E12: Montana 2020 | L12: 5 | M12: =IFERROR(INDEX(Listas!$G$14:$G$21,MATCH($B12,Listas!$F$14:$F$21,0)),"") | N12: =IF(OR($H12="",$L12=""),"",MIN($L12*12,MAX(0,DATEDIF($H12,Listas!$N$2,"m")))) | O12: =IF(OR($K12="",$N12=""),"",MIN($K12,ROUND($K12*($M12/12)*$N12,2))) | P12: =IF($K12="","",$K12-IF($O12="",0,$O12)) | Q12: Em uso | R12: Fábrica | T12: =IFERROR(INDEX(Listas!$B$2:$B$40,MATCH($S12,Listas!$A$2:$A$40,0)),"")
A13: VLV-0007 | B13: Informática | C13: Computador de escritório | L13: 5 | M13: =IFERROR(INDEX(Listas!$G$14:$G$21,MATCH($B13,Listas!$F$14:$F$21,0)),"") | N13: =IF(OR($H13="",$L13=""),"",MIN($L13*12,MAX(0,DATEDIF($H13,Listas!$N$2,"m")))) | O13: =IF(OR($K13="",$N13=""),"",MIN($K13,ROUND($K13*($M13/12)*$N13,2))) | P13: =IF($K13="","",$K13-IF($O13="",0,$O13)) | Q13: Em uso | R13: Fábrica | T13: =IFERROR(INDEX(Listas!$B$2:$B$40,MATCH($S13,Listas!$A$2:$A$40,0)),"")
A14: VLV-0008 | B14: Informática | C14: Tablet do chão de fábrica | L14: 5 | M14: =IFERROR(INDEX(Listas!$G$14:$G$21,MATCH($B14,Listas!$F$14:$F$21,0)),"") | N14: =IF(OR($H14="",$L14=""),"",MIN($L14*12,MAX(0,DATEDIF($H14,Listas!$N$2,"m")))) | O14: =IF(OR($K14="",$N14=""),"",MIN($K14,ROUND($K14*($M14/12)*$N14,2))) | P14: =IF($K14="","",$K14-IF($O14="",0,$O14)) | Q14: Em uso | R14: Fábrica | T14: =IFERROR(INDEX(Listas!$B$2:$B$40,MATCH($S14,Listas!$A$2:$A$40,0)),"")
A15: VLV-0009 | B15: Ferramenta elétrica | C15: Furador de coluna | L15: 10 | M15: =IFERROR(INDEX(Listas!$G$14:$G$21,MATCH($B15,Listas!$F$14:$F$21,0)),"") | N15: =IF(OR($H15="",$L15=""),"",MIN($L15*12,MAX(0,DATEDIF($H15,Listas!$N$2,"m")))) | O15: =IF(OR($K15="",$N15=""),"",MIN($K15,ROUND($K15*($M15/12)*$N15,2))) | P15: =IF($K15="","",$K15-IF($O15="",0,$O15)) | Q15: Em uso | R15: Fábrica | T15: =IFERROR(INDEX(Listas!$B$2:$B$40,MATCH($S15,Listas!$A$2:$A$40,0)),"")
A16: VLV-0010 | B16: Ferramenta elétrica | C16: Etiquetadora | L16: 10 | M16: =IFERROR(INDEX(Listas!$G$14:$G$21,MATCH($B16,Listas!$F$14:$F$21,0)),"") | N16: =IF(OR($H16="",$L16=""),"",MIN($L16*12,MAX(0,DATEDIF($H16,Listas!$N$2,"m")))) | O16: =IF(OR($K16="",$N16=""),"",MIN($K16,ROUND($K16*($M16/12)*$N16,2))) | P16: =IF($K16="","",$K16-IF($O16="",0,$O16)) | Q16: Em uso | R16: Fábrica | T16: =IFERROR(INDEX(Listas!$B$2:$B$40,MATCH($S16,Listas!$A$2:$A$40,0)),"")
A17: VLV-0011 | B17: Ferramenta elétrica | C17: Parafusadeira / furadeira de impacto a bateria 18V com 2 baterias | D17: Makita | E17: DHP482 | F17: PARAF-MAK-DHP482 | K17: 890 | L17: 5 | M17: =IFERROR(INDEX(Listas!$G$14:$G$21,MATCH($B17,Listas!$F$14:$F$21,0)),"") | N17: =IF(OR($H17="",$L17=""),"",MIN($L17*12,MAX(0,DATEDIF($H17,Listas!$N$2,"m")))) | O17: =IF(OR($K17="",$N17=""),"",MIN($K17,ROUND($K17*($M17/12)*$N17,2))) | P17: =IF($K17="","",$K17-IF($O17="",0,$O17)) | Q17: Em estoque | R17: Fábrica | T17: =IFERROR(INDEX(Listas!$B$2:$B$40,MATCH($S17,Listas!$A$2:$A$40,0)),"")
A18: VLV-0012 | B18: Ferramenta elétrica | C18: Serra circular manual 7.1/4" | D18: Bosch | E18: GKS 150 | F18: SERRA-BOS-GKS150 | K18: 690 | L18: 5 | M18: =IFERROR(INDEX(Listas!$G$14:$G$21,MATCH($B18,Listas!$F$14:$F$21,0)),"") | N18: =IF(OR($H18="",$L18=""),"",MIN($L18*12,MAX(0,DATEDIF($H18,Listas!$N$2,"m")))) | O18: =IF(OR($K18="",$N18=""),"",MIN($K18,ROUND($K18*($M18/12)*$N18,2))) | P18: =IF($K18="","",$K18-IF($O18="",0,$O18)) | Q18: Em estoque | R18: Fábrica | T18: =IFERROR(INDEX(Listas!$B$2:$B$40,MATCH($S18,Listas!$A$2:$A$40,0)),"")
A19: VLV-0013 | B19: Ferramenta elétrica | C19: Tupia manual 1/4" | D19: Makita | E19: RT0700C | F19: TUPIA-MAK-RT0700C | K19: 780 | L19: 5 | M19: =IFERROR(INDEX(Listas!$G$14:$G$21,MATCH($B19,Listas!$F$14:$F$21,0)),"") | N19: =IF(OR($H19="",$L19=""),"",MIN($L19*12,MAX(0,DATEDIF($H19,Listas!$N$2,"m")))) | O19: =IF(OR($K19="",$N19=""),"",MIN($K19,ROUND($K19*($M19/12)*$N19,2))) | P19: =IF($K19="","",$K19-IF($O19="",0,$O19)) | Q19: Em estoque | R19: Fábrica | T19: =IFERROR(INDEX(Listas!$B$2:$B$40,MATCH($S19,Listas!$A$2:$A$40,0)),"")
A20: VLV-0014 | B20: Ferramenta elétrica | C20: Lixadeira orbital 1/4 de folha | D20: Bosch | E20: GSS 140 | F20: LIXA-BOS-GSS140 | K20: 380 | L20: 5 | M20: =IFERROR(INDEX(Listas!$G$14:$G$21,MATCH($B20,Listas!$F$14:$F$21,0)),"") | N20: =IF(OR($H20="",$L20=""),"",MIN($L20*12,MAX(0,DATEDIF($H20,Listas!$N$2,"m")))) | O20: =IF(OR($K20="",$N20=""),"",MIN($K20,ROUND($K20*($M20/12)*$N20,2))) | P20: =IF($K20="","",$K20-IF($O20="",0,$O20)) | Q20: Em estoque | R20: Fábrica | T20: =IFERROR(INDEX(Listas!$B$2:$B$40,MATCH($S20,Listas!$A$2:$A$40,0)),"")
A21: VLV-0015 | B21: Ferramenta manual | C21: Jogo de formões 4 peças | D21: Tramontina | F21: FORMAO-TRA-4P | K21: 180 | L21: 10 | M21: =IFERROR(INDEX(Listas!$G$14:$G$21,MATCH($B21,Listas!$F$14:$F$21,0)),"") | N21: =IF(OR($H21="",$L21=""),"",MIN($L21*12,MAX(0,DATEDIF($H21,Listas!$N$2,"m")))) | O21: =IF(OR($K21="",$N21=""),"",MIN($K21,ROUND($K21*($M21/12)*$N21,2))) | P21: =IF($K21="","",$K21-IF($O21="",0,$O21)) | Q21: Em estoque | R21: Fábrica | T21: =IFERROR(INDEX(Listas!$B$2:$B$40,MATCH($S21,Listas!$A$2:$A$40,0)),"")
A22: VLV-0016 | B22: Ferramenta manual | C22: Martelo unha 27 mm cabo de fibra | D22: Tramontina | F22: MARTELO-TRA-27 | K22: 75 | L22: 10 | M22: =IFERROR(INDEX(Listas!$G$14:$G$21,MATCH($B22,Listas!$F$14:$F$21,0)),"") | N22: =IF(OR($H22="",$L22=""),"",MIN($L22*12,MAX(0,DATEDIF($H22,Listas!$N$2,"m")))) | O22: =IF(OR($K22="",$N22=""),"",MIN($K22,ROUND($K22*($M22/12)*$N22,2))) | P22: =IF($K22="","",$K22-IF($O22="",0,$O22)) | Q22: Em estoque | R22: Fábrica | T22: =IFERROR(INDEX(Listas!$B$2:$B$40,MATCH($S22,Listas!$A$2:$A$40,0)),"")
A23: VLV-0017 | B23: Ferramenta manual | C23: Jogo de chaves de fenda e philips 6 peças | D23: Gedore | F23: CHAVES-GED-6P | K23: 130 | L23: 10 | M23: =IFERROR(INDEX(Listas!$G$14:$G$21,MATCH($B23,Listas!$F$14:$F$21,0)),"") | N23: =IF(OR($H23="",$L23=""),"",MIN($L23*12,MAX(0,DATEDIF($H23,Listas!$N$2,"m")))) | O23: =IF(OR($K23="",$N23=""),"",MIN($K23,ROUND($K23*($M23/12)*$N23,2))) | P23: =IF($K23="","",$K23-IF($O23="",0,$O23)) | Q23: Em estoque | R23: Fábrica | T23: =IFERROR(INDEX(Listas!$B$2:$B$40,MATCH($S23,Listas!$A$2:$A$40,0)),"")
A24: VLV-0018 | B24: Ferramenta manual | C24: Grampo sargento 300 mm — par | D24: Vonder | F24: SARGENTO-VON-300 | K24: 160 | L24: 10 | M24: =IFERROR(INDEX(Listas!$G$14:$G$21,MATCH($B24,Listas!$F$14:$F$21,0)),"") | N24: =IF(OR($H24="",$L24=""),"",MIN($L24*12,MAX(0,DATEDIF($H24,Listas!$N$2,"m")))) | O24: =IF(OR($K24="",$N24=""),"",MIN($K24,ROUND($K24*($M24/12)*$N24,2))) | P24: =IF($K24="","",$K24-IF($O24="",0,$O24)) | Q24: Em estoque | R24: Fábrica | T24: =IFERROR(INDEX(Listas!$B$2:$B$40,MATCH($S24,Listas!$A$2:$A$40,0)),"")
A25: VLV-0019 | B25: Instrumento de medição | C25: Trena 5 m | D25: Starrett | F25: TRENA-STA-5M | K25: 55 | L25: 5 | M25: =IFERROR(INDEX(Listas!$G$14:$G$21,MATCH($B25,Listas!$F$14:$F$21,0)),"") | N25: =IF(OR($H25="",$L25=""),"",MIN($L25*12,MAX(0,DATEDIF($H25,Listas!$N$2,"m")))) | O25: =IF(OR($K25="",$N25=""),"",MIN($K25,ROUND($K25*($M25/12)*$N25,2))) | P25: =IF($K25="","",$K25-IF($O25="",0,$O25)) | Q25: Em estoque | R25: Fábrica | T25: =IFERROR(INDEX(Listas!$B$2:$B$40,MATCH($S25,Listas!$A$2:$A$40,0)),"")
A26: VLV-0020 | B26: Instrumento de medição | C26: Esquadro de precisão 300 mm | D26: Starrett | F26: ESQUADRO-STA-300 | K26: 120 | L26: 10 | M26: =IFERROR(INDEX(Listas!$G$14:$G$21,MATCH($B26,Listas!$F$14:$F$21,0)),"") | N26: =IF(OR($H26="",$L26=""),"",MIN($L26*12,MAX(0,DATEDIF($H26,Listas!$N$2,"m")))) | O26: =IF(OR($K26="",$N26=""),"",MIN($K26,ROUND($K26*($M26/12)*$N26,2))) | P26: =IF($K26="","",$K26-IF($O26="",0,$O26)) | Q26: Em estoque | R26: Fábrica | T26: =IFERROR(INDEX(Listas!$B$2:$B$40,MATCH($S26,Listas!$A$2:$A$40,0)),"")
A27: VLV-0021 | B27: Instrumento de medição | C27: Nível a laser de linha | D27: Bosch | E27: GLL 2-10 | F27: LASER-BOS-GLL210 | K27: 520 | L27: 5 | M27: =IFERROR(INDEX(Listas!$G$14:$G$21,MATCH($B27,Listas!$F$14:$F$21,0)),"") | N27: =IF(OR($H27="",$L27=""),"",MIN($L27*12,MAX(0,DATEDIF($H27,Listas!$N$2,"m")))) | O27: =IF(OR($K27="",$N27=""),"",MIN($K27,ROUND($K27*($M27/12)*$N27,2))) | P27: =IF($K27="","",$K27-IF($O27="",0,$O27)) | Q27: Em estoque | R27: Fábrica | T27: =IFERROR(INDEX(Listas!$B$2:$B$40,MATCH($S27,Listas!$A$2:$A$40,0)),"")
A28: VLV-0022 | B28: Ferramenta manual | C28: Maleta / caixa organizadora de ferramentas | D28: Tramontina | F28: MALETA-TRA-ORG | K28: 210 | L28: 5 | M28: =IFERROR(INDEX(Listas!$G$14:$G$21,MATCH($B28,Listas!$F$14:$F$21,0)),"") | N28: =IF(OR($H28="",$L28=""),"",MIN($L28*12,MAX(0,DATEDIF($H28,Listas!$N$2,"m")))) | O28: =IF(OR($K28="",$N28=""),"",MIN($K28,ROUND($K28*($M28/12)*$N28,2))) | P28: =IF($K28="","",$K28-IF($O28="",0,$O28)) | Q28: Em estoque | R28: Fábrica | T28: =IFERROR(INDEX(Listas!$B$2:$B$40,MATCH($S28,Listas!$A$2:$A$40,0)),"")
M29: =IFERROR(INDEX(Listas!$G$14:$G$21,MATCH($B29,Listas!$F$14:$F$21,0)),"") | N29: =IF(OR($H29="",$L29=""),"",MIN($L29*12,MAX(0,DATEDIF($H29,Listas!$N$2,"m")))) | O29: =IF(OR($K29="",$N29=""),"",MIN($K29,ROUND($K29*($M29/12)*$N29,2))) | P29: =IF($K29="","",$K29-IF($O29="",0,$O29)) | T29: =IFERROR(INDEX(Listas!$B$2:$B$40,MATCH($S29,Listas!$A$2:$A$40,0)),"")
M30: =IFERROR(INDEX(Listas!$G$14:$G$21,MATCH($B30,Listas!$F$14:$F$21,0)),"") | N30: =IF(OR($H30="",$L30=""),"",MIN($L30*12,MAX(0,DATEDIF($H30,Listas!$N$2,"m")))) | O30: =IF(OR($K30="",$N30=""),"",MIN($K30,ROUND($K30*($M30/12)*$N30,2))) | P30: =IF($K30="","",$K30-IF($O30="",0,$O30)) | T30: =IFERROR(INDEX(Listas!$B$2:$B$40,MATCH($S30,Listas!$A$2:$A$40,0)),"")
M31: =IFERROR(INDEX(Listas!$G$14:$G$21,MATCH($B31,Listas!$F$14:$F$21,0)),"") | N31: =IF(OR($H31="",$L31=""),"",MIN($L31*12,MAX(0,DATEDIF($H31,Listas!$N$2,"m")))) | O31: =IF(OR($K31="",$N31=""),"",MIN($K31,ROUND($K31*($M31/12)*$N31,2))) | P31: =IF($K31="","",$K31-IF($O31="",0,$O31)) | T31: =IFERROR(INDEX(Listas!$B$2:$B$40,MATCH($S31,Listas!$A$2:$A$40,0)),"")
M32: =IFERROR(INDEX(Listas!$G$14:$G$21,MATCH($B32,Listas!$F$14:$F$21,0)),"") | N32: =IF(OR($H32="",$L32=""),"",MIN($L32*12,MAX(0,DATEDIF($H32,Listas!$N$2,"m")))) | O32: =IF(OR($K32="",$N32=""),"",MIN($K32,ROUND($K32*($M32/12)*$N32,2))) | P32: =IF($K32="","",$K32-IF($O32="",0,$O32)) | T32: =IFERROR(INDEX(Listas!$B$2:$B$40,MATCH($S32,Listas!$A$2:$A$40,0)),"")
M33: =IFERROR(INDEX(Listas!$G$14:$G$21,MATCH($B33,Listas!$F$14:$F$21,0)),"") | N33: =IF(OR($H33="",$L33=""),"",MIN($L33*12,MAX(0,DATEDIF($H33,Listas!$N$2,"m")))) | O33: =IF(OR($K33="",$N33=""),"",MIN($K33,ROUND($K33*($M33/12)*$N33,2))) | P33: =IF($K33="","",$K33-IF($O33="",0,$O33)) | T33: =IFERROR(INDEX(Listas!$B$2:$B$40,MATCH($S33,Listas!$A$2:$A$40,0)),"")
M34: =IFERROR(INDEX(Listas!$G$14:$G$21,MATCH($B34,Listas!$F$14:$F$21,0)),"") | N34: =IF(OR($H34="",$L34=""),"",MIN($L34*12,MAX(0,DATEDIF($H34,Listas!$N$2,"m")))) | O34: =IF(OR($K34="",$N34=""),"",MIN($K34,ROUND($K34*($M34/12)*$N34,2))) | P34: =IF($K34="","",$K34-IF($O34="",0,$O34)) | T34: =IFERROR(INDEX(Listas!$B$2:$B$40,MATCH($S34,Listas!$A$2:$A$40,0)),"")
M35: =IFERROR(INDEX(Listas!$G$14:$G$21,MATCH($B35,Listas!$F$14:$F$21,0)),"") | N35: =IF(OR($H35="",$L35=""),"",MIN($L35*12,MAX(0,DATEDIF($H35,Listas!$N$2,"m")))) | O35: =IF(OR($K35="",$N35=""),"",MIN($K35,ROUND($K35*($M35/12)*$N35,2))) | P35: =IF($K35="","",$K35-IF($O35="",0,$O35)) | T35: =IFERROR(INDEX(Listas!$B$2:$B$40,MATCH($S35,Listas!$A$2:$A$40,0)),"")
M36: =IFERROR(INDEX(Listas!$G$14:$G$21,MATCH($B36,Listas!$F$14:$F$21,0)),"") | N36: =IF(OR($H36="",$L36=""),"",MIN($L36*12,MAX(0,DATEDIF($H36,Listas!$N$2,"m")))) | O36: =IF(OR($K36="",$N36=""),"",MIN($K36,ROUND($K36*($M36/12)*$N36,2))) | P36: =IF($K36="","",$K36-IF($O36="",0,$O36)) | T36: =IFERROR(INDEX(Listas!$B$2:$B$40,MATCH($S36,Listas!$A$2:$A$40,0)),"")
M37: =IFERROR(INDEX(Listas!$G$14:$G$21,MATCH($B37,Listas!$F$14:$F$21,0)),"") | N37: =IF(OR($H37="",$L37=""),"",MIN($L37*12,MAX(0,DATEDIF($H37,Listas!$N$2,"m")))) | O37: =IF(OR($K37="",$N37=""),"",MIN($K37,ROUND($K37*($M37/12)*$N37,2))) | P37: =IF($K37="","",$K37-IF($O37="",0,$O37)) | T37: =IFERROR(INDEX(Listas!$B$2:$B$40,MATCH($S37,Listas!$A$2:$A$40,0)),"")
M38: =IFERROR(INDEX(Listas!$G$14:$G$21,MATCH($B38,Listas!$F$14:$F$21,0)),"") | N38: =IF(OR($H38="",$L38=""),"",MIN($L38*12,MAX(0,DATEDIF($H38,Listas!$N$2,"m")))) | O38: =IF(OR($K38="",$N38=""),"",MIN($K38,ROUND($K38*($M38/12)*$N38,2))) | P38: =IF($K38="","",$K38-IF($O38="",0,$O38)) | T38: =IFERROR(INDEX(Listas!$B$2:$B$40,MATCH($S38,Listas!$A$2:$A$40,0)),"")
M39: =IFERROR(INDEX(Listas!$G$14:$G$21,MATCH($B39,Listas!$F$14:$F$21,0)),"") | N39: =IF(OR($H39="",$L39=""),"",MIN($L39*12,MAX(0,DATEDIF($H39,Listas!$N$2,"m")))) | O39: =IF(OR($K39="",$N39=""),"",MIN($K39,ROUND($K39*($M39/12)*$N39,2))) | P39: =IF($K39="","",$K39-IF($O39="",0,$O39)) | T39: =IFERROR(INDEX(Listas!$B$2:$B$40,MATCH($S39,Listas!$A$2:$A$40,0)),"")
M40: =IFERROR(INDEX(Listas!$G$14:$G$21,MATCH($B40,Listas!$F$14:$F$21,0)),"") | N40: =IF(OR($H40="",$L40=""),"",MIN($L40*12,MAX(0,DATEDIF($H40,Listas!$N$2,"m")))) | O40: =IF(OR($K40="",$N40=""),"",MIN($K40,ROUND($K40*($M40/12)*$N40,2))) | P40: =IF($K40="","",$K40-IF($O40="",0,$O40)) | T40: =IFERROR(INDEX(Listas!$B$2:$B$40,MATCH($S40,Listas!$A$2:$A$40,0)),"")
... M156: =IFERROR(INDEX(Listas!$G$14:$G$21,MATCH($B156,Listas!$F$14:$F$21,0)),"") | N156: =IF(OR($H156="",$L156=""),"",MIN($L156*12,MAX(0,DATEDIF($H156,Listas!$N$2,"m")))) | O156: =IF(OR($K156="",$N156=""),"",MIN($K156,ROUND($K156*($M156/12)*$N156,2))) | P156: =IF($K156="","",$K156-IF($O156="",0,$O156)) | T156: =IFERROR(INDEX(Listas!$B$2:$B$40,MATCH($S156,Listas!$A$2:$A$40,0)),"")
...

Sheet Kit Padrão
A1: VALVIC MARCENARIA
A2: Vargas Decor Ltda · CNPJ 17.269.304/0001-51 · Belo Horizonte / MG
A3: KIT PADRÃO
A4: O que compõe um kit completo · e quantos kits o estoque atual permite montar
A6: Modelo padrão (SKU) | B6: Item | C6: Categoria | D6: Qtd por kit | E6: Valor unitário | F6: Valor por kit | G6: Unidades cadastradas | H6: Já cedidas | I6: Disponíveis | J6: Kits completos possíveis
A7: PARAF-MAK-DHP482 | B7: Parafusadeira / furadeira de impacto a bateria 18V com 2 baterias | C7: Ferramenta elétrica | D7: 1 | E7: 890 | F7: =IF(OR($D7="",$E7=""),"",$D7*$E7) | G7: =COUNTIF('Patrimônio Geral'!$F$7:$F$156,$A7) | H7: =COUNTIFS('Patrimônio Geral'!$F$7:$F$156,$A7,'Patrimônio Geral'!$S$7:$S$156,"?*") | I7: =$G7-$H7 | J7: =IF($D7=0,"",INT($G7/$D7))
A8: SERRA-BOS-GKS150 | B8: Serra circular manual 7.1/4" | C8: Ferramenta elétrica | D8: 1 | E8: 690 | F8: =IF(OR($D8="",$E8=""),"",$D8*$E8) | G8: =COUNTIF('Patrimônio Geral'!$F$7:$F$156,$A8) | H8: =COUNTIFS('Patrimônio Geral'!$F$7:$F$156,$A8,'Patrimônio Geral'!$S$7:$S$156,"?*") | I8: =$G8-$H8 | J8: =IF($D8=0,"",INT($G8/$D8))
A9: TUPIA-MAK-RT0700C | B9: Tupia manual 1/4" | C9: Ferramenta elétrica | D9: 1 | E9: 780 | F9: =IF(OR($D9="",$E9=""),"",$D9*$E9) | G9: =COUNTIF('Patrimônio Geral'!$F$7:$F$156,$A9) | H9: =COUNTIFS('Patrimônio Geral'!$F$7:$F$156,$A9,'Patrimônio Geral'!$S$7:$S$156,"?*") | I9: =$G9-$H9 | J9: =IF($D9=0,"",INT($G9/$D9))
A10: LIXA-BOS-GSS140 | B10: Lixadeira orbital 1/4 de folha | C10: Ferramenta elétrica | D10: 1 | E10: 380 | F10: =IF(OR($D10="",$E10=""),"",$D10*$E10) | G10: =COUNTIF('Patrimônio Geral'!$F$7:$F$156,$A10) | H10: =COUNTIFS('Patrimônio Geral'!$F$7:$F$156,$A10,'Patrimônio Geral'!$S$7:$S$156,"?*") | I10: =$G10-$H10 | J10: =IF($D10=0,"",INT($G10/$D10))
A11: FORMAO-TRA-4P | B11: Jogo de formões 4 peças | C11: Ferramenta manual | D11: 1 | E11: 180 | F11: =IF(OR($D11="",$E11=""),"",$D11*$E11) | G11: =COUNTIF('Patrimônio Geral'!$F$7:$F$156,$A11) | H11: =COUNTIFS('Patrimônio Geral'!$F$7:$F$156,$A11,'Patrimônio Geral'!$S$7:$S$156,"?*") | I11: =$G11-$H11 | J11: =IF($D11=0,"",INT($G11/$D11))
A12: MARTELO-TRA-27 | B12: Martelo unha 27 mm cabo de fibra | C12: Ferramenta manual | D12: 1 | E12: 75 | F12: =IF(OR($D12="",$E12=""),"",$D12*$E12) | G12: =COUNTIF('Patrimônio Geral'!$F$7:$F$156,$A12) | H12: =COUNTIFS('Patrimônio Geral'!$F$7:$F$156,$A12,'Patrimônio Geral'!$S$7:$S$156,"?*") | I12: =$G12-$H12 | J12: =IF($D12=0,"",INT($G12/$D12))
A13: CHAVES-GED-6P | B13: Jogo de chaves de fenda e philips 6 peças | C13: Ferramenta manual | D13: 1 | E13: 130 | F13: =IF(OR($D13="",$E13=""),"",$D13*$E13) | G13: =COUNTIF('Patrimônio Geral'!$F$7:$F$156,$A13) | H13: =COUNTIFS('Patrimônio Geral'!$F$7:$F$156,$A13,'Patrimônio Geral'!$S$7:$S$156,"?*") | I13: =$G13-$H13 | J13: =IF($D13=0,"",INT($G13/$D13))
A14: SARGENTO-VON-300 | B14: Grampo sargento 300 mm — par | C14: Ferramenta manual | D14: 1 | E14: 160 | F14: =IF(OR($D14="",$E14=""),"",$D14*$E14) | G14: =COUNTIF('Patrimônio Geral'!$F$7:$F$156,$A14) | H14: =COUNTIFS('Patrimônio Geral'!$F$7:$F$156,$A14,'Patrimônio Geral'!$S$7:$S$156,"?*") | I14: =$G14-$H14 | J14: =IF($D14=0,"",INT($G14/$D14))
A15: TRENA-STA-5M | B15: Trena 5 m | C15: Instrumento de medição | D15: 1 | E15: 55 | F15: =IF(OR($D15="",$E15=""),"",$D15*$E15) | G15: =COUNTIF('Patrimônio Geral'!$F$7:$F$156,$A15) | H15: =COUNTIFS('Patrimônio Geral'!$F$7:$F$156,$A15,'Patrimônio Geral'!$S$7:$S$156,"?*") | I15: =$G15-$H15 | J15: =IF($D15=0,"",INT($G15/$D15))
A16: ESQUADRO-STA-300 | B16: Esquadro de precisão 300 mm | C16: Instrumento de medição | D16: 1 | E16: 120 | F16: =IF(OR($D16="",$E16=""),"",$D16*$E16) | G16: =COUNTIF('Patrimônio Geral'!$F$7:$F$156,$A16) | H16: =COUNTIFS('Patrimônio Geral'!$F$7:$F$156,$A16,'Patrimônio Geral'!$S$7:$S$156,"?*") | I16: =$G16-$H16 | J16: =IF($D16=0,"",INT($G16/$D16))
A17: LASER-BOS-GLL210 | B17: Nível a laser de linha | C17: Instrumento de medição | D17: 1 | E17: 520 | F17: =IF(OR($D17="",$E17=""),"",$D17*$E17) | G17: =COUNTIF('Patrimônio Geral'!$F$7:$F$156,$A17) | H17: =COUNTIFS('Patrimônio Geral'!$F$7:$F$156,$A17,'Patrimônio Geral'!$S$7:$S$156,"?*") | I17: =$G17-$H17 | J17: =IF($D17=0,"",INT($G17/$D17))
A18: MALETA-TRA-ORG | B18: Maleta / caixa organizadora de ferramentas | C18: Ferramenta manual | D18: 1 | E18: 210 | F18: =IF(OR($D18="",$E18=""),"",$D18*$E18) | G18: =COUNTIF('Patrimônio Geral'!$F$7:$F$156,$A18) | H18: =COUNTIFS('Patrimônio Geral'!$F$7:$F$156,$A18,'Patrimônio Geral'!$S$7:$S$156,"?*") | I18: =$G18-$H18 | J18: =IF($D18=0,"",INT($G18/$D18))
A19: TOTAL | F19: =SUM(F7:F18) | G19: =SUM(G7:G18) | H19: =SUM(H7:H18) | I19: =SUM(I7:I18) | J19: =MIN(J7:J18)
A21: COMO LER
A22: 1. Esta aba define o que é um kit completo. A quantidade vive aqui — no desenho do kit — e não no cadastro de bens.
A23: 2. "Unidades cadastradas" conta quantas unidades daquele SKU existem na aba Patrimônio Geral. "Já cedidas" conta as que têm responsável.
A24: 3. "Kits completos possíveis" é quantos kits inteiros o estoque atual permite montar — o menor valor da coluna manda no total.
A25: 4. Para incluir um item novo no kit: cadastre o SKU na aba Listas, acrescente a linha aqui e registre cada unidade física no Patrimônio Geral.

Sheet Movimentações
A1: VALVIC MARCENARIA
A2: Vargas Decor Ltda · CNPJ 17.269.304/0001-51 · Belo Horizonte / MG
A3: MOVIMENTAÇÕES
A4: Histórico de entregas, devoluções, manutenções e baixas — uma linha por evento
A6: Data | B6: Código do item | C6: Descrição | D6: Movimento | E6: De | F6: Para | G6: Estado do item | H6: Documento / termo | I6: Registrado por | J6: Observações
C7: =IFERROR(INDEX('Patrimônio Geral'!$C$7:$C$156,MATCH($B7,'Patrimônio Geral'!$A$7:$A$156,0)),"")
C8: =IFERROR(INDEX('Patrimônio Geral'!$C$7:$C$156,MATCH($B8,'Patrimônio Geral'!$A$7:$A$156,0)),"")
C9: =IFERROR(INDEX('Patrimônio Geral'!$C$7:$C$156,MATCH($B9,'Patrimônio Geral'!$A$7:$A$156,0)),"")
C10: =IFERROR(INDEX('Patrimônio Geral'!$C$7:$C$156,MATCH($B10,'Patrimônio Geral'!$A$7:$A$156,0)),"")
C11: =IFERROR(INDEX('Patrimônio Geral'!$C$7:$C$156,MATCH($B11,'Patrimônio Geral'!$A$7:$A$156,0)),"")
C12: =IFERROR(INDEX('Patrimônio Geral'!$C$7:$C$156,MATCH($B12,'Patrimônio Geral'!$A$7:$A$156,0)),"")
C13: =IFERROR(INDEX('Patrimônio Geral'!$C$7:$C$156,MATCH($B13,'Patrimônio Geral'!$A$7:$A$156,0)),"")
C14: =IFERROR(INDEX('Patrimônio Geral'!$C$7:$C$156,MATCH($B14,'Patrimônio Geral'!$A$7:$A$156,0)),"")
C15: =IFERROR(INDEX('Patrimônio Geral'!$C$7:$C$156,MATCH($B15,'Patrimônio Geral'!$A$7:$A$156,0)),"")
C16: =IFERROR(INDEX('Patrimônio Geral'!$C$7:$C$156,MATCH($B16,'Patrimônio Geral'!$A$7:$A$156,0)),"")
C17: =IFERROR(INDEX('Patrimônio Geral'!$C$7:$C$156,MATCH($B17,'Patrimônio Geral'!$A$7:$A$156,0)),"")
C18: =IFERROR(INDEX('Patrimônio Geral'!$C$7:$C$156,MATCH($B18,'Patrimônio Geral'!$A$7:$A$156,0)),"")
... C106: =IFERROR(INDEX('Patrimônio Geral'!$C$7:$C$156,MATCH($B106,'Patrimônio Geral'!$A$7:$A$156,0)),"")

Sheet Conferência Mensal
A1: VALVIC MARCENARIA
A2: Vargas Decor Ltda · CNPJ 17.269.304/0001-51 · Belo Horizonte / MG
A3: CONFERÊNCIA MENSAL
A4: Checagem física do patrimônio · responsável pela conferência: Deivson · periodicidade mensal
A6: Código | B6: Descrição | C6: Responsável | D6: Localização | E6: Conferido? | F6: Estado encontrado | G6: Divergência | H6: Ação tomada | I6: Data | J6: Conferido por
B7: =IFERROR(INDEX('Patrimônio Geral'!$C$7:$C$156,MATCH($A7,'Patrimônio Geral'!$A$7:$A$156,0)),"") | C7: =IFERROR(INDEX('Patrimônio Geral'!$S$7:$S$156,MATCH($A7,'Patrimônio Geral'!$A$7:$A$156,0)),"") | D7: =IFERROR(INDEX('Patrimônio Geral'!$R$7:$R$156,MATCH($A7,'Patrimônio Geral'!$A$7:$A$156,0)),"")
B8: =IFERROR(INDEX('Patrimônio Geral'!$C$7:$C$156,MATCH($A8,'Patrimônio Geral'!$A$7:$A$156,0)),"") | C8: =IFERROR(INDEX('Patrimônio Geral'!$S$7:$S$156,MATCH($A8,'Patrimônio Geral'!$A$7:$A$156,0)),"") | D8: =IFERROR(INDEX('Patrimônio Geral'!$R$7:$R$156,MATCH($A8,'Patrimônio Geral'!$A$7:$A$156,0)),"")
B9: =IFERROR(INDEX('Patrimônio Geral'!$C$7:$C$156,MATCH($A9,'Patrimônio Geral'!$A$7:$A$156,0)),"") | C9: =IFERROR(INDEX('Patrimônio Geral'!$S$7:$S$156,MATCH($A9,'Patrimônio Geral'!$A$7:$A$156,0)),"") | D9: =IFERROR(INDEX('Patrimônio Geral'!$R$7:$R$156,MATCH($A9,'Patrimônio Geral'!$A$7:$A$156,0)),"")
B10: =IFERROR(INDEX('Patrimônio Geral'!$C$7:$C$156,MATCH($A10,'Patrimônio Geral'!$A$7:$A$156,0)),"") | C10: =IFERROR(INDEX('Patrimônio Geral'!$S$7:$S$156,MATCH($A10,'Patrimônio Geral'!$A$7:$A$156,0)),"") | D10: =IFERROR(INDEX('Patrimônio Geral'!$R$7:$R$156,MATCH($A10,'Patrimônio Geral'!$A$7:$A$156,0)),"")
B11: =IFERROR(INDEX('Patrimônio Geral'!$C$7:$C$156,MATCH($A11,'Patrimônio Geral'!$A$7:$A$156,0)),"") | C11: =IFERROR(INDEX('Patrimônio Geral'!$S$7:$S$156,MATCH($A11,'Patrimônio Geral'!$A$7:$A$156,0)),"") | D11: =IFERROR(INDEX('Patrimônio Geral'!$R$7:$R$156,MATCH($A11,'Patrimônio Geral'!$A$7:$A$156,0)),"")
B12: =IFERROR(INDEX('Patrimônio Geral'!$C$7:$C$156,MATCH($A12,'Patrimônio Geral'!$A$7:$A$156,0)),"") | C12: =IFERROR(INDEX('Patrimônio Geral'!$S$7:$S$156,MATCH($A12,'Patrimônio Geral'!$A$7:$A$156,0)),"") | D12: =IFERROR(INDEX('Patrimônio Geral'!$R$7:$R$156,MATCH($A12,'Patrimônio Geral'!$A$7:$A$156,0)),"")
B13: =IFERROR(INDEX('Patrimônio Geral'!$C$7:$C$156,MATCH($A13,'Patrimônio Geral'!$A$7:$A$156,0)),"") | C13: =IFERROR(INDEX('Patrimônio Geral'!$S$7:$S$156,MATCH($A13,'Patrimônio Geral'!$A$7:$A$156,0)),"") | D13: =IFERROR(INDEX('Patrimônio Geral'!$R$7:$R$156,MATCH($A13,'Patrimônio Geral'!$A$7:$A$156,0)),"")
B14: =IFERROR(INDEX('Patrimônio Geral'!$C$7:$C$156,MATCH($A14,'Patrimônio Geral'!$A$7:$A$156,0)),"") | C14: =IFERROR(INDEX('Patrimônio Geral'!$S$7:$S$156,MATCH($A14,'Patrimônio Geral'!$A$7:$A$156,0)),"") | D14: =IFERROR(INDEX('Patrimônio Geral'!$R$7:$R$156,MATCH($A14,'Patrimônio Geral'!$A$7:$A$156,0)),"")
B15: =IFERROR(INDEX('Patrimônio Geral'!$C$7:$C$156,MATCH($A15,'Patrimônio Geral'!$A$7:$A$156,0)),"") | C15: =IFERROR(INDEX('Patrimônio Geral'!$S$7:$S$156,MATCH($A15,'Patrimônio Geral'!$A$7:$A$156,0)),"") | D15: =IFERROR(INDEX('Patrimônio Geral'!$R$7:$R$156,MATCH($A15,'Patrimônio Geral'!$A$7:$A$156,0)),"")
B16: =IFERROR(INDEX('Patrimônio Geral'!$C$7:$C$156,MATCH($A16,'Patrimônio Geral'!$A$7:$A$156,0)),"") | C16: =IFERROR(INDEX('Patrimônio Geral'!$S$7:$S$156,MATCH($A16,'Patrimônio Geral'!$A$7:$A$156,0)),"") | D16: =IFERROR(INDEX('Patrimônio Geral'!$R$7:$R$156,MATCH($A16,'Patrimônio Geral'!$A$7:$A$156,0)),"")
B17: =IFERROR(INDEX('Patrimônio Geral'!$C$7:$C$156,MATCH($A17,'Patrimônio Geral'!$A$7:$A$156,0)),"") | C17: =IFERROR(INDEX('Patrimônio Geral'!$S$7:$S$156,MATCH($A17,'Patrimônio Geral'!$A$7:$A$156,0)),"") | D17: =IFERROR(INDEX('Patrimônio Geral'!$R$7:$R$156,MATCH($A17,'Patrimônio Geral'!$A$7:$A$156,0)),"")
B18: =IFERROR(INDEX('Patrimônio Geral'!$C$7:$C$156,MATCH($A18,'Patrimônio Geral'!$A$7:$A$156,0)),"") | C18: =IFERROR(INDEX('Patrimônio Geral'!$S$7:$S$156,MATCH($A18,'Patrimônio Geral'!$A$7:$A$156,0)),"") | D18: =IFERROR(INDEX('Patrimônio Geral'!$R$7:$R$156,MATCH($A18,'Patrimônio Geral'!$A$7:$A$156,0)),"")
... B86: =IFERROR(INDEX('Patrimônio Geral'!$C$7:$C$156,MATCH($A86,'Patrimônio Geral'!$A$7:$A$156,0)),"") | C86: =IFERROR(INDEX('Patrimônio Geral'!$S$7:$S$156,MATCH($A86,'Patrimônio Geral'!$A$7:$A$156,0)),"") | D86: =IFERROR(INDEX('Patrimônio Geral'!$R$7:$R$156,MATCH($A86,'Patrimônio Geral'!$A$7:$A$156,0)),"")

Sheet Termo · Deivson
A1: VALVIC MARCENARIA
A2: Vargas Decor Ltda · CNPJ 17.269.304/0001-51 · Belo Horizonte / MG
A3: TERMO DE COMODATO DE FERRAMENTAS
A4: Ferramentas e equipamentos cedidos em comodato · prestador de serviços PJ
A6: IDENTIFICAÇÃO
A7: Nome completo | B7: Deivson | E7: CPF / CNPJ
A8: Função | B8: Coordenador de Produção | E8: Vínculo | F8: PJ
A9: Data da entrega | E9: Local de guarda | F9: Fábrica / canteiro de obra
A11: RELAÇÃO DE ITENS ENTREGUES preencha o código — descrição, marca e valor vêm da aba Patrimônio Geral
A12: Código | B12: Descrição do item | C12: Marca | D12: Etiqueta / nº série | E12: Estado | F12: Valor de referência
B13: =IFERROR(INDEX('Patrimônio Geral'!$C$7:$C$156,MATCH($A13,'Patrimônio Geral'!$A$7:$A$156,0)),"") | C13: =IFERROR(INDEX('Patrimônio Geral'!$D$7:$D$156,MATCH($A13,'Patrimônio Geral'!$A$7:$A$156,0)),"") | D13: =IFERROR(INDEX('Patrimônio Geral'!$G$7:$G$156,MATCH($A13,'Patrimônio Geral'!$A$7:$A$156,0)),"") | F13: =IFERROR(INDEX('Patrimônio Geral'!$K$7:$K$156,MATCH($A13,'Patrimônio Geral'!$A$7:$A$156,0)),"")
B14: =IFERROR(INDEX('Patrimônio Geral'!$C$7:$C$156,MATCH($A14,'Patrimônio Geral'!$A$7:$A$156,0)),"") | C14: =IFERROR(INDEX('Patrimônio Geral'!$D$7:$D$156,MATCH($A14,'Patrimônio Geral'!$A$7:$A$156,0)),"") | D14: =IFERROR(INDEX('Patrimônio Geral'!$G$7:$G$156,MATCH($A14,'Patrimônio Geral'!$A$7:$A$156,0)),"") | F14: =IFERROR(INDEX('Patrimônio Geral'!$K$7:$K$156,MATCH($A14,'Patrimônio Geral'!$A$7:$A$156,0)),"")
B15: =IFERROR(INDEX('Patrimônio Geral'!$C$7:$C$156,MATCH($A15,'Patrimônio Geral'!$A$7:$A$156,0)),"") | C15: =IFERROR(INDEX('Patrimônio Geral'!$D$7:$D$156,MATCH($A15,'Patrimônio Geral'!$A$7:$A$156,0)),"") | D15: =IFERROR(INDEX('Patrimônio Geral'!$G$7:$G$156,MATCH($A15,'Patrimônio Geral'!$A$7:$A$156,0)),"") | F15: =IFERROR(INDEX('Patrimônio Geral'!$K$7:$K$156,MATCH($A15,'Patrimônio Geral'!$A$7:$A$156,0)),"")
B16: =IFERROR(INDEX('Patrimônio Geral'!$C$7:$C$156,MATCH($A16,'Patrimônio Geral'!$A$7:$A$156,0)),"") | C16: =IFERROR(INDEX('Patrimônio Geral'!$D$7:$D$156,MATCH($A16,'Patrimônio Geral'!$A$7:$A$156,0)),"") | D16: =IFERROR(INDEX('Patrimônio Geral'!$G$7:$G$156,MATCH($A16,'Patrimônio Geral'!$A$7:$A$156,0)),"") | F16: =IFERROR(INDEX('Patrimônio Geral'!$K$7:$K$156,MATCH($A16,'Patrimônio Geral'!$A$7:$A$156,0)),"")
B17: =IFERROR(INDEX('Patrimônio Geral'!$C$7:$C$156,MATCH($A17,'Patrimônio Geral'!$A$7:$A$156,0)),"") | C17: =IFERROR(INDEX('Patrimônio Geral'!$D$7:$D$156,MATCH($A17,'Patrimônio Geral'!$A$7:$A$156,0)),"") | D17: =IFERROR(INDEX('Patrimônio Geral'!$G$7:$G$156,MATCH($A17,'Patrimônio Geral'!$A$7:$A$156,0)),"") | F17: =IFERROR(INDEX('Patrimônio Geral'!$K$7:$K$156,MATCH($A17,'Patrimônio Geral'!$A$7:$A$156,0)),"")
B18: =IFERROR(INDEX('Patrimônio Geral'!$C$7:$C$156,MATCH($A18,'Patrimônio Geral'!$A$7:$A$156,0)),"") | C18: =IFERROR(INDEX('Patrimônio Geral'!$D$7:$D$156,MATCH($A18,'Patrimônio Geral'!$A$7:$A$156,0)),"") | D18: =IFERROR(INDEX('Patrimônio Geral'!$G$7:$G$156,MATCH($A18,'Patrimônio Geral'!$A$7:$A$156,0)),"") | F18: =IFERROR(INDEX('Patrimônio Geral'!$K$7:$K$156,MATCH($A18,'Patrimônio Geral'!$A$7:$A$156,0)),"")
B19: =IFERROR(INDEX('Patrimônio Geral'!$C$7:$C$156,MATCH($A19,'Patrimônio Geral'!$A$7:$A$156,0)),"") | C19: =IFERROR(INDEX('Patrimônio Geral'!$D$7:$D$156,MATCH($A19,'Patrimônio Geral'!$A$7:$A$156,0)),"") | D19: =IFERROR(INDEX('Patrimônio Geral'!$G$7:$G$156,MATCH($A19,'Patrimônio Geral'!$A$7:$A$156,0)),"") | F19: =IFERROR(INDEX('Patrimônio Geral'!$K$7:$K$156,MATCH($A19,'Patrimônio Geral'!$A$7:$A$156,0)),"")
B20: =IFERROR(INDEX('Patrimônio Geral'!$C$7:$C$156,MATCH($A20,'Patrimônio Geral'!$A$7:$A$156,0)),"") | C20: =IFERROR(INDEX('Patrimônio Geral'!$D$7:$D$156,MATCH($A20,'Patrimônio Geral'!$A$7:$A$156,0)),"") | D20: =IFERROR(INDEX('Patrimônio Geral'!$G$7:$G$156,MATCH($A20,'Patrimônio Geral'!$A$7:$A$156,0)),"") | F20: =IFERROR(INDEX('Patrimônio Geral'!$K$7:$K$156,MATCH($A20,'Patrimônio Geral'!$A$7:$A$156,0)),"")
B21: =IFERROR(INDEX('Patrimônio Geral'!$C$7:$C$156,MATCH($A21,'Patrimônio Geral'!$A$7:$A$156,0)),"") | C21: =IFERROR(INDEX('Patrimônio Geral'!$D$7:$D$156,MATCH($A21,'Patrimônio Geral'!$A$7:$A$156,0)),"") | D21: =IFERROR(INDEX('Patrimônio Geral'!$G$7:$G$156,MATCH($A21,'Patrimônio Geral'!$A$7:$A$156,0)),"") | F21: =IFERROR(INDEX('Patrimônio Geral'!$K$7:$K$156,MATCH($A21,'Patrimônio Geral'!$A$7:$A$156,0)),"")
B22: =IFERROR(INDEX('Patrimônio Geral'!$C$7:$C$156,MATCH($A22,'Patrimônio Geral'!$A$7:$A$156,0)),"") | C22: =IFERROR(INDEX('Patrimônio Geral'!$D$7:$D$156,MATCH($A22,'Patrimônio Geral'!$A$7:$A$156,0)),"") | D22: =IFERROR(INDEX('Patrimônio Geral'!$G$7:$G$156,MATCH($A22,'Patrimônio Geral'!$A$7:$A$156,0)),"") | F22: =IFERROR(INDEX('Patrimônio Geral'!$K$7:$K$156,MATCH($A22,'Patrimônio Geral'!$A$7:$A$156,0)),"")
B23: =IFERROR(INDEX('Patrimônio Geral'!$C$7:$C$156,MATCH($A23,'Patrimônio Geral'!$A$7:$A$156,0)),"") | C23: =IFERROR(INDEX('Patrimônio Geral'!$D$7:$D$156,MATCH($A23,'Patrimônio Geral'!$A$7:$A$156,0)),"") | D23: =IFERROR(INDEX('Patrimônio Geral'!$G$7:$G$156,MATCH($A23,'Patrimônio Geral'!$A$7:$A$156,0)),"") | F23: =IFERROR(INDEX('Patrimônio Geral'!$K$7:$K$156,MATCH($A23,'Patrimônio Geral'!$A$7:$A$156,0)),"")
B24: =IFERROR(INDEX('Patrimônio Geral'!$C$7:$C$156,MATCH($A24,'Patrimônio Geral'!$A$7:$A$156,0)),"") | C24: =IFERROR(INDEX('Patrimônio Geral'!$D$7:$D$156,MATCH($A24,'Patrimônio Geral'!$A$7:$A$156,0)),"") | D24: =IFERROR(INDEX('Patrimônio Geral'!$G$7:$G$156,MATCH($A24,'Patrimônio Geral'!$A$7:$A$156,0)),"") | F24: =IFERROR(INDEX('Patrimônio Geral'!$K$7:$K$156,MATCH($A24,'Patrimônio Geral'!$A$7:$A$156,0)),"")
... B26: =IFERROR(INDEX('Patrimônio Geral'!$C$7:$C$156,MATCH($A26,'Patrimônio Geral'!$A$7:$A$156,0)),"") | C26: =IFERROR(INDEX('Patrimônio Geral'!$D$7:$D$156,MATCH($A26,'Patrimônio Geral'!$A$7:$A$156,0)),"") | D26: =IFERROR(INDEX('Patrimônio Geral'!$G$7:$G$156,MATCH($A26,'Patrimônio Geral'!$A$7:$A$156,0)),"") | F26: =IFERROR(INDEX('Patrimônio Geral'!$K$7:$K$156,MATCH($A26,'Patrimônio Geral'!$A$7:$A$156,0)),"")
A27: TOTAL DE REFERÊNCIA DOS ITENS ENTREGUES | F27: =SUM(F13:F26)
A28: O valor de referência serve apenas para identificar o bem. Não constitui caução, depósito, garantia nem autorização prévia de desconto.
A30: CONDIÇÕES
A31: 1. OBJETO E NATUREZA — A COMODANTE entrega à COMODATÁRIA, em COMODATO GRATUITO, nos termos dos artigos 579 e seguintes do Código Civil, as ferramentas e equipamentos relacionados no quadro acima, que permanecem sendo de propriedade integral da COMODANTE.
A32: 2. USO — Os itens destinam-se exclusivamente à execução dos serviços contratados. É vedado emprestá-los, sublocá-los, cedê-los ou aliená-los, sob qualquer título.
A33: 3. GUARDA — Os itens NÃO podem ser levados para a residência da COMODATÁRIA. A guarda deve ocorrer nas dependências da COMODANTE ou no canteiro de obra, em local seguro indicado pela coordenação.
A34: 4. CONSERVAÇÃO — A COMODATÁRIA obriga-se a conservar os itens como se seus fossem, respondendo pela guarda e pelo uso adequado, nos termos do art. 582 do Código Civil.
A35: 5. DESGASTE NATURAL — O desgaste decorrente do uso normal e a manutenção preventiva correm por conta da COMODANTE, sem ônus para a COMODATÁRIA.
A36: 6. DANO OU PERDA — Havendo dano por uso indevido, negligência ou perda, a COMODATÁRIA se compromete a REPOR o item por outro de mesma especificação e em estado equivalente, no prazo de 30 (trinta) dias, adquirindo-o por sua própria conta e da forma que lhe for mais conveniente.
A37: 7. FURTO OU ROUBO — Em caso de furto ou roubo, a COMODATÁRIA deve comunicar imediatamente a coordenação e registrar Boletim de Ocorrência em até 48 (quarenta e oito) horas. Comprovado o fato, não haverá ônus de reposição.
A38: 8. RESTITUIÇÃO — Os itens devem ser restituídos sempre que solicitados pela COMODANTE e, obrigatoriamente, ao término da prestação de serviços, mediante registro no quadro de devolução.
A39: 9. REGISTRO FOTOGRÁFICO — O registro fotográfico do estado dos itens, feito na data da entrega, integra este termo para todos os efeitos.
A41: DECLARAÇÃO E ASSINATURAS
A42: Declaro ter recebido os itens acima relacionados, conferido seu estado de conservação e estar ciente das condições deste termo, que assino em duas vias de igual teor. Fica a COMODATÁRIA responsável pela guarda e pelo uso adequado dos itens enquanto estiverem sob sua posse.
A45: Deivson | E45: Valvic Marcenaria — Vargas Decor Ltda
A46: CNPJ | E46: Representante legal
A47: Belo Horizonte / MG, ______ de ____________________ de __________
...

Sheet Termo · Samuel
A1: VALVIC MARCENARIA
A2: Vargas Decor Ltda · CNPJ 17.269.304/0001-51 · Belo Horizonte / MG
A3: TERMO DE COMODATO DE FERRAMENTAS
A4: Ferramentas e equipamentos cedidos em comodato · prestador de serviços PJ
A6: IDENTIFICAÇÃO
A7: Nome completo | B7: Samuel | E7: CPF / CNPJ
A8: Função | B8: Marceneiro Sênior | E8: Vínculo | F8: PJ
A9: Data da entrega | E9: Local de guarda | F9: Fábrica / canteiro de obra
A11: RELAÇÃO DE ITENS ENTREGUES preencha o código — descrição, marca e valor vêm da aba Patrimônio Geral
A12: Código | B12: Descrição do item | C12: Marca | D12: Etiqueta / nº série | E12: Estado | F12: Valor de referência
B13: =IFERROR(INDEX('Patrimônio Geral'!$C$7:$C$156,MATCH($A13,'Patrimônio Geral'!$A$7:$A$156,0)),"") | C13: =IFERROR(INDEX('Patrimônio Geral'!$D$7:$D$156,MATCH($A13,'Patrimônio Geral'!$A$7:$A$156,0)),"") | D13: =IFERROR(INDEX('Patrimônio Geral'!$G$7:$G$156,MATCH($A13,'Patrimônio Geral'!$A$7:$A$156,0)),"") | F13: =IFERROR(INDEX('Patrimônio Geral'!$K$7:$K$156,MATCH($A13,'Patrimônio Geral'!$A$7:$A$156,0)),"")
B14: =IFERROR(INDEX('Patrimônio Geral'!$C$7:$C$156,MATCH($A14,'Patrimônio Geral'!$A$7:$A$156,0)),"") | C14: =IFERROR(INDEX('Patrimônio Geral'!$D$7:$D$156,MATCH($A14,'Patrimônio Geral'!$A$7:$A$156,0)),"") | D14: =IFERROR(INDEX('Patrimônio Geral'!$G$7:$G$156,MATCH($A14,'Patrimônio Geral'!$A$7:$A$156,0)),"") | F14: =IFERROR(INDEX('Patrimônio Geral'!$K$7:$K$156,MATCH($A14,'Patrimônio Geral'!$A$7:$A$156,0)),"")
B15: =IFERROR(INDEX('Patrimônio Geral'!$C$7:$C$156,MATCH($A15,'Patrimônio Geral'!$A$7:$A$156,0)),"") | C15: =IFERROR(INDEX('Patrimônio Geral'!$D$7:$D$156,MATCH($A15,'Patrimônio Geral'!$A$7:$A$156,0)),"") | D15: =IFERROR(INDEX('Patrimônio Geral'!$G$7:$G$156,MATCH($A15,'Patrimônio Geral'!$A$7:$A$156,0)),"") | F15: =IFERROR(INDEX('Patrimônio Geral'!$K$7:$K$156,MATCH($A15,'Patrimônio Geral'!$A$7:$A$156,0)),"")
B16: =IFERROR(INDEX('Patrimônio Geral'!$C$7:$C$156,MATCH($A16,'Patrimônio Geral'!$A$7:$A$156,0)),"") | C16: =IFERROR(INDEX('Patrimônio Geral'!$D$7:$D$156,MATCH($A16,'Patrimônio Geral'!$A$7:$A$156,0)),"") | D16: =IFERROR(INDEX('Patrimônio Geral'!$G$7:$G$156,MATCH($A16,'Patrimônio Geral'!$A$7:$A$156,0)),"") | F16: =IFERROR(INDEX('Patrimônio Geral'!$K$7:$K$156,MATCH($A16,'Patrimônio Geral'!$A$7:$A$156,0)),"")
B17: =IFERROR(INDEX('Patrimônio Geral'!$C$7:$C$156,MATCH($A17,'Patrimônio Geral'!$A$7:$A$156,0)),"") | C17: =IFERROR(INDEX('Patrimônio Geral'!$D$7:$D$156,MATCH($A17,'Patrimônio Geral'!$A$7:$A$156,0)),"") | D17: =IFERROR(INDEX('Patrimônio Geral'!$G$7:$G$156,MATCH($A17,'Patrimônio Geral'!$A$7:$A$156,0)),"") | F17: =IFERROR(INDEX('Patrimônio Geral'!$K$7:$K$156,MATCH($A17,'Patrimônio Geral'!$A$7:$A$156,0)),"")
B18: =IFERROR(INDEX('Patrimônio Geral'!$C$7:$C$156,MATCH($A18,'Patrimônio Geral'!$A$7:$A$156,0)),"") | C18: =IFERROR(INDEX('Patrimônio Geral'!$D$7:$D$156,MATCH($A18,'Patrimônio Geral'!$A$7:$A$156,0)),"") | D18: =IFERROR(INDEX('Patrimônio Geral'!$G$7:$G$156,MATCH($A18,'Patrimônio Geral'!$A$7:$A$156,0)),"") | F18: =IFERROR(INDEX('Patrimônio Geral'!$K$7:$K$156,MATCH($A18,'Patrimônio Geral'!$A$7:$A$156,0)),"")
B19: =IFERROR(INDEX('Patrimônio Geral'!$C$7:$C$156,MATCH($A19,'Patrimônio Geral'!$A$7:$A$156,0)),"") | C19: =IFERROR(INDEX('Patrimônio Geral'!$D$7:$D$156,MATCH($A19,'Patrimônio Geral'!$A$7:$A$156,0)),"") | D19: =IFERROR(INDEX('Patrimônio Geral'!$G$7:$G$156,MATCH($A19,'Patrimônio Geral'!$A$7:$A$156,0)),"") | F19: =IFERROR(INDEX('Patrimônio Geral'!$K$7:$K$156,MATCH($A19,'Patrimônio Geral'!$A$7:$A$156,0)),"")
B20: =IFERROR(INDEX('Patrimônio Geral'!$C$7:$C$156,MATCH($A20,'Patrimônio Geral'!$A$7:$A$156,0)),"") | C20: =IFERROR(INDEX('Patrimônio Geral'!$D$7:$D$156,MATCH($A20,'Patrimônio Geral'!$A$7:$A$156,0)),"") | D20: =IFERROR(INDEX('Patrimônio Geral'!$G$7:$G$156,MATCH($A20,'Patrimônio Geral'!$A$7:$A$156,0)),"") | F20: =IFERROR(INDEX('Patrimônio Geral'!$K$7:$K$156,MATCH($A20,'Patrimônio Geral'!$A$7:$A$156,0)),"")
B21: =IFERROR(INDEX('Patrimônio Geral'!$C$7:$C$156,MATCH($A21,'Patrimônio Geral'!$A$7:$A$156,0)),"") | C21: =IFERROR(INDEX('Patrimônio Geral'!$D$7:$D$156,MATCH($A21,'Patrimônio Geral'!$A$7:$A$156,0)),"") | D21: =IFERROR(INDEX('Patrimônio Geral'!$G$7:$G$156,MATCH($A21,'Patrimônio Geral'!$A$7:$A$156,0)),"") | F21: =IFERROR(INDEX('Patrimônio Geral'!$K$7:$K$156,MATCH($A21,'Patrimônio Geral'!$A$7:$A$156,0)),"")
B22: =IFERROR(INDEX('Patrimônio Geral'!$C$7:$C$156,MATCH($A22,'Patrimônio Geral'!$A$7:$A$156,0)),"") | C22: =IFERROR(INDEX('Patrimônio Geral'!$D$7:$D$156,MATCH($A22,'Patrimônio Geral'!$A$7:$A$156,0)),"") | D22: =IFERROR(INDEX('Patrimônio Geral'!$G$7:$G$156,MATCH($A22,'Patrimônio Geral'!$A$7:$A$156,0)),"") | F22: =IFERROR(INDEX('Patrimônio Geral'!$K$7:$K$156,MATCH($A22,'Patrimônio Geral'!$A$7:$A$156,0)),"")
B23: =IFERROR(INDEX('Patrimônio Geral'!$C$7:$C$156,MATCH($A23,'Patrimônio Geral'!$A$7:$A$156,0)),"") | C23: =IFERROR(INDEX('Patrimônio Geral'!$D$7:$D$156,MATCH($A23,'Patrimônio Geral'!$A$7:$A$156,0)),"") | D23: =IFERROR(INDEX('Patrimônio Geral'!$G$7:$G$156,MATCH($A23,'Patrimônio Geral'!$A$7:$A$156,0)),"") | F23: =IFERROR(INDEX('Patrimônio Geral'!$K$7:$K$156,MATCH($A23,'Patrimônio Geral'!$A$7:$A$156,0)),"")
B24: =IFERROR(INDEX('Patrimônio Geral'!$C$7:$C$156,MATCH($A24,'Patrimônio Geral'!$A$7:$A$156,0)),"") | C24: =IFERROR(INDEX('Patrimônio Geral'!$D$7:$D$156,MATCH($A24,'Patrimônio Geral'!$A$7:$A$156,0)),"") | D24: =IFERROR(INDEX('Patrimônio Geral'!$G$7:$G$156,MATCH($A24,'Patrimônio Geral'!$A$7:$A$156,0)),"") | F24: =IFERROR(INDEX('Patrimônio Geral'!$K$7:$K$156,MATCH($A24,'Patrimônio Geral'!$A$7:$A$156,0)),"")
... B26: =IFERROR(INDEX('Patrimônio Geral'!$C$7:$C$156,MATCH($A26,'Patrimônio Geral'!$A$7:$A$156,0)),"") | C26: =IFERROR(INDEX('Patrimônio Geral'!$D$7:$D$156,MATCH($A26,'Patrimônio Geral'!$A$7:$A$156,0)),"") | D26: =IFERROR(INDEX('Patrimônio Geral'!$G$7:$G$156,MATCH($A26,'Patrimônio Geral'!$A$7:$A$156,0)),"") | F26: =IFERROR(INDEX('Patrimônio Geral'!$K$7:$K$156,MATCH($A26,'Patrimônio Geral'!$A$7:$A$156,0)),"")
A27: TOTAL DE REFERÊNCIA DOS ITENS ENTREGUES | F27: =SUM(F13:F26)
A28: O valor de referência serve apenas para identificar o bem. Não constitui caução, depósito, garantia nem autorização prévia de desconto.
A30: CONDIÇÕES
A31: 1. OBJETO E NATUREZA — A COMODANTE entrega à COMODATÁRIA, em COMODATO GRATUITO, nos termos dos artigos 579 e seguintes do Código Civil, as ferramentas e equipamentos relacionados no quadro acima, que permanecem sendo de propriedade integral da COMODANTE.
A32: 2. USO — Os itens destinam-se exclusivamente à execução dos serviços contratados. É vedado emprestá-los, sublocá-los, cedê-los ou aliená-los, sob qualquer título.
A33: 3. GUARDA — Os itens NÃO podem ser levados para a residência da COMODATÁRIA. A guarda deve ocorrer nas dependências da COMODANTE ou no canteiro de obra, em local seguro indicado pela coordenação.
A34: 4. CONSERVAÇÃO — A COMODATÁRIA obriga-se a conservar os itens como se seus fossem, respondendo pela guarda e pelo uso adequado, nos termos do art. 582 do Código Civil.
A35: 5. DESGASTE NATURAL — O desgaste decorrente do uso normal e a manutenção preventiva correm por conta da COMODANTE, sem ônus para a COMODATÁRIA.
A36: 6. DANO OU PERDA — Havendo dano por uso indevido, negligência ou perda, a COMODATÁRIA se compromete a REPOR o item por outro de mesma especificação e em estado equivalente, no prazo de 30 (trinta) dias, adquirindo-o por sua própria conta e da forma que lhe for mais conveniente.
A37: 7. FURTO OU ROUBO — Em caso de furto ou roubo, a COMODATÁRIA deve comunicar imediatamente a coordenação e registrar Boletim de Ocorrência em até 48 (quarenta e oito) horas. Comprovado o fato, não haverá ônus de reposição.
A38: 8. RESTITUIÇÃO — Os itens devem ser restituídos sempre que solicitados pela COMODANTE e, obrigatoriamente, ao término da prestação de serviços, mediante registro no quadro de devolução.
A39: 9. REGISTRO FOTOGRÁFICO — O registro fotográfico do estado dos itens, feito na data da entrega, integra este termo para todos os efeitos.
A41: DECLARAÇÃO E ASSINATURAS
A42: Declaro ter recebido os itens acima relacionados, conferido seu estado de conservação e estar ciente das condições deste termo, que assino em duas vias de igual teor. Fica a COMODATÁRIA responsável pela guarda e pelo uso adequado dos itens enquanto estiverem sob sua posse.
A45: Samuel | E45: Valvic Marcenaria — Vargas Decor Ltda
A46: CNPJ | E46: Representante legal
A47: Belo Horizonte / MG, ______ de ____________________ de __________
...

Sheet Termo · Jackson
A1: VALVIC MARCENARIA
A2: Vargas Decor Ltda · CNPJ 17.269.304/0001-51 · Belo Horizonte / MG
A3: TERMO DE COMODATO DE FERRAMENTAS
A4: Ferramentas e equipamentos cedidos em comodato · prestador de serviços PJ
A6: IDENTIFICAÇÃO
A7: Nome completo | B7: Jackson | E7: CPF / CNPJ
A8: Função | B8: Marceneiro Pleno | E8: Vínculo | F8: PJ
A9: Data da entrega | E9: Local de guarda | F9: Fábrica / canteiro de obra
A11: RELAÇÃO DE ITENS ENTREGUES preencha o código — descrição, marca e valor vêm da aba Patrimônio Geral
A12: Código | B12: Descrição do item | C12: Marca | D12: Etiqueta / nº série | E12: Estado | F12: Valor de referência
B13: =IFERROR(INDEX('Patrimônio Geral'!$C$7:$C$156,MATCH($A13,'Patrimônio Geral'!$A$7:$A$156,0)),"") | C13: =IFERROR(INDEX('Patrimônio Geral'!$D$7:$D$156,MATCH($A13,'Patrimônio Geral'!$A$7:$A$156,0)),"") | D13: =IFERROR(INDEX('Patrimônio Geral'!$G$7:$G$156,MATCH($A13,'Patrimônio Geral'!$A$7:$A$156,0)),"") | F13: =IFERROR(INDEX('Patrimônio Geral'!$K$7:$K$156,MATCH($A13,'Patrimônio Geral'!$A$7:$A$156,0)),"")
B14: =IFERROR(INDEX('Patrimônio Geral'!$C$7:$C$156,MATCH($A14,'Patrimônio Geral'!$A$7:$A$156,0)),"") | C14: =IFERROR(INDEX('Patrimônio Geral'!$D$7:$D$156,MATCH($A14,'Patrimônio Geral'!$A$7:$A$156,0)),"") | D14: =IFERROR(INDEX('Patrimônio Geral'!$G$7:$G$156,MATCH($A14,'Patrimônio Geral'!$A$7:$A$156,0)),"") | F14: =IFERROR(INDEX('Patrimônio Geral'!$K$7:$K$156,MATCH($A14,'Patrimônio Geral'!$A$7:$A$156,0)),"")
B15: =IFERROR(INDEX('Patrimônio Geral'!$C$7:$C$156,MATCH($A15,'Patrimônio Geral'!$A$7:$A$156,0)),"") | C15: =IFERROR(INDEX('Patrimônio Geral'!$D$7:$D$156,MATCH($A15,'Patrimônio Geral'!$A$7:$A$156,0)),"") | D15: =IFERROR(INDEX('Patrimônio Geral'!$G$7:$G$156,MATCH($A15,'Patrimônio Geral'!$A$7:$A$156,0)),"") | F15: =IFERROR(INDEX('Patrimônio Geral'!$K$7:$K$156,MATCH($A15,'Patrimônio Geral'!$A$7:$A$156,0)),"")
B16: =IFERROR(INDEX('Patrimônio Geral'!$C$7:$C$156,MATCH($A16,'Patrimônio Geral'!$A$7:$A$156,0)),"") | C16: =IFERROR(INDEX('Patrimônio Geral'!$D$7:$D$156,MATCH($A16,'Patrimônio Geral'!$A$7:$A$156,0)),"") | D16: =IFERROR(INDEX('Patrimônio Geral'!$G$7:$G$156,MATCH($A16,'Patrimônio Geral'!$A$7:$A$156,0)),"") | F16: =IFERROR(INDEX('Patrimônio Geral'!$K$7:$K$156,MATCH($A16,'Patrimônio Geral'!$A$7:$A$156,0)),"")
B17: =IFERROR(INDEX('Patrimônio Geral'!$C$7:$C$156,MATCH($A17,'Patrimônio Geral'!$A$7:$A$156,0)),"") | C17: =IFERROR(INDEX('Patrimônio Geral'!$D$7:$D$156,MATCH($A17,'Patrimônio Geral'!$A$7:$A$156,0)),"") | D17: =IFERROR(INDEX('Patrimônio Geral'!$G$7:$G$156,MATCH($A17,'Patrimônio Geral'!$A$7:$A$156,0)),"") | F17: =IFERROR(INDEX('Patrimônio Geral'!$K$7:$K$156,MATCH($A17,'Patrimônio Geral'!$A$7:$A$156,0)),"")
B18: =IFERROR(INDEX('Patrimônio Geral'!$C$7:$C$156,MATCH($A18,'Patrimônio Geral'!$A$7:$A$156,0)),"") | C18: =IFERROR(INDEX('Patrimônio Geral'!$D$7:$D$156,MATCH($A18,'Patrimônio Geral'!$A$7:$A$156,0)),"") | D18: =IFERROR(INDEX('Patrimônio Geral'!$G$7:$G$156,MATCH($A18,'Patrimônio Geral'!$A$7:$A$156,0)),"") | F18: =IFERROR(INDEX('Patrimônio Geral'!$K$7:$K$156,MATCH($A18,'Patrimônio Geral'!$A$7:$A$156,0)),"")
B19: =IFERROR(INDEX('Patrimônio Geral'!$C$7:$C$156,MATCH($A19,'Patrimônio Geral'!$A$7:$A$156,0)),"") | C19: =IFERROR(INDEX('Patrimônio Geral'!$D$7:$D$156,MATCH($A19,'Patrimônio Geral'!$A$7:$A$156,0)),"") | D19: =IFERROR(INDEX('Patrimônio Geral'!$G$7:$G$156,MATCH($A19,'Patrimônio Geral'!$A$7:$A$156,0)),"") | F19: =IFERROR(INDEX('Patrimônio Geral'!$K$7:$K$156,MATCH($A19,'Patrimônio Geral'!$A$7:$A$156,0)),"")
B20: =IFERROR(INDEX('Patrimônio Geral'!$C$7:$C$156,MATCH($A20,'Patrimônio Geral'!$A$7:$A$156,0)),"") | C20: =IFERROR(INDEX('Patrimônio Geral'!$D$7:$D$156,MATCH($A20,'Patrimônio Geral'!$A$7:$A$156,0)),"") | D20: =IFERROR(INDEX('Patrimônio Geral'!$G$7:$G$156,MATCH($A20,'Patrimônio Geral'!$A$7:$A$156,0)),"") | F20: =IFERROR(INDEX('Patrimônio Geral'!$K$7:$K$156,MATCH($A20,'Patrimônio Geral'!$A$7:$A$156,0)),"")
B21: =IFERROR(INDEX('Patrimônio Geral'!$C$7:$C$156,MATCH($A21,'Patrimônio Geral'!$A$7:$A$156,0)),"") | C21: =IFERROR(INDEX('Patrimônio Geral'!$D$7:$D$156,MATCH($A21,'Patrimônio Geral'!$A$7:$A$156,0)),"") | D21: =IFERROR(INDEX('Patrimônio Geral'!$G$7:$G$156,MATCH($A21,'Patrimônio Geral'!$A$7:$A$156,0)),"") | F21: =IFERROR(INDEX('Patrimônio Geral'!$K$7:$K$156,MATCH($A21,'Patrimônio Geral'!$A$7:$A$156,0)),"")
B22: =IFERROR(INDEX('Patrimônio Geral'!$C$7:$C$156,MATCH($A22,'Patrimônio Geral'!$A$7:$A$156,0)),"") | C22: =IFERROR(INDEX('Patrimônio Geral'!$D$7:$D$156,MATCH($A22,'Patrimônio Geral'!$A$7:$A$156,0)),"") | D22: =IFERROR(INDEX('Patrimônio Geral'!$G$7:$G$156,MATCH($A22,'Patrimônio Geral'!$A$7:$A$156,0)),"") | F22: =IFERROR(INDEX('Patrimônio Geral'!$K$7:$K$156,MATCH($A22,'Patrimônio Geral'!$A$7:$A$156,0)),"")
B23: =IFERROR(INDEX('Patrimônio Geral'!$C$7:$C$156,MATCH($A23,'Patrimônio Geral'!$A$7:$A$156,0)),"") | C23: =IFERROR(INDEX('Patrimônio Geral'!$D$7:$D$156,MATCH($A23,'Patrimônio Geral'!$A$7:$A$156,0)),"") | D23: =IFERROR(INDEX('Patrimônio Geral'!$G$7:$G$156,MATCH($A23,'Patrimônio Geral'!$A$7:$A$156,0)),"") | F23: =IFERROR(INDEX('Patrimônio Geral'!$K$7:$K$156,MATCH($A23,'Patrimônio Geral'!$A$7:$A$156,0)),"")
B24: =IFERROR(INDEX('Patrimônio Geral'!$C$7:$C$156,MATCH($A24,'Patrimônio Geral'!$A$7:$A$156,0)),"") | C24: =IFERROR(INDEX('Patrimônio Geral'!$D$7:$D$156,MATCH($A24,'Patrimônio Geral'!$A$7:$A$156,0)),"") | D24: =IFERROR(INDEX('Patrimônio Geral'!$G$7:$G$156,MATCH($A24,'Patrimônio Geral'!$A$7:$A$156,0)),"") | F24: =IFERROR(INDEX('Patrimônio Geral'!$K$7:$K$156,MATCH($A24,'Patrimônio Geral'!$A$7:$A$156,0)),"")
... B26: =IFERROR(INDEX('Patrimônio Geral'!$C$7:$C$156,MATCH($A26,'Patrimônio Geral'!$A$7:$A$156,0)),"") | C26: =IFERROR(INDEX('Patrimônio Geral'!$D$7:$D$156,MATCH($A26,'Patrimônio Geral'!$A$7:$A$156,0)),"") | D26: =IFERROR(INDEX('Patrimônio Geral'!$G$7:$G$156,MATCH($A26,'Patrimônio Geral'!$A$7:$A$156,0)),"") | F26: =IFERROR(INDEX('Patrimônio Geral'!$K$7:$K$156,MATCH($A26,'Patrimônio Geral'!$A$7:$A$156,0)),"")
A27: TOTAL DE REFERÊNCIA DOS ITENS ENTREGUES | F27: =SUM(F13:F26)
A28: O valor de referência serve apenas para identificar o bem. Não constitui caução, depósito, garantia nem autorização prévia de desconto.
A30: CONDIÇÕES
A31: 1. OBJETO E NATUREZA — A COMODANTE entrega à COMODATÁRIA, em COMODATO GRATUITO, nos termos dos artigos 579 e seguintes do Código Civil, as ferramentas e equipamentos relacionados no quadro acima, que permanecem sendo de propriedade integral da COMODANTE.
A32: 2. USO — Os itens destinam-se exclusivamente à execução dos serviços contratados. É vedado emprestá-los, sublocá-los, cedê-los ou aliená-los, sob qualquer título.
A33: 3. GUARDA — Os itens NÃO podem ser levados para a residência da COMODATÁRIA. A guarda deve ocorrer nas dependências da COMODANTE ou no canteiro de obra, em local seguro indicado pela coordenação.
