Workbook
Name CATEGORIA_COMPRA: Listas!$D$2:$D$17
Name FORMA_PAGAMENTO: Listas!$E$2:$E$9
Name STATUS_COMPRA: Listas!$F$2:$F$4
Name EQUIPE_COMISSAO: Listas!$A$2:$A$13
Name VENDEDOR: Listas!$B$2:$B$6
Name CAUSA_RETRABALHO: Listas!$C$2:$C$10
Name PROJETISTA: Listas!$H$2:$H$4

Sheet Instruções
A1: VALVIC MARCENARIA
A2: Vargas Decor Ltda · CNPJ 17.269.304/0001-51 · Belo Horizonte / MG
A3: COMO USAR ESTA PLANILHA
A4: Custo direto por projeto · orçado × realizado · eficiência do orçamento
A6: PARA QUE SERVE
A8: Medir se o seu orçamento acerta. Cada linha de custo tem ORÇADO e REALIZADO lado a lado, e o desvio entre os dois é a resposta.
A9: Sem a coluna ORÇADO isto seria só um controle de gasto. Com ela, vira uma régua: você descobre que sempre erra ferragem para menos, ou que a logística custa o dobro do que imagina.
A11: O PASSO A PASSO
A13: 1 · Botão direito na aba "Ficha Modelo" → Mover ou copiar → marcar "Criar uma cópia". Renomeie (ex.: P-2026-042 Maria).
A14: 2 · Preencha a identificação: cliente, nº, projeto, data de entrada, entrega prevista, vendedor e coordenador.
A15: 3 · Lance o valor de venda ORÇADO (proposta) e REALIZADO (fechado). A diferença entre os dois já é informação: é o desconto que você deu.
A16: 4 · Preencha as premissas de custo de venda (% de imposto, máquina, comissão e RT). Elas se aplicam sozinhas aos dois cenários.
... A67: Abas: Instruções · Painel Geral · Ficha Modelo (duplique esta) · Exemplo P-2026-041 (preenchido) · Listas

Sheet Painel Geral
A1: VALVIC MARCENARIA
A2: Vargas Decor Ltda · CNPJ 17.269.304/0001-51 · Belo Horizonte / MG
A3: PAINEL GERAL DE CUSTO POR PROJETO
A4: Cada linha puxa uma ficha · digite o nome exato da aba na coluna ABA e o resto aparece sozinho
A6: PROJETOS | D6: VENDIDO | G6: CUSTO TOTAL | J6: AINDA A COMPRAR | M6: MARGEM DE CONTRIB. | O6: MC MÉDIA | Q6: ENTREGA NO PRAZO
A7: =COUNTA($B$11:$B$50) | D7: =ROUND(SUM($J$11:$J$50),2) | G7: =ROUND(SUM($K$11:$K$50),2) | J7: =ROUND(SUM($L$11:$L$50),2) | M7: =ROUND(SUM($M$11:$M$50),2) | O7: =IF(SUM($J$11:$J$50)=0,"",SUM($M$11:$M$50)/SUM($J$11:$J$50)) | Q7: =IF(COUNTIF($I$11:$I$50,"No prazo")+COUNTIF($I$11:$I$50,"Atrasado")=0,"",COUNTIF($I$11:$I$50,"No prazo")/(COUNTIF($I$11:$I$50,"No prazo")+COUNTIF($I$11:$I$50,"Atrasado")))
A9: PROJETOS digite na coluna ABA o nome exato da lâmina de cada projeto
A10: # | B10: Aba do projeto | C10: Cliente | D10: Projeto | E10: Entrada | F10: Prevista | G10: Entregue | H10: Dias | I10: Entrega | J10: Venda | K10: Custo total | L10: A comprar | M10: MC (R$) | N10: MC % | O10: MC % orç. | P10: Δ p.p. | Q10: Desvio de custo | R10: Diagnóstico
A11: 1 | B11: Ana Carolina | C11: =IFERROR(INDIRECT("'"&$B11&"'!A7"),"") | D11: =IFERROR(INDIRECT("'"&$B11&"'!A9"),"") | E11: =IFERROR(INDIRECT("'"&$B11&"'!F7"),"") | F11: =IFERROR(INDIRECT("'"&$B11&"'!H7"),"") | G11: =IFERROR(INDIRECT("'"&$B11&"'!J7"),"") | H11: =IFERROR(INDIRECT("'"&$B11&"'!H9"),"") | I11: =IFERROR(INDIRECT("'"&$B11&"'!J9"),"") | J11: =IFERROR(INDIRECT("'"&$B11&"'!A13"),"") | K11: =IFERROR(INDIRECT("'"&$B11&"'!C13"),"") | L11: =IFERROR(INDIRECT("'"&$B11&"'!I24"),"") | M11: =IFERROR(INDIRECT("'"&$B11&"'!E13"),"") | N11: =IFERROR(INDIRECT("'"&$B11&"'!G13"),"") | O11: =IFERROR(INDIRECT("'"&$B11&"'!H13"),"") | P11: =IF(OR($N11="",$O11=""),"",ROUND(($N11-$O11)*100,1)) | Q11: =IFERROR(INDIRECT("'"&$B11&"'!I13"),"") | R11: =IF($N11="","",IF($N11>=0.35,"Margem boa",IF($N11>=0.25,"Margem apertada","Margem crítica"))) | AH11: =IFERROR(INDIRECT("'"&$B11&"'!C16"),"") | AI11: =IFERROR(INDIRECT("'"&$B11&"'!D16"),"") | AJ11: =IFERROR(INDIRECT("'"&$B11&"'!C17"),"") | AK11: =IFERROR(INDIRECT("'"&$B11&"'!D17"),"") | AL11: =IFERROR(INDIRECT("'"&$B11&"'!C18"),"") | AM11: =IFERROR(INDIRECT("'"&$B11&"'!D18"),"") | AN11: =IFERROR(INDIRECT("'"&$B11&"'!C19"),"") | AO11: =IFERROR(INDIRECT("'"&$B11&"'!D19"),"") | AP11: =IFERROR(INDIRECT("'"&$B11&"'!C20"),"") | AQ11: =IFERROR(INDIRECT("'"&$B11&"'!D20"),"") | AR11: =IFERROR(INDIRECT("'"&$B11&"'!C21"),"") | AS11: =IFERROR(INDIRECT("'"&$B11&"'!D21"),"")
A12: 2 | B12: Andrea | C12: =IFERROR(INDIRECT("'"&$B12&"'!A7"),"") | D12: =IFERROR(INDIRECT("'"&$B12&"'!A9"),"") | E12: =IFERROR(INDIRECT("'"&$B12&"'!F7"),"") | F12: =IFERROR(INDIRECT("'"&$B12&"'!H7"),"") | G12: =IFERROR(INDIRECT("'"&$B12&"'!J7"),"") | H12: =IFERROR(INDIRECT("'"&$B12&"'!H9"),"") | I12: =IFERROR(INDIRECT("'"&$B12&"'!J9"),"") | J12: =IFERROR(INDIRECT("'"&$B12&"'!A13"),"") | K12: =IFERROR(INDIRECT("'"&$B12&"'!C13"),"") | L12: =IFERROR(INDIRECT("'"&$B12&"'!I24"),"") | M12: =IFERROR(INDIRECT("'"&$B12&"'!E13"),"") | N12: =IFERROR(INDIRECT("'"&$B12&"'!G13"),"") | O12: =IFERROR(INDIRECT("'"&$B12&"'!H13"),"") | P12: =IF(OR($N12="",$O12=""),"",ROUND(($N12-$O12)*100,1)) | Q12: =IFERROR(INDIRECT("'"&$B12&"'!I13"),"") | R12: =IF($N12="","",IF($N12>=0.35,"Margem boa",IF($N12>=0.25,"Margem apertada","Margem crítica"))) | AH12: =IFERROR(INDIRECT("'"&$B12&"'!C16"),"") | AI12: =IFERROR(INDIRECT("'"&$B12&"'!D16"),"") | AJ12: =IFERROR(INDIRECT("'"&$B12&"'!C17"),"") | AK12: =IFERROR(INDIRECT("'"&$B12&"'!D17"),"") | AL12: =IFERROR(INDIRECT("'"&$B12&"'!C18"),"") | AM12: =IFERROR(INDIRECT("'"&$B12&"'!D18"),"") | AN12: =IFERROR(INDIRECT("'"&$B12&"'!C19"),"") | AO12: =IFERROR(INDIRECT("'"&$B12&"'!D19"),"") | AP12: =IFERROR(INDIRECT("'"&$B12&"'!C20"),"") | AQ12: =IFERROR(INDIRECT("'"&$B12&"'!D20"),"") | AR12: =IFERROR(INDIRECT("'"&$B12&"'!C21"),"") | AS12: =IFERROR(INDIRECT("'"&$B12&"'!D21"),"")
A13: 3 | B13: Cristiane Chrys Andrade | C13: =IFERROR(INDIRECT("'"&$B13&"'!A7"),"") | D13: =IFERROR(INDIRECT("'"&$B13&"'!A9"),"") | E13: =IFERROR(INDIRECT("'"&$B13&"'!F7"),"") | F13: =IFERROR(INDIRECT("'"&$B13&"'!H7"),"") | G13: =IFERROR(INDIRECT("'"&$B13&"'!J7"),"") | H13: =IFERROR(INDIRECT("'"&$B13&"'!H9"),"") | I13: =IFERROR(INDIRECT("'"&$B13&"'!J9"),"") | J13: =IFERROR(INDIRECT("'"&$B13&"'!A13"),"") | K13: =IFERROR(INDIRECT("'"&$B13&"'!C13"),"") | L13: =IFERROR(INDIRECT("'"&$B13&"'!I24"),"") | M13: =IFERROR(INDIRECT("'"&$B13&"'!E13"),"") | N13: =IFERROR(INDIRECT("'"&$B13&"'!G13"),"") | O13: =IFERROR(INDIRECT("'"&$B13&"'!H13"),"") | P13: =IF(OR($N13="",$O13=""),"",ROUND(($N13-$O13)*100,1)) | Q13: =IFERROR(INDIRECT("'"&$B13&"'!I13"),"") | R13: =IF($N13="","",IF($N13>=0.35,"Margem boa",IF($N13>=0.25,"Margem apertada","Margem crítica"))) | AH13: =IFERROR(INDIRECT("'"&$B13&"'!C16"),"") | AI13: =IFERROR(INDIRECT("'"&$B13&"'!D16"),"") | AJ13: =IFERROR(INDIRECT("'"&$B13&"'!C17"),"") | AK13: =IFERROR(INDIRECT("'"&$B13&"'!D17"),"") | AL13: =IFERROR(INDIRECT("'"&$B13&"'!C18"),"") | AM13: =IFERROR(INDIRECT("'"&$B13&"'!D18"),"") | AN13: =IFERROR(INDIRECT("'"&$B13&"'!C19"),"") | AO13: =IFERROR(INDIRECT("'"&$B13&"'!D19"),"") | AP13: =IFERROR(INDIRECT("'"&$B13&"'!C20"),"") | AQ13: =IFERROR(INDIRECT("'"&$B13&"'!D20"),"") | AR13: =IFERROR(INDIRECT("'"&$B13&"'!C21"),"") | AS13: =IFERROR(INDIRECT("'"&$B13&"'!D21"),"")
A14: 4 | B14: EPE Formas | C14: =IFERROR(INDIRECT("'"&$B14&"'!A7"),"") | D14: =IFERROR(INDIRECT("'"&$B14&"'!A9"),"") | E14: =IFERROR(INDIRECT("'"&$B14&"'!F7"),"") | F14: =IFERROR(INDIRECT("'"&$B14&"'!H7"),"") | G14: =IFERROR(INDIRECT("'"&$B14&"'!J7"),"") | H14: =IFERROR(INDIRECT("'"&$B14&"'!H9"),"") | I14: =IFERROR(INDIRECT("'"&$B14&"'!J9"),"") | J14: =IFERROR(INDIRECT("'"&$B14&"'!A13"),"") | K14: =IFERROR(INDIRECT("'"&$B14&"'!C13"),"") | L14: =IFERROR(INDIRECT("'"&$B14&"'!I24"),"") | M14: =IFERROR(INDIRECT("'"&$B14&"'!E13"),"") | N14: =IFERROR(INDIRECT("'"&$B14&"'!G13"),"") | O14: =IFERROR(INDIRECT("'"&$B14&"'!H13"),"") | P14: =IF(OR($N14="",$O14=""),"",ROUND(($N14-$O14)*100,1)) | Q14: =IFERROR(INDIRECT("'"&$B14&"'!I13"),"") | R14: =IF($N14="","",IF($N14>=0.35,"Margem boa",IF($N14>=0.25,"Margem apertada","Margem crítica"))) | AH14: =IFERROR(INDIRECT("'"&$B14&"'!C16"),"") | AI14: =IFERROR(INDIRECT("'"&$B14&"'!D16"),"") | AJ14: =IFERROR(INDIRECT("'"&$B14&"'!C17"),"") | AK14: =IFERROR(INDIRECT("'"&$B14&"'!D17"),"") | AL14: =IFERROR(INDIRECT("'"&$B14&"'!C18"),"") | AM14: =IFERROR(INDIRECT("'"&$B14&"'!D18"),"") | AN14: =IFERROR(INDIRECT("'"&$B14&"'!C19"),"") | AO14: =IFERROR(INDIRECT("'"&$B14&"'!D19"),"") | AP14: =IFERROR(INDIRECT("'"&$B14&"'!C20"),"") | AQ14: =IFERROR(INDIRECT("'"&$B14&"'!D20"),"") | AR14: =IFERROR(INDIRECT("'"&$B14&"'!C21"),"") | AS14: =IFERROR(INDIRECT("'"&$B14&"'!D21"),"")
A15: 5 | B15: Flavia | C15: =IFERROR(INDIRECT("'"&$B15&"'!A7"),"") | D15: =IFERROR(INDIRECT("'"&$B15&"'!A9"),"") | E15: =IFERROR(INDIRECT("'"&$B15&"'!F7"),"") | F15: =IFERROR(INDIRECT("'"&$B15&"'!H7"),"") | G15: =IFERROR(INDIRECT("'"&$B15&"'!J7"),"") | H15: =IFERROR(INDIRECT("'"&$B15&"'!H9"),"") | I15: =IFERROR(INDIRECT("'"&$B15&"'!J9"),"") | J15: =IFERROR(INDIRECT("'"&$B15&"'!A13"),"") | K15: =IFERROR(INDIRECT("'"&$B15&"'!C13"),"") | L15: =IFERROR(INDIRECT("'"&$B15&"'!I24"),"") | M15: =IFERROR(INDIRECT("'"&$B15&"'!E13"),"") | N15: =IFERROR(INDIRECT("'"&$B15&"'!G13"),"") | O15: =IFERROR(INDIRECT("'"&$B15&"'!H13"),"") | P15: =IF(OR($N15="",$O15=""),"",ROUND(($N15-$O15)*100,1)) | Q15: =IFERROR(INDIRECT("'"&$B15&"'!I13"),"") | R15: =IF($N15="","",IF($N15>=0.35,"Margem boa",IF($N15>=0.25,"Margem apertada","Margem crítica"))) | AH15: =IFERROR(INDIRECT("'"&$B15&"'!C16"),"") | AI15: =IFERROR(INDIRECT("'"&$B15&"'!D16"),"") | AJ15: =IFERROR(INDIRECT("'"&$B15&"'!C17"),"") | AK15: =IFERROR(INDIRECT("'"&$B15&"'!D17"),"") | AL15: =IFERROR(INDIRECT("'"&$B15&"'!C18"),"") | AM15: =IFERROR(INDIRECT("'"&$B15&"'!D18"),"") | AN15: =IFERROR(INDIRECT("'"&$B15&"'!C19"),"") | AO15: =IFERROR(INDIRECT("'"&$B15&"'!D19"),"") | AP15: =IFERROR(INDIRECT("'"&$B15&"'!C20"),"") | AQ15: =IFERROR(INDIRECT("'"&$B15&"'!D20"),"") | AR15: =IFERROR(INDIRECT("'"&$B15&"'!C21"),"") | AS15: =IFERROR(INDIRECT("'"&$B15&"'!D21"),"")
A16: 6 | B16: Jairo | C16: =IFERROR(INDIRECT("'"&$B16&"'!A7"),"") | D16: =IFERROR(INDIRECT("'"&$B16&"'!A9"),"") | E16: =IFERROR(INDIRECT("'"&$B16&"'!F7"),"") | F16: =IFERROR(INDIRECT("'"&$B16&"'!H7"),"") | G16: =IFERROR(INDIRECT("'"&$B16&"'!J7"),"") | H16: =IFERROR(INDIRECT("'"&$B16&"'!H9"),"") | I16: =IFERROR(INDIRECT("'"&$B16&"'!J9"),"") | J16: =IFERROR(INDIRECT("'"&$B16&"'!A13"),"") | K16: =IFERROR(INDIRECT("'"&$B16&"'!C13"),"") | L16: =IFERROR(INDIRECT("'"&$B16&"'!I24"),"") | M16: =IFERROR(INDIRECT("'"&$B16&"'!E13"),"") | N16: =IFERROR(INDIRECT("'"&$B16&"'!G13"),"") | O16: =IFERROR(INDIRECT("'"&$B16&"'!H13"),"") | P16: =IF(OR($N16="",$O16=""),"",ROUND(($N16-$O16)*100,1)) | Q16: =IFERROR(INDIRECT("'"&$B16&"'!I13"),"") | R16: =IF($N16="","",IF($N16>=0.35,"Margem boa",IF($N16>=0.25,"Margem apertada","Margem crítica"))) | AH16: =IFERROR(INDIRECT("'"&$B16&"'!C16"),"") | AI16: =IFERROR(INDIRECT("'"&$B16&"'!D16"),"") | AJ16: =IFERROR(INDIRECT("'"&$B16&"'!C17"),"") | AK16: =IFERROR(INDIRECT("'"&$B16&"'!D17"),"") | AL16: =IFERROR(INDIRECT("'"&$B16&"'!C18"),"") | AM16: =IFERROR(INDIRECT("'"&$B16&"'!D18"),"") | AN16: =IFERROR(INDIRECT("'"&$B16&"'!C19"),"") | AO16: =IFERROR(INDIRECT("'"&$B16&"'!D19"),"") | AP16: =IFERROR(INDIRECT("'"&$B16&"'!C20"),"") | AQ16: =IFERROR(INDIRECT("'"&$B16&"'!D20"),"") | AR16: =IFERROR(INDIRECT("'"&$B16&"'!C21"),"") | AS16: =IFERROR(INDIRECT("'"&$B16&"'!D21"),"")
A17: 7 | B17: Graciene | C17: =IFERROR(INDIRECT("'"&$B17&"'!A7"),"") | D17: =IFERROR(INDIRECT("'"&$B17&"'!A9"),"") | E17: =IFERROR(INDIRECT("'"&$B17&"'!F7"),"") | F17: =IFERROR(INDIRECT("'"&$B17&"'!H7"),"") | G17: =IFERROR(INDIRECT("'"&$B17&"'!J7"),"") | H17: =IFERROR(INDIRECT("'"&$B17&"'!H9"),"") | I17: =IFERROR(INDIRECT("'"&$B17&"'!J9"),"") | J17: =IFERROR(INDIRECT("'"&$B17&"'!A13"),"") | K17: =IFERROR(INDIRECT("'"&$B17&"'!C13"),"") | L17: =IFERROR(INDIRECT("'"&$B17&"'!I24"),"") | M17: =IFERROR(INDIRECT("'"&$B17&"'!E13"),"") | N17: =IFERROR(INDIRECT("'"&$B17&"'!G13"),"") | O17: =IFERROR(INDIRECT("'"&$B17&"'!H13"),"") | P17: =IF(OR($N17="",$O17=""),"",ROUND(($N17-$O17)*100,1)) | Q17: =IFERROR(INDIRECT("'"&$B17&"'!I13"),"") | R17: =IF($N17="","",IF($N17>=0.35,"Margem boa",IF($N17>=0.25,"Margem apertada","Margem crítica"))) | AH17: =IFERROR(INDIRECT("'"&$B17&"'!C16"),"") | AI17: =IFERROR(INDIRECT("'"&$B17&"'!D16"),"") | AJ17: =IFERROR(INDIRECT("'"&$B17&"'!C17"),"") | AK17: =IFERROR(INDIRECT("'"&$B17&"'!D17"),"") | AL17: =IFERROR(INDIRECT("'"&$B17&"'!C18"),"") | AM17: =IFERROR(INDIRECT("'"&$B17&"'!D18"),"") | AN17: =IFERROR(INDIRECT("'"&$B17&"'!C19"),"") | AO17: =IFERROR(INDIRECT("'"&$B17&"'!D19"),"") | AP17: =IFERROR(INDIRECT("'"&$B17&"'!C20"),"") | AQ17: =IFERROR(INDIRECT("'"&$B17&"'!D20"),"") | AR17: =IFERROR(INDIRECT("'"&$B17&"'!C21"),"") | AS17: =IFERROR(INDIRECT("'"&$B17&"'!D21"),"")
A18: 8 | B18: Larissa | C18: =IFERROR(INDIRECT("'"&$B18&"'!A7"),"") | D18: =IFERROR(INDIRECT("'"&$B18&"'!A9"),"") | E18: =IFERROR(INDIRECT("'"&$B18&"'!F7"),"") | F18: =IFERROR(INDIRECT("'"&$B18&"'!H7"),"") | G18: =IFERROR(INDIRECT("'"&$B18&"'!J7"),"") | H18: =IFERROR(INDIRECT("'"&$B18&"'!H9"),"") | I18: =IFERROR(INDIRECT("'"&$B18&"'!J9"),"") | J18: =IFERROR(INDIRECT("'"&$B18&"'!A13"),"") | K18: =IFERROR(INDIRECT("'"&$B18&"'!C13"),"") | L18: =IFERROR(INDIRECT("'"&$B18&"'!I24"),"") | M18: =IFERROR(INDIRECT("'"&$B18&"'!E13"),"") | N18: =IFERROR(INDIRECT("'"&$B18&"'!G13"),"") | O18: =IFERROR(INDIRECT("'"&$B18&"'!H13"),"") | P18: =IF(OR($N18="",$O18=""),"",ROUND(($N18-$O18)*100,1)) | Q18: =IFERROR(INDIRECT("'"&$B18&"'!I13"),"") | R18: =IF($N18="","",IF($N18>=0.35,"Margem boa",IF($N18>=0.25,"Margem apertada","Margem crítica"))) | AH18: =IFERROR(INDIRECT("'"&$B18&"'!C16"),"") | AI18: =IFERROR(INDIRECT("'"&$B18&"'!D16"),"") | AJ18: =IFERROR(INDIRECT("'"&$B18&"'!C17"),"") | AK18: =IFERROR(INDIRECT("'"&$B18&"'!D17"),"") | AL18: =IFERROR(INDIRECT("'"&$B18&"'!C18"),"") | AM18: =IFERROR(INDIRECT("'"&$B18&"'!D18"),"") | AN18: =IFERROR(INDIRECT("'"&$B18&"'!C19"),"") | AO18: =IFERROR(INDIRECT("'"&$B18&"'!D19"),"") | AP18: =IFERROR(INDIRECT("'"&$B18&"'!C20"),"") | AQ18: =IFERROR(INDIRECT("'"&$B18&"'!D20"),"") | AR18: =IFERROR(INDIRECT("'"&$B18&"'!C21"),"") | AS18: =IFERROR(INDIRECT("'"&$B18&"'!D21"),"")
A19: 9 | B19: Leonardo | C19: =IFERROR(INDIRECT("'"&$B19&"'!A7"),"") | D19: =IFERROR(INDIRECT("'"&$B19&"'!A9"),"") | E19: =IFERROR(INDIRECT("'"&$B19&"'!F7"),"") | F19: =IFERROR(INDIRECT("'"&$B19&"'!H7"),"") | G19: =IFERROR(INDIRECT("'"&$B19&"'!J7"),"") | H19: =IFERROR(INDIRECT("'"&$B19&"'!H9"),"") | I19: =IFERROR(INDIRECT("'"&$B19&"'!J9"),"") | J19: =IFERROR(INDIRECT("'"&$B19&"'!A13"),"") | K19: =IFERROR(INDIRECT("'"&$B19&"'!C13"),"") | L19: =IFERROR(INDIRECT("'"&$B19&"'!I24"),"") | M19: =IFERROR(INDIRECT("'"&$B19&"'!E13"),"") | N19: =IFERROR(INDIRECT("'"&$B19&"'!G13"),"") | O19: =IFERROR(INDIRECT("'"&$B19&"'!H13"),"") | P19: =IF(OR($N19="",$O19=""),"",ROUND(($N19-$O19)*100,1)) | Q19: =IFERROR(INDIRECT("'"&$B19&"'!I13"),"") | R19: =IF($N19="","",IF($N19>=0.35,"Margem boa",IF($N19>=0.25,"Margem apertada","Margem crítica"))) | AH19: =IFERROR(INDIRECT("'"&$B19&"'!C16"),"") | AI19: =IFERROR(INDIRECT("'"&$B19&"'!D16"),"") | AJ19: =IFERROR(INDIRECT("'"&$B19&"'!C17"),"") | AK19: =IFERROR(INDIRECT("'"&$B19&"'!D17"),"") | AL19: =IFERROR(INDIRECT("'"&$B19&"'!C18"),"") | AM19: =IFERROR(INDIRECT("'"&$B19&"'!D18"),"") | AN19: =IFERROR(INDIRECT("'"&$B19&"'!C19"),"") | AO19: =IFERROR(INDIRECT("'"&$B19&"'!D19"),"") | AP19: =IFERROR(INDIRECT("'"&$B19&"'!C20"),"") | AQ19: =IFERROR(INDIRECT("'"&$B19&"'!D20"),"") | AR19: =IFERROR(INDIRECT("'"&$B19&"'!C21"),"") | AS19: =IFERROR(INDIRECT("'"&$B19&"'!D21"),"")
A20: 10 | B20: Luiz | C20: =IFERROR(INDIRECT("'"&$B20&"'!A7"),"") | D20: =IFERROR(INDIRECT("'"&$B20&"'!A9"),"") | E20: =IFERROR(INDIRECT("'"&$B20&"'!F7"),"") | F20: =IFERROR(INDIRECT("'"&$B20&"'!H7"),"") | G20: =IFERROR(INDIRECT("'"&$B20&"'!J7"),"") | H20: =IFERROR(INDIRECT("'"&$B20&"'!H9"),"") | I20: =IFERROR(INDIRECT("'"&$B20&"'!J9"),"") | J20: =IFERROR(INDIRECT("'"&$B20&"'!A13"),"") | K20: =IFERROR(INDIRECT("'"&$B20&"'!C13"),"") | L20: =IFERROR(INDIRECT("'"&$B20&"'!I24"),"") | M20: =IFERROR(INDIRECT("'"&$B20&"'!E13"),"") | N20: =IFERROR(INDIRECT("'"&$B20&"'!G13"),"") | O20: =IFERROR(INDIRECT("'"&$B20&"'!H13"),"") | P20: =IF(OR($N20="",$O20=""),"",ROUND(($N20-$O20)*100,1)) | Q20: =IFERROR(INDIRECT("'"&$B20&"'!I13"),"") | R20: =IF($N20="","",IF($N20>=0.35,"Margem boa",IF($N20>=0.25,"Margem apertada","Margem crítica"))) | AH20: =IFERROR(INDIRECT("'"&$B20&"'!C16"),"") | AI20: =IFERROR(INDIRECT("'"&$B20&"'!D16"),"") | AJ20: =IFERROR(INDIRECT("'"&$B20&"'!C17"),"") | AK20: =IFERROR(INDIRECT("'"&$B20&"'!D17"),"") | AL20: =IFERROR(INDIRECT("'"&$B20&"'!C18"),"") | AM20: =IFERROR(INDIRECT("'"&$B20&"'!D18"),"") | AN20: =IFERROR(INDIRECT("'"&$B20&"'!C19"),"") | AO20: =IFERROR(INDIRECT("'"&$B20&"'!D19"),"") | AP20: =IFERROR(INDIRECT("'"&$B20&"'!C20"),"") | AQ20: =IFERROR(INDIRECT("'"&$B20&"'!D20"),"") | AR20: =IFERROR(INDIRECT("'"&$B20&"'!C21"),"") | AS20: =IFERROR(INDIRECT("'"&$B20&"'!D21"),"")
A21: 11 | B21: Carla Dresller | C21: =IFERROR(INDIRECT("'"&$B21&"'!A7"),"") | D21: =IFERROR(INDIRECT("'"&$B21&"'!A9"),"") | E21: =IFERROR(INDIRECT("'"&$B21&"'!F7"),"") | F21: =IFERROR(INDIRECT("'"&$B21&"'!H7"),"") | G21: =IFERROR(INDIRECT("'"&$B21&"'!J7"),"") | H21: =IFERROR(INDIRECT("'"&$B21&"'!H9"),"") | I21: =IFERROR(INDIRECT("'"&$B21&"'!J9"),"") | J21: =IFERROR(INDIRECT("'"&$B21&"'!A13"),"") | K21: =IFERROR(INDIRECT("'"&$B21&"'!C13"),"") | L21: =IFERROR(INDIRECT("'"&$B21&"'!I24"),"") | M21: =IFERROR(INDIRECT("'"&$B21&"'!E13"),"") | N21: =IFERROR(INDIRECT("'"&$B21&"'!G13"),"") | O21: =IFERROR(INDIRECT("'"&$B21&"'!H13"),"") | P21: =IF(OR($N21="",$O21=""),"",ROUND(($N21-$O21)*100,1)) | Q21: =IFERROR(INDIRECT("'"&$B21&"'!I13"),"") | R21: =IF($N21="","",IF($N21>=0.35,"Margem boa",IF($N21>=0.25,"Margem apertada","Margem crítica"))) | AH21: =IFERROR(INDIRECT("'"&$B21&"'!C16"),"") | AI21: =IFERROR(INDIRECT("'"&$B21&"'!D16"),"") | AJ21: =IFERROR(INDIRECT("'"&$B21&"'!C17"),"") | AK21: =IFERROR(INDIRECT("'"&$B21&"'!D17"),"") | AL21: =IFERROR(INDIRECT("'"&$B21&"'!C18"),"") | AM21: =IFERROR(INDIRECT("'"&$B21&"'!D18"),"") | AN21: =IFERROR(INDIRECT("'"&$B21&"'!C19"),"") | AO21: =IFERROR(INDIRECT("'"&$B21&"'!D19"),"") | AP21: =IFERROR(INDIRECT("'"&$B21&"'!C20"),"") | AQ21: =IFERROR(INDIRECT("'"&$B21&"'!D20"),"") | AR21: =IFERROR(INDIRECT("'"&$B21&"'!C21"),"") | AS21: =IFERROR(INDIRECT("'"&$B21&"'!D21"),"")
A22: 12 | B22: Maria | C22: =IFERROR(INDIRECT("'"&$B22&"'!A7"),"") | D22: =IFERROR(INDIRECT("'"&$B22&"'!A9"),"") | E22: =IFERROR(INDIRECT("'"&$B22&"'!F7"),"") | F22: =IFERROR(INDIRECT("'"&$B22&"'!H7"),"") | G22: =IFERROR(INDIRECT("'"&$B22&"'!J7"),"") | H22: =IFERROR(INDIRECT("'"&$B22&"'!H9"),"") | I22: =IFERROR(INDIRECT("'"&$B22&"'!J9"),"") | J22: =IFERROR(INDIRECT("'"&$B22&"'!A13"),"") | K22: =IFERROR(INDIRECT("'"&$B22&"'!C13"),"") | L22: =IFERROR(INDIRECT("'"&$B22&"'!I24"),"") | M22: =IFERROR(INDIRECT("'"&$B22&"'!E13"),"") | N22: =IFERROR(INDIRECT("'"&$B22&"'!G13"),"") | O22: =IFERROR(INDIRECT("'"&$B22&"'!H13"),"") | P22: =IF(OR($N22="",$O22=""),"",ROUND(($N22-$O22)*100,1)) | Q22: =IFERROR(INDIRECT("'"&$B22&"'!I13"),"") | R22: =IF($N22="","",IF($N22>=0.35,"Margem boa",IF($N22>=0.25,"Margem apertada","Margem crítica"))) | AH22: =IFERROR(INDIRECT("'"&$B22&"'!C16"),"") | AI22: =IFERROR(INDIRECT("'"&$B22&"'!D16"),"") | AJ22: =IFERROR(INDIRECT("'"&$B22&"'!C17"),"") | AK22: =IFERROR(INDIRECT("'"&$B22&"'!D17"),"") | AL22: =IFERROR(INDIRECT("'"&$B22&"'!C18"),"") | AM22: =IFERROR(INDIRECT("'"&$B22&"'!D18"),"") | AN22: =IFERROR(INDIRECT("'"&$B22&"'!C19"),"") | AO22: =IFERROR(INDIRECT("'"&$B22&"'!D19"),"") | AP22: =IFERROR(INDIRECT("'"&$B22&"'!C20"),"") | AQ22: =IFERROR(INDIRECT("'"&$B22&"'!D20"),"") | AR22: =IFERROR(INDIRECT("'"&$B22&"'!C21"),"") | AS22: =IFERROR(INDIRECT("'"&$B22&"'!D21"),"")
... A27: 17 | B27: Exemplo P-2026-041 | C27: =IFERROR(INDIRECT("'"&$B27&"'!A7"),"") | D27: =IFERROR(INDIRECT("'"&$B27&"'!A9"),"") | E27: =IFERROR(INDIRECT("'"&$B27&"'!F7"),"") | F27: =IFERROR(INDIRECT("'"&$B27&"'!H7"),"") | G27: =IFERROR(INDIRECT("'"&$B27&"'!J7"),"") | H27: =IFERROR(INDIRECT("'"&$B27&"'!H9"),"") | I27: =IFERROR(INDIRECT("'"&$B27&"'!J9"),"") | J27: =IFERROR(INDIRECT("'"&$B27&"'!A13"),"") | K27: =IFERROR(INDIRECT("'"&$B27&"'!C13"),"") | L27: =IFERROR(INDIRECT("'"&$B27&"'!I24"),"") | M27: =IFERROR(INDIRECT("'"&$B27&"'!E13"),"") | N27: =IFERROR(INDIRECT("'"&$B27&"'!G13"),"") | O27: =IFERROR(INDIRECT("'"&$B27&"'!H13"),"") | P27: =IF(OR($N27="",$O27=""),"",ROUND(($N27-$O27)*100,1)) | Q27: =IFERROR(INDIRECT("'"&$B27&"'!I13"),"") | R27: =IF($N27="","",IF($N27>=0.35,"Margem boa",IF($N27>=0.25,"Margem apertada","Margem crítica"))) | AH27: =IFERROR(INDIRECT("'"&$B27&"'!C16"),"") | AI27: =IFERROR(INDIRECT("'"&$B27&"'!D16"),"") | AJ27: =IFERROR(INDIRECT("'"&$B27&"'!C17"),"") | AK27: =IFERROR(INDIRECT("'"&$B27&"'!D17"),"") | AL27: =IFERROR(INDIRECT("'"&$B27&"'!C18"),"") | AM27: =IFERROR(INDIRECT("'"&$B27&"'!D18"),"") | AN27: =IFERROR(INDIRECT("'"&$B27&"'!C19"),"") | AO27: =IFERROR(INDIRECT("'"&$B27&"'!D19"),"") | AP27: =IFERROR(INDIRECT("'"&$B27&"'!C20"),"") | AQ27: =IFERROR(INDIRECT("'"&$B27&"'!D20"),"") | AR27: =IFERROR(INDIRECT("'"&$B27&"'!C21"),"") | AS27: =IFERROR(INDIRECT("'"&$B27&"'!D21"),"")
A28: 18 | C28: =IFERROR(INDIRECT("'"&$B28&"'!A7"),"") | D28: =IFERROR(INDIRECT("'"&$B28&"'!A9"),"") | E28: =IFERROR(INDIRECT("'"&$B28&"'!F7"),"") | F28: =IFERROR(INDIRECT("'"&$B28&"'!H7"),"") | G28: =IFERROR(INDIRECT("'"&$B28&"'!J7"),"") | H28: =IFERROR(INDIRECT("'"&$B28&"'!H9"),"") | I28: =IFERROR(INDIRECT("'"&$B28&"'!J9"),"") | J28: =IFERROR(INDIRECT("'"&$B28&"'!A13"),"") | K28: =IFERROR(INDIRECT("'"&$B28&"'!C13"),"") | L28: =IFERROR(INDIRECT("'"&$B28&"'!I24"),"") | M28: =IFERROR(INDIRECT("'"&$B28&"'!E13"),"") | N28: =IFERROR(INDIRECT("'"&$B28&"'!G13"),"") | O28: =IFERROR(INDIRECT("'"&$B28&"'!H13"),"") | P28: =IF(OR($N28="",$O28=""),"",ROUND(($N28-$O28)*100,1)) | Q28: =IFERROR(INDIRECT("'"&$B28&"'!I13"),"") | R28: =IF($N28="","",IF($N28>=0.35,"Margem boa",IF($N28>=0.25,"Margem apertada","Margem crítica"))) | AH28: =IFERROR(INDIRECT("'"&$B28&"'!C16"),"") | AI28: =IFERROR(INDIRECT("'"&$B28&"'!D16"),"") | AJ28: =IFERROR(INDIRECT("'"&$B28&"'!C17"),"") | AK28: =IFERROR(INDIRECT("'"&$B28&"'!D17"),"") | AL28: =IFERROR(INDIRECT("'"&$B28&"'!C18"),"") | AM28: =IFERROR(INDIRECT("'"&$B28&"'!D18"),"") | AN28: =IFERROR(INDIRECT("'"&$B28&"'!C19"),"") | AO28: =IFERROR(INDIRECT("'"&$B28&"'!D19"),"") | AP28: =IFERROR(INDIRECT("'"&$B28&"'!C20"),"") | AQ28: =IFERROR(INDIRECT("'"&$B28&"'!D20"),"") | AR28: =IFERROR(INDIRECT("'"&$B28&"'!C21"),"") | AS28: =IFERROR(INDIRECT("'"&$B28&"'!D21"),"")
A29: 19 | C29: =IFERROR(INDIRECT("'"&$B29&"'!A7"),"") | D29: =IFERROR(INDIRECT("'"&$B29&"'!A9"),"") | E29: =IFERROR(INDIRECT("'"&$B29&"'!F7"),"") | F29: =IFERROR(INDIRECT("'"&$B29&"'!H7"),"") | G29: =IFERROR(INDIRECT("'"&$B29&"'!J7"),"") | H29: =IFERROR(INDIRECT("'"&$B29&"'!H9"),"") | I29: =IFERROR(INDIRECT("'"&$B29&"'!J9"),"") | J29: =IFERROR(INDIRECT("'"&$B29&"'!A13"),"") | K29: =IFERROR(INDIRECT("'"&$B29&"'!C13"),"") | L29: =IFERROR(INDIRECT("'"&$B29&"'!I24"),"") | M29: =IFERROR(INDIRECT("'"&$B29&"'!E13"),"") | N29: =IFERROR(INDIRECT("'"&$B29&"'!G13"),"") | O29: =IFERROR(INDIRECT("'"&$B29&"'!H13"),"") | P29: =IF(OR($N29="",$O29=""),"",ROUND(($N29-$O29)*100,1)) | Q29: =IFERROR(INDIRECT("'"&$B29&"'!I13"),"") | R29: =IF($N29="","",IF($N29>=0.35,"Margem boa",IF($N29>=0.25,"Margem apertada","Margem crítica"))) | AH29: =IFERROR(INDIRECT("'"&$B29&"'!C16"),"") | AI29: =IFERROR(INDIRECT("'"&$B29&"'!D16"),"") | AJ29: =IFERROR(INDIRECT("'"&$B29&"'!C17"),"") | AK29: =IFERROR(INDIRECT("'"&$B29&"'!D17"),"") | AL29: =IFERROR(INDIRECT("'"&$B29&"'!C18"),"") | AM29: =IFERROR(INDIRECT("'"&$B29&"'!D18"),"") | AN29: =IFERROR(INDIRECT("'"&$B29&"'!C19"),"") | AO29: =IFERROR(INDIRECT("'"&$B29&"'!D19"),"") | AP29: =IFERROR(INDIRECT("'"&$B29&"'!C20"),"") | AQ29: =IFERROR(INDIRECT("'"&$B29&"'!D20"),"") | AR29: =IFERROR(INDIRECT("'"&$B29&"'!C21"),"") | AS29: =IFERROR(INDIRECT("'"&$B29&"'!D21"),"")
A30: 20 | C30: =IFERROR(INDIRECT("'"&$B30&"'!A7"),"") | D30: =IFERROR(INDIRECT("'"&$B30&"'!A9"),"") | E30: =IFERROR(INDIRECT("'"&$B30&"'!F7"),"") | F30: =IFERROR(INDIRECT("'"&$B30&"'!H7"),"") | G30: =IFERROR(INDIRECT("'"&$B30&"'!J7"),"") | H30: =IFERROR(INDIRECT("'"&$B30&"'!H9"),"") | I30: =IFERROR(INDIRECT("'"&$B30&"'!J9"),"") | J30: =IFERROR(INDIRECT("'"&$B30&"'!A13"),"") | K30: =IFERROR(INDIRECT("'"&$B30&"'!C13"),"") | L30: =IFERROR(INDIRECT("'"&$B30&"'!I24"),"") | M30: =IFERROR(INDIRECT("'"&$B30&"'!E13"),"") | N30: =IFERROR(INDIRECT("'"&$B30&"'!G13"),"") | O30: =IFERROR(INDIRECT("'"&$B30&"'!H13"),"") | P30: =IF(OR($N30="",$O30=""),"",ROUND(($N30-$O30)*100,1)) | Q30: =IFERROR(INDIRECT("'"&$B30&"'!I13"),"") | R30: =IF($N30="","",IF($N30>=0.35,"Margem boa",IF($N30>=0.25,"Margem apertada","Margem crítica"))) | AH30: =IFERROR(INDIRECT("'"&$B30&"'!C16"),"") | AI30: =IFERROR(INDIRECT("'"&$B30&"'!D16"),"") | AJ30: =IFERROR(INDIRECT("'"&$B30&"'!C17"),"") | AK30: =IFERROR(INDIRECT("'"&$B30&"'!D17"),"") | AL30: =IFERROR(INDIRECT("'"&$B30&"'!C18"),"") | AM30: =IFERROR(INDIRECT("'"&$B30&"'!D18"),"") | AN30: =IFERROR(INDIRECT("'"&$B30&"'!C19"),"") | AO30: =IFERROR(INDIRECT("'"&$B30&"'!D19"),"") | AP30: =IFERROR(INDIRECT("'"&$B30&"'!C20"),"") | AQ30: =IFERROR(INDIRECT("'"&$B30&"'!D20"),"") | AR30: =IFERROR(INDIRECT("'"&$B30&"'!C21"),"") | AS30: =IFERROR(INDIRECT("'"&$B30&"'!D21"),"")
A31: 21 | C31: =IFERROR(INDIRECT("'"&$B31&"'!A7"),"") | D31: =IFERROR(INDIRECT("'"&$B31&"'!A9"),"") | E31: =IFERROR(INDIRECT("'"&$B31&"'!F7"),"") | F31: =IFERROR(INDIRECT("'"&$B31&"'!H7"),"") | G31: =IFERROR(INDIRECT("'"&$B31&"'!J7"),"") | H31: =IFERROR(INDIRECT("'"&$B31&"'!H9"),"") | I31: =IFERROR(INDIRECT("'"&$B31&"'!J9"),"") | J31: =IFERROR(INDIRECT("'"&$B31&"'!A13"),"") | K31: =IFERROR(INDIRECT("'"&$B31&"'!C13"),"") | L31: =IFERROR(INDIRECT("'"&$B31&"'!I24"),"") | M31: =IFERROR(INDIRECT("'"&$B31&"'!E13"),"") | N31: =IFERROR(INDIRECT("'"&$B31&"'!G13"),"") | O31: =IFERROR(INDIRECT("'"&$B31&"'!H13"),"") | P31: =IF(OR($N31="",$O31=""),"",ROUND(($N31-$O31)*100,1)) | Q31: =IFERROR(INDIRECT("'"&$B31&"'!I13"),"") | R31: =IF($N31="","",IF($N31>=0.35,"Margem boa",IF($N31>=0.25,"Margem apertada","Margem crítica"))) | AH31: =IFERROR(INDIRECT("'"&$B31&"'!C16"),"") | AI31: =IFERROR(INDIRECT("'"&$B31&"'!D16"),"") | AJ31: =IFERROR(INDIRECT("'"&$B31&"'!C17"),"") | AK31: =IFERROR(INDIRECT("'"&$B31&"'!D17"),"") | AL31: =IFERROR(INDIRECT("'"&$B31&"'!C18"),"") | AM31: =IFERROR(INDIRECT("'"&$B31&"'!D18"),"") | AN31: =IFERROR(INDIRECT("'"&$B31&"'!C19"),"") | AO31: =IFERROR(INDIRECT("'"&$B31&"'!D19"),"") | AP31: =IFERROR(INDIRECT("'"&$B31&"'!C20"),"") | AQ31: =IFERROR(INDIRECT("'"&$B31&"'!D20"),"") | AR31: =IFERROR(INDIRECT("'"&$B31&"'!C21"),"") | AS31: =IFERROR(INDIRECT("'"&$B31&"'!D21"),"")
A32: 22 | C32: =IFERROR(INDIRECT("'"&$B32&"'!A7"),"") | D32: =IFERROR(INDIRECT("'"&$B32&"'!A9"),"") | E32: =IFERROR(INDIRECT("'"&$B32&"'!F7"),"") | F32: =IFERROR(INDIRECT("'"&$B32&"'!H7"),"") | G32: =IFERROR(INDIRECT("'"&$B32&"'!J7"),"") | H32: =IFERROR(INDIRECT("'"&$B32&"'!H9"),"") | I32: =IFERROR(INDIRECT("'"&$B32&"'!J9"),"") | J32: =IFERROR(INDIRECT("'"&$B32&"'!A13"),"") | K32: =IFERROR(INDIRECT("'"&$B32&"'!C13"),"") | L32: =IFERROR(INDIRECT("'"&$B32&"'!I24"),"") | M32: =IFERROR(INDIRECT("'"&$B32&"'!E13"),"") | N32: =IFERROR(INDIRECT("'"&$B32&"'!G13"),"") | O32: =IFERROR(INDIRECT("'"&$B32&"'!H13"),"") | P32: =IF(OR($N32="",$O32=""),"",ROUND(($N32-$O32)*100,1)) | Q32: =IFERROR(INDIRECT("'"&$B32&"'!I13"),"") | R32: =IF($N32="","",IF($N32>=0.35,"Margem boa",IF($N32>=0.25,"Margem apertada","Margem crítica"))) | AH32: =IFERROR(INDIRECT("'"&$B32&"'!C16"),"") | AI32: =IFERROR(INDIRECT("'"&$B32&"'!D16"),"") | AJ32: =IFERROR(INDIRECT("'"&$B32&"'!C17"),"") | AK32: =IFERROR(INDIRECT("'"&$B32&"'!D17"),"") | AL32: =IFERROR(INDIRECT("'"&$B32&"'!C18"),"") | AM32: =IFERROR(INDIRECT("'"&$B32&"'!D18"),"") | AN32: =IFERROR(INDIRECT("'"&$B32&"'!C19"),"") | AO32: =IFERROR(INDIRECT("'"&$B32&"'!D19"),"") | AP32: =IFERROR(INDIRECT("'"&$B32&"'!C20"),"") | AQ32: =IFERROR(INDIRECT("'"&$B32&"'!D20"),"") | AR32: =IFERROR(INDIRECT("'"&$B32&"'!C21"),"") | AS32: =IFERROR(INDIRECT("'"&$B32&"'!D21"),"")
A33: 23 | C33: =IFERROR(INDIRECT("'"&$B33&"'!A7"),"") | D33: =IFERROR(INDIRECT("'"&$B33&"'!A9"),"") | E33: =IFERROR(INDIRECT("'"&$B33&"'!F7"),"") | F33: =IFERROR(INDIRECT("'"&$B33&"'!H7"),"") | G33: =IFERROR(INDIRECT("'"&$B33&"'!J7"),"") | H33: =IFERROR(INDIRECT("'"&$B33&"'!H9"),"") | I33: =IFERROR(INDIRECT("'"&$B33&"'!J9"),"") | J33: =IFERROR(INDIRECT("'"&$B33&"'!A13"),"") | K33: =IFERROR(INDIRECT("'"&$B33&"'!C13"),"") | L33: =IFERROR(INDIRECT("'"&$B33&"'!I24"),"") | M33: =IFERROR(INDIRECT("'"&$B33&"'!E13"),"") | N33: =IFERROR(INDIRECT("'"&$B33&"'!G13"),"") | O33: =IFERROR(INDIRECT("'"&$B33&"'!H13"),"") | P33: =IF(OR($N33="",$O33=""),"",ROUND(($N33-$O33)*100,1)) | Q33: =IFERROR(INDIRECT("'"&$B33&"'!I13"),"") | R33: =IF($N33="","",IF($N33>=0.35,"Margem boa",IF($N33>=0.25,"Margem apertada","Margem crítica"))) | AH33: =IFERROR(INDIRECT("'"&$B33&"'!C16"),"") | AI33: =IFERROR(INDIRECT("'"&$B33&"'!D16"),"") | AJ33: =IFERROR(INDIRECT("'"&$B33&"'!C17"),"") | AK33: =IFERROR(INDIRECT("'"&$B33&"'!D17"),"") | AL33: =IFERROR(INDIRECT("'"&$B33&"'!C18"),"") | AM33: =IFERROR(INDIRECT("'"&$B33&"'!D18"),"") | AN33: =IFERROR(INDIRECT("'"&$B33&"'!C19"),"") | AO33: =IFERROR(INDIRECT("'"&$B33&"'!D19"),"") | AP33: =IFERROR(INDIRECT("'"&$B33&"'!C20"),"") | AQ33: =IFERROR(INDIRECT("'"&$B33&"'!D20"),"") | AR33: =IFERROR(INDIRECT("'"&$B33&"'!C21"),"") | AS33: =IFERROR(INDIRECT("'"&$B33&"'!D21"),"")
A34: 24 | C34: =IFERROR(INDIRECT("'"&$B34&"'!A7"),"") | D34: =IFERROR(INDIRECT("'"&$B34&"'!A9"),"") | E34: =IFERROR(INDIRECT("'"&$B34&"'!F7"),"") | F34: =IFERROR(INDIRECT("'"&$B34&"'!H7"),"") | G34: =IFERROR(INDIRECT("'"&$B34&"'!J7"),"") | H34: =IFERROR(INDIRECT("'"&$B34&"'!H9"),"") | I34: =IFERROR(INDIRECT("'"&$B34&"'!J9"),"") | J34: =IFERROR(INDIRECT("'"&$B34&"'!A13"),"") | K34: =IFERROR(INDIRECT("'"&$B34&"'!C13"),"") | L34: =IFERROR(INDIRECT("'"&$B34&"'!I24"),"") | M34: =IFERROR(INDIRECT("'"&$B34&"'!E13"),"") | N34: =IFERROR(INDIRECT("'"&$B34&"'!G13"),"") | O34: =IFERROR(INDIRECT("'"&$B34&"'!H13"),"") | P34: =IF(OR($N34="",$O34=""),"",ROUND(($N34-$O34)*100,1)) | Q34: =IFERROR(INDIRECT("'"&$B34&"'!I13"),"") | R34: =IF($N34="","",IF($N34>=0.35,"Margem boa",IF($N34>=0.25,"Margem apertada","Margem crítica"))) | AH34: =IFERROR(INDIRECT("'"&$B34&"'!C16"),"") | AI34: =IFERROR(INDIRECT("'"&$B34&"'!D16"),"") | AJ34: =IFERROR(INDIRECT("'"&$B34&"'!C17"),"") | AK34: =IFERROR(INDIRECT("'"&$B34&"'!D17"),"") | AL34: =IFERROR(INDIRECT("'"&$B34&"'!C18"),"") | AM34: =IFERROR(INDIRECT("'"&$B34&"'!D18"),"") | AN34: =IFERROR(INDIRECT("'"&$B34&"'!C19"),"") | AO34: =IFERROR(INDIRECT("'"&$B34&"'!D19"),"") | AP34: =IFERROR(INDIRECT("'"&$B34&"'!C20"),"") | AQ34: =IFERROR(INDIRECT("'"&$B34&"'!D20"),"") | AR34: =IFERROR(INDIRECT("'"&$B34&"'!C21"),"") | AS34: =IFERROR(INDIRECT("'"&$B34&"'!D21"),"")
A35: 25 | C35: =IFERROR(INDIRECT("'"&$B35&"'!A7"),"") | D35: =IFERROR(INDIRECT("'"&$B35&"'!A9"),"") | E35: =IFERROR(INDIRECT("'"&$B35&"'!F7"),"") | F35: =IFERROR(INDIRECT("'"&$B35&"'!H7"),"") | G35: =IFERROR(INDIRECT("'"&$B35&"'!J7"),"") | H35: =IFERROR(INDIRECT("'"&$B35&"'!H9"),"") | I35: =IFERROR(INDIRECT("'"&$B35&"'!J9"),"") | J35: =IFERROR(INDIRECT("'"&$B35&"'!A13"),"") | K35: =IFERROR(INDIRECT("'"&$B35&"'!C13"),"") | L35: =IFERROR(INDIRECT("'"&$B35&"'!I24"),"") | M35: =IFERROR(INDIRECT("'"&$B35&"'!E13"),"") | N35: =IFERROR(INDIRECT("'"&$B35&"'!G13"),"") | O35: =IFERROR(INDIRECT("'"&$B35&"'!H13"),"") | P35: =IF(OR($N35="",$O35=""),"",ROUND(($N35-$O35)*100,1)) | Q35: =IFERROR(INDIRECT("'"&$B35&"'!I13"),"") | R35: =IF($N35="","",IF($N35>=0.35,"Margem boa",IF($N35>=0.25,"Margem apertada","Margem crítica"))) | AH35: =IFERROR(INDIRECT("'"&$B35&"'!C16"),"") | AI35: =IFERROR(INDIRECT("'"&$B35&"'!D16"),"") | AJ35: =IFERROR(INDIRECT("'"&$B35&"'!C17"),"") | AK35: =IFERROR(INDIRECT("'"&$B35&"'!D17"),"") | AL35: =IFERROR(INDIRECT("'"&$B35&"'!C18"),"") | AM35: =IFERROR(INDIRECT("'"&$B35&"'!D18"),"") | AN35: =IFERROR(INDIRECT("'"&$B35&"'!C19"),"") | AO35: =IFERROR(INDIRECT("'"&$B35&"'!D19"),"") | AP35: =IFERROR(INDIRECT("'"&$B35&"'!C20"),"") | AQ35: =IFERROR(INDIRECT("'"&$B35&"'!D20"),"") | AR35: =IFERROR(INDIRECT("'"&$B35&"'!C21"),"") | AS35: =IFERROR(INDIRECT("'"&$B35&"'!D21"),"")
A36: 26 | C36: =IFERROR(INDIRECT("'"&$B36&"'!A7"),"") | D36: =IFERROR(INDIRECT("'"&$B36&"'!A9"),"") | E36: =IFERROR(INDIRECT("'"&$B36&"'!F7"),"") | F36: =IFERROR(INDIRECT("'"&$B36&"'!H7"),"") | G36: =IFERROR(INDIRECT("'"&$B36&"'!J7"),"") | H36: =IFERROR(INDIRECT("'"&$B36&"'!H9"),"") | I36: =IFERROR(INDIRECT("'"&$B36&"'!J9"),"") | J36: =IFERROR(INDIRECT("'"&$B36&"'!A13"),"") | K36: =IFERROR(INDIRECT("'"&$B36&"'!C13"),"") | L36: =IFERROR(INDIRECT("'"&$B36&"'!I24"),"") | M36: =IFERROR(INDIRECT("'"&$B36&"'!E13"),"") | N36: =IFERROR(INDIRECT("'"&$B36&"'!G13"),"") | O36: =IFERROR(INDIRECT("'"&$B36&"'!H13"),"") | P36: =IF(OR($N36="",$O36=""),"",ROUND(($N36-$O36)*100,1)) | Q36: =IFERROR(INDIRECT("'"&$B36&"'!I13"),"") | R36: =IF($N36="","",IF($N36>=0.35,"Margem boa",IF($N36>=0.25,"Margem apertada","Margem crítica"))) | AH36: =IFERROR(INDIRECT("'"&$B36&"'!C16"),"") | AI36: =IFERROR(INDIRECT("'"&$B36&"'!D16"),"") | AJ36: =IFERROR(INDIRECT("'"&$B36&"'!C17"),"") | AK36: =IFERROR(INDIRECT("'"&$B36&"'!D17"),"") | AL36: =IFERROR(INDIRECT("'"&$B36&"'!C18"),"") | AM36: =IFERROR(INDIRECT("'"&$B36&"'!D18"),"") | AN36: =IFERROR(INDIRECT("'"&$B36&"'!C19"),"") | AO36: =IFERROR(INDIRECT("'"&$B36&"'!D19"),"") | AP36: =IFERROR(INDIRECT("'"&$B36&"'!C20"),"") | AQ36: =IFERROR(INDIRECT("'"&$B36&"'!D20"),"") | AR36: =IFERROR(INDIRECT("'"&$B36&"'!C21"),"") | AS36: =IFERROR(INDIRECT("'"&$B36&"'!D21"),"")
A37: 27 | C37: =IFERROR(INDIRECT("'"&$B37&"'!A7"),"") | D37: =IFERROR(INDIRECT("'"&$B37&"'!A9"),"") | E37: =IFERROR(INDIRECT("'"&$B37&"'!F7"),"") | F37: =IFERROR(INDIRECT("'"&$B37&"'!H7"),"") | G37: =IFERROR(INDIRECT("'"&$B37&"'!J7"),"") | H37: =IFERROR(INDIRECT("'"&$B37&"'!H9"),"") | I37: =IFERROR(INDIRECT("'"&$B37&"'!J9"),"") | J37: =IFERROR(INDIRECT("'"&$B37&"'!A13"),"") | K37: =IFERROR(INDIRECT("'"&$B37&"'!C13"),"") | L37: =IFERROR(INDIRECT("'"&$B37&"'!I24"),"") | M37: =IFERROR(INDIRECT("'"&$B37&"'!E13"),"") | N37: =IFERROR(INDIRECT("'"&$B37&"'!G13"),"") | O37: =IFERROR(INDIRECT("'"&$B37&"'!H13"),"") | P37: =IF(OR($N37="",$O37=""),"",ROUND(($N37-$O37)*100,1)) | Q37: =IFERROR(INDIRECT("'"&$B37&"'!I13"),"") | R37: =IF($N37="","",IF($N37>=0.35,"Margem boa",IF($N37>=0.25,"Margem apertada","Margem crítica"))) | AH37: =IFERROR(INDIRECT("'"&$B37&"'!C16"),"") | AI37: =IFERROR(INDIRECT("'"&$B37&"'!D16"),"") | AJ37: =IFERROR(INDIRECT("'"&$B37&"'!C17"),"") | AK37: =IFERROR(INDIRECT("'"&$B37&"'!D17"),"") | AL37: =IFERROR(INDIRECT("'"&$B37&"'!C18"),"") | AM37: =IFERROR(INDIRECT("'"&$B37&"'!D18"),"") | AN37: =IFERROR(INDIRECT("'"&$B37&"'!C19"),"") | AO37: =IFERROR(INDIRECT("'"&$B37&"'!D19"),"") | AP37: =IFERROR(INDIRECT("'"&$B37&"'!C20"),"") | AQ37: =IFERROR(INDIRECT("'"&$B37&"'!D20"),"") | AR37: =IFERROR(INDIRECT("'"&$B37&"'!C21"),"") | AS37: =IFERROR(INDIRECT("'"&$B37&"'!D21"),"")
A38: 28 | C38: =IFERROR(INDIRECT("'"&$B38&"'!A7"),"") | D38: =IFERROR(INDIRECT("'"&$B38&"'!A9"),"") | E38: =IFERROR(INDIRECT("'"&$B38&"'!F7"),"") | F38: =IFERROR(INDIRECT("'"&$B38&"'!H7"),"") | G38: =IFERROR(INDIRECT("'"&$B38&"'!J7"),"") | H38: =IFERROR(INDIRECT("'"&$B38&"'!H9"),"") | I38: =IFERROR(INDIRECT("'"&$B38&"'!J9"),"") | J38: =IFERROR(INDIRECT("'"&$B38&"'!A13"),"") | K38: =IFERROR(INDIRECT("'"&$B38&"'!C13"),"") | L38: =IFERROR(INDIRECT("'"&$B38&"'!I24"),"") | M38: =IFERROR(INDIRECT("'"&$B38&"'!E13"),"") | N38: =IFERROR(INDIRECT("'"&$B38&"'!G13"),"") | O38: =IFERROR(INDIRECT("'"&$B38&"'!H13"),"") | P38: =IF(OR($N38="",$O38=""),"",ROUND(($N38-$O38)*100,1)) | Q38: =IFERROR(INDIRECT("'"&$B38&"'!I13"),"") | R38: =IF($N38="","",IF($N38>=0.35,"Margem boa",IF($N38>=0.25,"Margem apertada","Margem crítica"))) | AH38: =IFERROR(INDIRECT("'"&$B38&"'!C16"),"") | AI38: =IFERROR(INDIRECT("'"&$B38&"'!D16"),"") | AJ38: =IFERROR(INDIRECT("'"&$B38&"'!C17"),"") | AK38: =IFERROR(INDIRECT("'"&$B38&"'!D17"),"") | AL38: =IFERROR(INDIRECT("'"&$B38&"'!C18"),"") | AM38: =IFERROR(INDIRECT("'"&$B38&"'!D18"),"") | AN38: =IFERROR(INDIRECT("'"&$B38&"'!C19"),"") | AO38: =IFERROR(INDIRECT("'"&$B38&"'!D19"),"") | AP38: =IFERROR(INDIRECT("'"&$B38&"'!C20"),"") | AQ38: =IFERROR(INDIRECT("'"&$B38&"'!D20"),"") | AR38: =IFERROR(INDIRECT("'"&$B38&"'!C21"),"") | AS38: =IFERROR(INDIRECT("'"&$B38&"'!D21"),"")
A39: 29 | C39: =IFERROR(INDIRECT("'"&$B39&"'!A7"),"") | D39: =IFERROR(INDIRECT("'"&$B39&"'!A9"),"") | E39: =IFERROR(INDIRECT("'"&$B39&"'!F7"),"") | F39: =IFERROR(INDIRECT("'"&$B39&"'!H7"),"") | G39: =IFERROR(INDIRECT("'"&$B39&"'!J7"),"") | H39: =IFERROR(INDIRECT("'"&$B39&"'!H9"),"") | I39: =IFERROR(INDIRECT("'"&$B39&"'!J9"),"") | J39: =IFERROR(INDIRECT("'"&$B39&"'!A13"),"") | K39: =IFERROR(INDIRECT("'"&$B39&"'!C13"),"") | L39: =IFERROR(INDIRECT("'"&$B39&"'!I24"),"") | M39: =IFERROR(INDIRECT("'"&$B39&"'!E13"),"") | N39: =IFERROR(INDIRECT("'"&$B39&"'!G13"),"") | O39: =IFERROR(INDIRECT("'"&$B39&"'!H13"),"") | P39: =IF(OR($N39="",$O39=""),"",ROUND(($N39-$O39)*100,1)) | Q39: =IFERROR(INDIRECT("'"&$B39&"'!I13"),"") | R39: =IF($N39="","",IF($N39>=0.35,"Margem boa",IF($N39>=0.25,"Margem apertada","Margem crítica"))) | AH39: =IFERROR(INDIRECT("'"&$B39&"'!C16"),"") | AI39: =IFERROR(INDIRECT("'"&$B39&"'!D16"),"") | AJ39: =IFERROR(INDIRECT("'"&$B39&"'!C17"),"") | AK39: =IFERROR(INDIRECT("'"&$B39&"'!D17"),"") | AL39: =IFERROR(INDIRECT("'"&$B39&"'!C18"),"") | AM39: =IFERROR(INDIRECT("'"&$B39&"'!D18"),"") | AN39: =IFERROR(INDIRECT("'"&$B39&"'!C19"),"") | AO39: =IFERROR(INDIRECT("'"&$B39&"'!D19"),"") | AP39: =IFERROR(INDIRECT("'"&$B39&"'!C20"),"") | AQ39: =IFERROR(INDIRECT("'"&$B39&"'!D20"),"") | AR39: =IFERROR(INDIRECT("'"&$B39&"'!C21"),"") | AS39: =IFERROR(INDIRECT("'"&$B39&"'!D21"),"")
... A50: 40 | C50: =IFERROR(INDIRECT("'"&$B50&"'!A7"),"") | D50: =IFERROR(INDIRECT("'"&$B50&"'!A9"),"") | E50: =IFERROR(INDIRECT("'"&$B50&"'!F7"),"") | F50: =IFERROR(INDIRECT("'"&$B50&"'!H7"),"") | G50: =IFERROR(INDIRECT("'"&$B50&"'!J7"),"") | H50: =IFERROR(INDIRECT("'"&$B50&"'!H9"),"") | I50: =IFERROR(INDIRECT("'"&$B50&"'!J9"),"") | J50: =IFERROR(INDIRECT("'"&$B50&"'!A13"),"") | K50: =IFERROR(INDIRECT("'"&$B50&"'!C13"),"") | L50: =IFERROR(INDIRECT("'"&$B50&"'!I24"),"") | M50: =IFERROR(INDIRECT("'"&$B50&"'!E13"),"") | N50: =IFERROR(INDIRECT("'"&$B50&"'!G13"),"") | O50: =IFERROR(INDIRECT("'"&$B50&"'!H13"),"") | P50: =IF(OR($N50="",$O50=""),"",ROUND(($N50-$O50)*100,1)) | Q50: =IFERROR(INDIRECT("'"&$B50&"'!I13"),"") | R50: =IF($N50="","",IF($N50>=0.35,"Margem boa",IF($N50>=0.25,"Margem apertada","Margem crítica"))) | AH50: =IFERROR(INDIRECT("'"&$B50&"'!C16"),"") | AI50: =IFERROR(INDIRECT("'"&$B50&"'!D16"),"") | AJ50: =IFERROR(INDIRECT("'"&$B50&"'!C17"),"") | AK50: =IFERROR(INDIRECT("'"&$B50&"'!D17"),"") | AL50: =IFERROR(INDIRECT("'"&$B50&"'!C18"),"") | AM50: =IFERROR(INDIRECT("'"&$B50&"'!D18"),"") | AN50: =IFERROR(INDIRECT("'"&$B50&"'!C19"),"") | AO50: =IFERROR(INDIRECT("'"&$B50&"'!D19"),"") | AP50: =IFERROR(INDIRECT("'"&$B50&"'!C20"),"") | AQ50: =IFERROR(INDIRECT("'"&$B50&"'!D20"),"") | AR50: =IFERROR(INDIRECT("'"&$B50&"'!C21"),"") | AS50: =IFERROR(INDIRECT("'"&$B50&"'!D21"),"")
A51: TOTAL | J51: =ROUND(SUM(J11:J50),2) | K51: =ROUND(SUM(K11:K50),2) | L51: =ROUND(SUM(L11:L50),2) | M51: =ROUND(SUM(M11:M50),2) | N51: =IF($J$51=0,"",$M$51/$J$51) | Q51: =ROUND(SUM($Q$11:$Q$50),2)
A53: ONDE O ORÇAMENTO ERRA somando todos os projetos lançados · desvio positivo = gastou mais do que previu
A54: Categoria | D54: Orçado (R$) | F54: Realizado (R$) | H54: Desvio (R$) | J54: Desvio (%) | L54: % da venda | N54: Leitura
A55: Custos de venda | D55: =ROUND(SUM(AH$11:AH$50),2) | F55: =ROUND(SUM(AI$11:AI$50),2) | H55: =ROUND($F55-$D55,2) | J55: =IF($D55=0,"",$F55/$D55-1) | L55: =IF($J$51=0,"",$F55/$J$51) | N55: =IF($D55=0,"—",IF($J55>0.1,"Estourou mais de 10% — revisar a premissa",IF($J55<-0.1,"Sobrou mais de 10% — orçamento pode estar gordo","Dentro do previsto")))
A56: Comissões operacionais | D56: =ROUND(SUM(AJ$11:AJ$50),2) | F56: =ROUND(SUM(AK$11:AK$50),2) | H56: =ROUND($F56-$D56,2) | J56: =IF($D56=0,"",$F56/$D56-1) | L56: =IF($J$51=0,"",$F56/$J$51) | N56: =IF($D56=0,"—",IF($J56>0.1,"Estourou mais de 10% — revisar a premissa",IF($J56<-0.1,"Sobrou mais de 10% — orçamento pode estar gordo","Dentro do previsto")))
A57: Material | D57: =ROUND(SUM(AL$11:AL$50),2) | F57: =ROUND(SUM(AM$11:AM$50),2) | H57: =ROUND($F57-$D57,2) | J57: =IF($D57=0,"",$F57/$D57-1) | L57: =IF($J$51=0,"",$F57/$J$51) | N57: =IF($D57=0,"—",IF($J57>0.1,"Estourou mais de 10% — revisar a premissa",IF($J57<-0.1,"Sobrou mais de 10% — orçamento pode estar gordo","Dentro do previsto")))
...

Sheet Ficha Modelo
A1: VALVIC MARCENARIA
A2: Vargas Decor Ltda · CNPJ 17.269.304/0001-51 · Belo Horizonte / MG
A3: FICHA DE CUSTO DO PROJETO
A4: Fundo creme = você preenche · fundo cinza = calculado · duplique esta aba a cada projeto e registre o nome dela no Painel Geral
A6: CLIENTE | D6: Nº DO PROJETO | F6: DATA DE ENTRADA | H6: ENTREGA PREVISTA | J6: ENTREGA REAL
A8: PROJETO | D8: VENDEDOR | F8: COORDENADOR | H8: DIAS DE ATRASO | J8: SITUAÇÃO DA ENTREGA
H9: =IF(OR($H$7="",$J$7=""),"",$J$7-$H$7) | J9: =IF($H$7="","",IF($J$7="",IF(TODAY()>$H$7,"Atrasado","Em produção"),IF($H$9<=0,"No prazo","Atrasado")))
A10: MÊS DE COMPETÊNCIA | F10: o mês em que a receita e o custo deste projeto pesam no painel de competência
A11: RESULTADO DO PROJETO tudo aqui se atualiza conforme você lança os custos mais abaixo
A12: VALOR DE VENDA | C12: CUSTO TOTAL | E12: MARGEM DE CONTRIBUIÇÃO | G12: MC % | H12: MC % ORÇADA | I12: DESVIO DE CUSTO
A13: =IF($D$28="",$C$28,$D$28) | C13: =IF($D$22=0,"",$D$22) | E13: =IF($A$13="","",$D$23) | G13: =IF(OR($A$13="",$A$13=0),"",$D$23/$A$13) | H13: =IF(OR($C$28="",$C$28=0),"",$C$23/$C$28) | I13: =IF(OR($C$22=0,$D$22=0),"",ROUND($D$22-$C$22,2))
A15: Resumo por categoria | C15: Orçado (R$) | D15: Realizado (R$) | E15: Desvio (R$) | G15: Desvio (%) | H15: % da venda realizada
A16: Custos de venda | C16: =IF(C44="","",C44) | D16: =IF(D44="","",D44) | E16: =IF(OR($C16="",$D16=""),"",ROUND($D16-$C16,2)) | G16: =IF(OR($C16="",$C16=0,$D16=""),"",$D16/$C16-1) | H16: =IF(OR($D16="",$A$13="",$A$13=0),"",$D16/$A$13)
A17: Comissões operacionais | C17: =IF(C70="","",C70) | D17: =IF(D70="","",D70) | E17: =IF(OR($C17="",$D17=""),"",ROUND($D17-$C17,2)) | G17: =IF(OR($C17="",$C17=0,$D17=""),"",$D17/$C17-1) | H17: =IF(OR($D17="",$A$13="",$A$13=0),"",$D17/$A$13)
A18: Material | C18: =IF(C103="","",C103) | D18: =IF(D103="","",D103) | E18: =IF(OR($C18="",$D18=""),"",ROUND($D18-$C18,2)) | G18: =IF(OR($C18="",$C18=0,$D18=""),"",$D18/$C18-1) | H18: =IF(OR($D18="",$A$13="",$A$13=0),"",$D18/$A$13)
A19: Serviços terceirizados | C19: =IF(C108="","",C108) | D19: =IF(D108="","",D108) | E19: =IF(OR($C19="",$D19=""),"",ROUND($D19-$C19,2)) | G19: =IF(OR($C19="",$C19=0,$D19=""),"",$D19/$C19-1) | H19: =IF(OR($D19="",$A$13="",$A$13=0),"",$D19/$A$13)
A20: Logística | C20: =IF(C114="","",C114) | D20: =IF(D114="","",D114) | E20: =IF(OR($C20="",$D20=""),"",ROUND($D20-$C20,2)) | G20: =IF(OR($C20="",$C20=0,$D20=""),"",$D20/$C20-1) | H20: =IF(OR($D20="",$A$13="",$A$13=0),"",$D20/$A$13)
A21: Retrabalho | C21: =IF(C130="","",C130) | D21: =IF(D130="","",D130) | E21: =IF(OR($C21="",$D21=""),"",ROUND($D21-$C21,2)) | G21: =IF(OR($C21="",$C21=0,$D21=""),"",$D21/$C21-1) | H21: =IF(OR($D21="",$A$13="",$A$13=0),"",$D21/$A$13)
A22: (=) CUSTO TOTAL DO PROJETO | C22: =ROUND(SUM(C16:C21),2) | D22: =ROUND(SUM(D16:D21),2) | E22: =ROUND($D$22-$C$22,2) | G22: =IF(OR($C$22="",$C$22=0),"",$D$22/$C$22-1) | H22: =IF(OR($A$13="",$A$13=0),"",$D$22/$A$13)
A23: (=) MARGEM DE CONTRIBUIÇÃO | C23: =ROUND($C$28-$C$22,2) | D23: =ROUND($A$13-$D$22,2) | E23: =ROUND($D$23-$C$23,2) | G23: =IF(OR($C$28="",$C$28=0),"",$C$23/$C$28) | H23: =IF(OR($A$13="",$A$13=0),"",$D$23/$A$13)
A24: =IF($A$13="","",IF(ROUND(SUMIF($I$134:$I$193,"A comprar",$E$134:$E$193),2)+ROUND(SUMIF($I$134:$I$193,"Comprado (a pagar)",$E$134:$E$193),2)=0," Nenhuma compra pendente lançada — o custo realizado já é o custo final."," Já comprado e ainda a pagar: "&TEXT(ROUND(SUMIF($I$134:$I$193,"Comprado (a pagar)",$E$134:$E$193),2),"R$ #,##0")&" · custo projetado: "&TEXT($D$22+ROUND(SUMIF($I$134:$I$193,"A comprar",$E$134:$E$193),2),"R$ #,##0")&" · MC projetada: "&TEXT(($A$13-$D$22-ROUND(SUMIF($I$134:$I$193,"A comprar",$E$134:$E$193),2))/$A$13,"0.0%"))) | I24: =IF($A$13="","",ROUND(SUMIF($I$134:$I$193,"A comprar",$E$134:$E$193),2))
A26: 1 · VALOR DE VENDA E NOTAS EMITIDAS o que foi vendido e o que já virou nota — a diferença é o que falta faturar
A27: Item | B27: % | C27: Orçado (R$) | D27: Realizado (R$) | E27: Desvio (R$) | G27: % da venda | H27: Observação
A28: Valor de venda do projeto | E28: =IF(OR($C28="",$D28=""),"",ROUND($D28-$C28,2)) | H28: Orçado = valor da proposta · Realizado = valor fechado
A29: Nota fiscal | B29: Número | C29: Data | D29: Valor (R$) | G29: % da venda | H29: Observação
A30: Nota 1 | G30: =IF(OR($D30="",$A$13="",$A$13=0),"",$D30/$A$13)
A31: Nota 2 | G31: =IF(OR($D31="",$A$13="",$A$13=0),"",$D31/$A$13)
A32: Nota 3 | G32: =IF(OR($D32="",$A$13="",$A$13=0),"",$D32/$A$13)
A33: Nota 4 | G33: =IF(OR($D33="",$A$13="",$A$13=0),"",$D33/$A$13)
A34: (=) TOTAL FATURADO → | D34: =ROUND(SUM($D$30:$D$33),2) | G34: =IF(OR($A$13="",$A$13=0),"",$D$34/$A$13) | H34: =IF(OR($A$13="",$A$13=0),"",IF(ROUND($A$13-$D$34,2)<=0," Projeto totalmente faturado."," Ainda a faturar: "&TEXT($A$13-$D$34,"R$ #,##0.00")))
A36: 2 · CUSTOS DE VENDA tudo que sai por causa da venda · define a RECEITA LÍQUIDA
A37: Item | B37: % | C37: Orçado (R$) | D37: Realizado (R$) | E37: Desvio (R$) | G37: % da venda | H37: Observação
A38: Impostos sobre a nota (Simples) | C38: =IF($B38="","",ROUND($B38*$C$28,2)) | D38: =IF($B38="","",ROUND($B38*$A$13,2)) | E38: =IF(OR($C38="",$D38=""),"",ROUND($D38-$C38,2)) | G38: =IF(OR($D38="",$A$13="",$A$13=0),"",$D38/$A$13) | H38: % sobre o valor de venda
A39: Taxa de máquina de cartão | C39: =IF($B39="","",ROUND($B39*$C$28,2)) | D39: =IF($B39="","",ROUND($B39*$A$13,2)) | E39: =IF(OR($C39="",$D39=""),"",ROUND($D39-$C39,2)) | G39: =IF(OR($D39="",$A$13="",$A$13=0),"",$D39/$A$13) | H39: % sobre o valor de venda
A40: Taxas de transação (PIX, boleto, TED) | E40: =IF(OR($C40="",$D40=""),"",ROUND($D40-$C40,2)) | G40: =IF(OR($D40="",$A$13="",$A$13=0),"",$D40/$A$13) | H40: valor em reais
A41: Comissão de venda (vendedor) | C41: =IF($B41="","",ROUND($B41*$C$28,2)) | D41: =IF($B41="","",ROUND($B41*$A$13,2)) | E41: =IF(OR($C41="",$D41=""),"",ROUND($D41-$C41,2)) | G41: =IF(OR($D41="",$A$13="",$A$13=0),"",$D41/$A$13) | H41: % sobre o valor de venda
A42: Projeto / anteprojeto (externo) | E42: =IF(OR($C42="",$D42=""),"",ROUND($D42-$C42,2)) | G42: =IF(OR($D42="",$A$13="",$A$13=0),"",$D42/$A$13) | H42: projetista ou arquiteto contratado para o projeto
A43: RT do parceiro | C43: =IF($B43="","",ROUND($B43*($C$28-SUM($C$38:$C$40)),2)) | D43: =IF($B43="","",ROUND($B43*($A$13-SUM($D$38:$D$40)),2)) | E43: =IF(OR($C43="",$D43=""),"",ROUND($D43-$C43,2)) | G43: =IF(OR($D43="",$A$13="",$A$13=0),"",$D43/$A$13) | H43: % sobre o líquido: venda menos impostos, máquina e taxas
A44: (=) SUBTOTAL DOS CUSTOS DE VENDA | C44: =ROUND(SUM(C38:C43),2) | D44: =ROUND(SUM(D38:D43),2) | E44: =ROUND($D44-$C44,2) | G44: =IF(OR($A$13="",$A$13=0),"",$D44/$A$13)
A45: (=) RECEITA LÍQUIDA | C45: =ROUND($C$28-$C$44,2) | D45: =ROUND($A$13-$D$44,2) | E45: =ROUND($D$45-$C$45,2) | G45: =IF(OR($A$13="",$A$13=0),"",$D$45/$A$13) | H45: É esta a base das comissões: coordenação, produção, montagem e projetista
...

Sheet Ana Carolina 
A1: VALVIC MARCENARIA
A2: Vargas Decor Ltda · CNPJ 17.269.304/0001-51 · Belo Horizonte / MG
A3: FICHA DE CUSTO DO PROJETO
A4: Fundo creme = você preenche · fundo cinza = calculado · duplique esta aba a cada projeto e registre o nome dela no Painel Geral
A6: CLIENTE | D6: Nº DO PROJETO | F6: DATA DE ENTRADA | H6: ENTREGA PREVISTA | J6: ENTREGA REAL
A8: PROJETO | D8: VENDEDOR | F8: COORDENADOR | H8: DIAS DE ATRASO | J8: SITUAÇÃO DA ENTREGA
H9: =IF(OR($H$7="",$J$7=""),"",$J$7-$H$7) | J9: =IF($H$7="","",IF($J$7="",IF(TODAY()>$H$7,"Atrasado","Em produção"),IF($H$9<=0,"No prazo","Atrasado")))
A10: MÊS DE COMPETÊNCIA | F10: o mês em que a receita e o custo deste projeto pesam no painel de competência
A11: RESULTADO DO PROJETO tudo aqui se atualiza conforme você lança os custos mais abaixo
A12: VALOR DE VENDA | C12: CUSTO TOTAL | E12: MARGEM DE CONTRIBUIÇÃO | G12: MC % | H12: MC % ORÇADA | I12: DESVIO DE CUSTO
A13: =IF($D$28="",$C$28,$D$28) | C13: =IF($D$22=0,"",$D$22) | E13: =IF($A$13="","",$D$23) | G13: =IF(OR($A$13="",$A$13=0),"",$D$23/$A$13) | H13: =IF(OR($C$28="",$C$28=0),"",$C$23/$C$28) | I13: =IF(OR($C$22=0,$D$22=0),"",ROUND($D$22-$C$22,2))
A15: Resumo por categoria | C15: Orçado (R$) | D15: Realizado (R$) | E15: Desvio (R$) | G15: Desvio (%) | H15: % da venda realizada
A16: Custos de venda | C16: =IF(C44="","",C44) | D16: =IF(D44="","",D44) | E16: =IF(OR($C16="",$D16=""),"",ROUND($D16-$C16,2)) | G16: =IF(OR($C16="",$C16=0,$D16=""),"",$D16/$C16-1) | H16: =IF(OR($D16="",$A$13="",$A$13=0),"",$D16/$A$13)
A17: Comissões operacionais | C17: =IF(C70="","",C70) | D17: =IF(D70="","",D70) | E17: =IF(OR($C17="",$D17=""),"",ROUND($D17-$C17,2)) | G17: =IF(OR($C17="",$C17=0,$D17=""),"",$D17/$C17-1) | H17: =IF(OR($D17="",$A$13="",$A$13=0),"",$D17/$A$13)
A18: Material | C18: =IF(C103="","",C103) | D18: =IF(D103="","",D103) | E18: =IF(OR($C18="",$D18=""),"",ROUND($D18-$C18,2)) | G18: =IF(OR($C18="",$C18=0,$D18=""),"",$D18/$C18-1) | H18: =IF(OR($D18="",$A$13="",$A$13=0),"",$D18/$A$13)
A19: Serviços terceirizados | C19: =IF(C108="","",C108) | D19: =IF(D108="","",D108) | E19: =IF(OR($C19="",$D19=""),"",ROUND($D19-$C19,2)) | G19: =IF(OR($C19="",$C19=0,$D19=""),"",$D19/$C19-1) | H19: =IF(OR($D19="",$A$13="",$A$13=0),"",$D19/$A$13)
A20: Logística | C20: =IF(C114="","",C114) | D20: =IF(D114="","",D114) | E20: =IF(OR($C20="",$D20=""),"",ROUND($D20-$C20,2)) | G20: =IF(OR($C20="",$C20=0,$D20=""),"",$D20/$C20-1) | H20: =IF(OR($D20="",$A$13="",$A$13=0),"",$D20/$A$13)
A21: Retrabalho | C21: =IF(C130="","",C130) | D21: =IF(D130="","",D130) | E21: =IF(OR($C21="",$D21=""),"",ROUND($D21-$C21,2)) | G21: =IF(OR($C21="",$C21=0,$D21=""),"",$D21/$C21-1) | H21: =IF(OR($D21="",$A$13="",$A$13=0),"",$D21/$A$13)
A22: (=) CUSTO TOTAL DO PROJETO | C22: =ROUND(SUM(C16:C21),2) | D22: =ROUND(SUM(D16:D21),2) | E22: =ROUND($D$22-$C$22,2) | G22: =IF(OR($C$22="",$C$22=0),"",$D$22/$C$22-1) | H22: =IF(OR($A$13="",$A$13=0),"",$D$22/$A$13)
A23: (=) MARGEM DE CONTRIBUIÇÃO | C23: =ROUND($C$28-$C$22,2) | D23: =ROUND($A$13-$D$22,2) | E23: =ROUND($D$23-$C$23,2) | G23: =IF(OR($C$28="",$C$28=0),"",$C$23/$C$28) | H23: =IF(OR($A$13="",$A$13=0),"",$D$23/$A$13)
A24: =IF($A$13="","",IF(ROUND(SUMIF($I$134:$I$193,"A comprar",$E$134:$E$193),2)+ROUND(SUMIF($I$134:$I$193,"Comprado (a pagar)",$E$134:$E$193),2)=0," Nenhuma compra pendente lançada — o custo realizado já é o custo final."," Já comprado e ainda a pagar: "&TEXT(ROUND(SUMIF($I$134:$I$193,"Comprado (a pagar)",$E$134:$E$193),2),"R$ #,##0")&" · custo projetado: "&TEXT($D$22+ROUND(SUMIF($I$134:$I$193,"A comprar",$E$134:$E$193),2),"R$ #,##0")&" · MC projetada: "&TEXT(($A$13-$D$22-ROUND(SUMIF($I$134:$I$193,"A comprar",$E$134:$E$193),2))/$A$13,"0.0%"))) | I24: =IF($A$13="","",ROUND(SUMIF($I$134:$I$193,"A comprar",$E$134:$E$193),2))
A26: 1 · VALOR DE VENDA E NOTAS EMITIDAS o que foi vendido e o que já virou nota — a diferença é o que falta faturar
A27: Item | B27: % | C27: Orçado (R$) | D27: Realizado (R$) | E27: Desvio (R$) | G27: % da venda | H27: Observação
A28: Valor de venda do projeto | E28: =IF(OR($C28="",$D28=""),"",ROUND($D28-$C28,2)) | H28: Orçado = valor da proposta · Realizado = valor fechado
A29: Nota fiscal | B29: Número | C29: Data | D29: Valor (R$) | G29: % da venda | H29: Observação
A30: Nota 1 | G30: =IF(OR($D30="",$A$13="",$A$13=0),"",$D30/$A$13)
A31: Nota 2 | G31: =IF(OR($D31="",$A$13="",$A$13=0),"",$D31/$A$13)
A32: Nota 3 | G32: =IF(OR($D32="",$A$13="",$A$13=0),"",$D32/$A$13)
A33: Nota 4 | G33: =IF(OR($D33="",$A$13="",$A$13=0),"",$D33/$A$13)
A34: (=) TOTAL FATURADO → | D34: =ROUND(SUM($D$30:$D$33),2) | G34: =IF(OR($A$13="",$A$13=0),"",$D$34/$A$13) | H34: =IF(OR($A$13="",$A$13=0),"",IF(ROUND($A$13-$D$34,2)<=0," Projeto totalmente faturado."," Ainda a faturar: "&TEXT($A$13-$D$34,"R$ #,##0.00")))
A36: 2 · CUSTOS DE VENDA tudo que sai por causa da venda · define a RECEITA LÍQUIDA
A37: Item | B37: % | C37: Orçado (R$) | D37: Realizado (R$) | E37: Desvio (R$) | G37: % da venda | H37: Observação
A38: Impostos sobre a nota (Simples) | C38: =IF($B38="","",ROUND($B38*$C$28,2)) | D38: =IF($B38="","",ROUND($B38*$A$13,2)) | E38: =IF(OR($C38="",$D38=""),"",ROUND($D38-$C38,2)) | G38: =IF(OR($D38="",$A$13="",$A$13=0),"",$D38/$A$13) | H38: % sobre o valor de venda
A39: Taxa de máquina de cartão | C39: =IF($B39="","",ROUND($B39*$C$28,2)) | D39: =IF($B39="","",ROUND($B39*$A$13,2)) | E39: =IF(OR($C39="",$D39=""),"",ROUND($D39-$C39,2)) | G39: =IF(OR($D39="",$A$13="",$A$13=0),"",$D39/$A$13) | H39: % sobre o valor de venda
A40: Taxas de transação (PIX, boleto, TED) | E40: =IF(OR($C40="",$D40=""),"",ROUND($D40-$C40,2)) | G40: =IF(OR($D40="",$A$13="",$A$13=0),"",$D40/$A$13) | H40: valor em reais
A41: Comissão de venda (vendedor) | C41: =IF($B41="","",ROUND($B41*$C$28,2)) | D41: =IF($B41="","",ROUND($B41*$A$13,2)) | E41: =IF(OR($C41="",$D41=""),"",ROUND($D41-$C41,2)) | G41: =IF(OR($D41="",$A$13="",$A$13=0),"",$D41/$A$13) | H41: % sobre o valor de venda
A42: Projeto / anteprojeto (externo) | E42: =IF(OR($C42="",$D42=""),"",ROUND($D42-$C42,2)) | G42: =IF(OR($D42="",$A$13="",$A$13=0),"",$D42/$A$13) | H42: projetista ou arquiteto contratado para o projeto
A43: RT do parceiro | C43: =IF($B43="","",ROUND($B43*($C$28-SUM($C$38:$C$40)),2)) | D43: =IF($B43="","",ROUND($B43*($A$13-SUM($D$38:$D$40)),2)) | E43: =IF(OR($C43="",$D43=""),"",ROUND($D43-$C43,2)) | G43: =IF(OR($D43="",$A$13="",$A$13=0),"",$D43/$A$13) | H43: % sobre o líquido: venda menos impostos, máquina e taxas
A44: (=) SUBTOTAL DOS CUSTOS DE VENDA | C44: =ROUND(SUM(C38:C43),2) | D44: =ROUND(SUM(D38:D43),2) | E44: =ROUND($D44-$C44,2) | G44: =IF(OR($A$13="",$A$13=0),"",$D44/$A$13)
A45: (=) RECEITA LÍQUIDA | C45: =ROUND($C$28-$C$44,2) | D45: =ROUND($A$13-$D$44,2) | E45: =ROUND($D$45-$C$45,2) | G45: =IF(OR($A$13="",$A$13=0),"",$D$45/$A$13) | H45: É esta a base das comissões: coordenação, produção, montagem e projetista
...

Sheet Andrea 
A1: VALVIC MARCENARIA
A2: Vargas Decor Ltda · CNPJ 17.269.304/0001-51 · Belo Horizonte / MG
A3: FICHA DE CUSTO DO PROJETO
A4: Fundo creme = você preenche · fundo cinza = calculado · duplique esta aba a cada projeto e registre o nome dela no Painel Geral
A6: CLIENTE | D6: Nº DO PROJETO | F6: DATA DE ENTRADA | H6: ENTREGA PREVISTA | J6: ENTREGA REAL
A8: PROJETO | D8: VENDEDOR | F8: COORDENADOR | H8: DIAS DE ATRASO | J8: SITUAÇÃO DA ENTREGA
H9: =IF(OR($H$7="",$J$7=""),"",$J$7-$H$7) | J9: =IF($H$7="","",IF($J$7="",IF(TODAY()>$H$7,"Atrasado","Em produção"),IF($H$9<=0,"No prazo","Atrasado")))
A10: MÊS DE COMPETÊNCIA | F10: o mês em que a receita e o custo deste projeto pesam no painel de competência
A11: RESULTADO DO PROJETO tudo aqui se atualiza conforme você lança os custos mais abaixo
A12: VALOR DE VENDA | C12: CUSTO TOTAL | E12: MARGEM DE CONTRIBUIÇÃO | G12: MC % | H12: MC % ORÇADA | I12: DESVIO DE CUSTO
A13: =IF($D$28="",$C$28,$D$28) | C13: =IF($D$22=0,"",$D$22) | E13: =IF($A$13="","",$D$23) | G13: =IF(OR($A$13="",$A$13=0),"",$D$23/$A$13) | H13: =IF(OR($C$28="",$C$28=0),"",$C$23/$C$28) | I13: =IF(OR($C$22=0,$D$22=0),"",ROUND($D$22-$C$22,2))
A15: Resumo por categoria | C15: Orçado (R$) | D15: Realizado (R$) | E15: Desvio (R$) | G15: Desvio (%) | H15: % da venda realizada
A16: Custos de venda | C16: =IF(C44="","",C44) | D16: =IF(D44="","",D44) | E16: =IF(OR($C16="",$D16=""),"",ROUND($D16-$C16,2)) | G16: =IF(OR($C16="",$C16=0,$D16=""),"",$D16/$C16-1) | H16: =IF(OR($D16="",$A$13="",$A$13=0),"",$D16/$A$13)
A17: Comissões operacionais | C17: =IF(C70="","",C70) | D17: =IF(D70="","",D70) | E17: =IF(OR($C17="",$D17=""),"",ROUND($D17-$C17,2)) | G17: =IF(OR($C17="",$C17=0,$D17=""),"",$D17/$C17-1) | H17: =IF(OR($D17="",$A$13="",$A$13=0),"",$D17/$A$13)
A18: Material | C18: =IF(C103="","",C103) | D18: =IF(D103="","",D103) | E18: =IF(OR($C18="",$D18=""),"",ROUND($D18-$C18,2)) | G18: =IF(OR($C18="",$C18=0,$D18=""),"",$D18/$C18-1) | H18: =IF(OR($D18="",$A$13="",$A$13=0),"",$D18/$A$13)
A19: Serviços terceirizados | C19: =IF(C108="","",C108) | D19: =IF(D108="","",D108) | E19: =IF(OR($C19="",$D19=""),"",ROUND($D19-$C19,2)) | G19: =IF(OR($C19="",$C19=0,$D19=""),"",$D19/$C19-1) | H19: =IF(OR($D19="",$A$13="",$A$13=0),"",$D19/$A$13)
A20: Logística | C20: =IF(C114="","",C114) | D20: =IF(D114="","",D114) | E20: =IF(OR($C20="",$D20=""),"",ROUND($D20-$C20,2)) | G20: =IF(OR($C20="",$C20=0,$D20=""),"",$D20/$C20-1) | H20: =IF(OR($D20="",$A$13="",$A$13=0),"",$D20/$A$13)
A21: Retrabalho | C21: =IF(C130="","",C130) | D21: =IF(D130="","",D130) | E21: =IF(OR($C21="",$D21=""),"",ROUND($D21-$C21,2)) | G21: =IF(OR($C21="",$C21=0,$D21=""),"",$D21/$C21-1) | H21: =IF(OR($D21="",$A$13="",$A$13=0),"",$D21/$A$13)
A22: (=) CUSTO TOTAL DO PROJETO | C22: =ROUND(SUM(C16:C21),2) | D22: =ROUND(SUM(D16:D21),2) | E22: =ROUND($D$22-$C$22,2) | G22: =IF(OR($C$22="",$C$22=0),"",$D$22/$C$22-1) | H22: =IF(OR($A$13="",$A$13=0),"",$D$22/$A$13)
A23: (=) MARGEM DE CONTRIBUIÇÃO | C23: =ROUND($C$28-$C$22,2) | D23: =ROUND($A$13-$D$22,2) | E23: =ROUND($D$23-$C$23,2) | G23: =IF(OR($C$28="",$C$28=0),"",$C$23/$C$28) | H23: =IF(OR($A$13="",$A$13=0),"",$D$23/$A$13)
A24: =IF($A$13="","",IF(ROUND(SUMIF($I$134:$I$193,"A comprar",$E$134:$E$193),2)+ROUND(SUMIF($I$134:$I$193,"Comprado (a pagar)",$E$134:$E$193),2)=0," Nenhuma compra pendente lançada — o custo realizado já é o custo final."," Já comprado e ainda a pagar: "&TEXT(ROUND(SUMIF($I$134:$I$193,"Comprado (a pagar)",$E$134:$E$193),2),"R$ #,##0")&" · custo projetado: "&TEXT($D$22+ROUND(SUMIF($I$134:$I$193,"A comprar",$E$134:$E$193),2),"R$ #,##0")&" · MC projetada: "&TEXT(($A$13-$D$22-ROUND(SUMIF($I$134:$I$193,"A comprar",$E$134:$E$193),2))/$A$13,"0.0%"))) | I24: =IF($A$13="","",ROUND(SUMIF($I$134:$I$193,"A comprar",$E$134:$E$193),2))
A26: 1 · VALOR DE VENDA E NOTAS EMITIDAS o que foi vendido e o que já virou nota — a diferença é o que falta faturar
A27: Item | B27: % | C27: Orçado (R$) | D27: Realizado (R$) | E27: Desvio (R$) | G27: % da venda | H27: Observação
A28: Valor de venda do projeto | E28: =IF(OR($C28="",$D28=""),"",ROUND($D28-$C28,2)) | H28: Orçado = valor da proposta · Realizado = valor fechado
A29: Nota fiscal | B29: Número | C29: Data | D29: Valor (R$) | G29: % da venda | H29: Observação
A30: Nota 1 | G30: =IF(OR($D30="",$A$13="",$A$13=0),"",$D30/$A$13)
A31: Nota 2 | G31: =IF(OR($D31="",$A$13="",$A$13=0),"",$D31/$A$13)
A32: Nota 3 | G32: =IF(OR($D32="",$A$13="",$A$13=0),"",$D32/$A$13)
A33: Nota 4 | G33: =IF(OR($D33="",$A$13="",$A$13=0),"",$D33/$A$13)
A34: (=) TOTAL FATURADO → | D34: =ROUND(SUM($D$30:$D$33),2) | G34: =IF(OR($A$13="",$A$13=0),"",$D$34/$A$13) | H34: =IF(OR($A$13="",$A$13=0),"",IF(ROUND($A$13-$D$34,2)<=0," Projeto totalmente faturado."," Ainda a faturar: "&TEXT($A$13-$D$34,"R$ #,##0.00")))
A36: 2 · CUSTOS DE VENDA tudo que sai por causa da venda · define a RECEITA LÍQUIDA
A37: Item | B37: % | C37: Orçado (R$) | D37: Realizado (R$) | E37: Desvio (R$) | G37: % da venda | H37: Observação
A38: Impostos sobre a nota (Simples) | C38: =IF($B38="","",ROUND($B38*$C$28,2)) | D38: =IF($B38="","",ROUND($B38*$A$13,2)) | E38: =IF(OR($C38="",$D38=""),"",ROUND($D38-$C38,2)) | G38: =IF(OR($D38="",$A$13="",$A$13=0),"",$D38/$A$13) | H38: % sobre o valor de venda
A39: Taxa de máquina de cartão | C39: =IF($B39="","",ROUND($B39*$C$28,2)) | D39: =IF($B39="","",ROUND($B39*$A$13,2)) | E39: =IF(OR($C39="",$D39=""),"",ROUND($D39-$C39,2)) | G39: =IF(OR($D39="",$A$13="",$A$13=0),"",$D39/$A$13) | H39: % sobre o valor de venda
