Workbook

Sheet Painel
A1: VALVIC MARCENARIA
A2: Vargas Decor Ltda · CNPJ 17.269.304/0001-51 · Belo Horizonte / MG
A3: PAINEL DE PAGAMENTOS
A4: Tudo aqui é calculado a partir das abas de ano — não digite nada nesta aba
A6: VENDIDO EM 2026 | D6: RECEBIDO | G6: A RECEBER | J6: % RECEBIDO | M6: PROJETOS | P6: TICKET MÉDIO
A7: ='2026'!$A$7 | D7: ='2026'!$D$7 | G7: ='2026'!$F$7 | J7: ='2026'!$H$7 | M7: =COUNT('2026'!$X$10:$X$107) | P7: =IF(COUNT('2026'!$X$10:$X$107)=0,"",'2026'!$A$7/COUNT('2026'!$X$10:$X$107))
A9: ANO A ANO vendido, recebido e o que ficou em aberto
A10: Ano | B10: Projetos | C10: Vendido | D10: Recebido | E10: A receber | F10: % recebido | G10: Ticket médio
A11: 2026 | B11: =COUNT('2026'!$X$10:$X$107) | C11: ='2026'!$A$7 | D11: ='2026'!$D$7 | E11: ='2026'!$F$7 | F11: ='2026'!$H$7 | G11: =IF(COUNT('2026'!$X$10:$X$107)=0,"",'2026'!$A$7/COUNT('2026'!$X$10:$X$107))
A12: 2025 | B12: =COUNT('2025'!$X$10:$X$112) | C12: ='2025'!$A$7 | D12: ='2025'!$D$7 | E12: ='2025'!$F$7 | F12: ='2025'!$H$7 | G12: =IF(COUNT('2025'!$X$10:$X$112)=0,"",'2025'!$A$7/COUNT('2025'!$X$10:$X$112))
A13: 2024 | B13: =COUNT('2024'!$X$10:$X$108) | C13: ='2024'!$A$7 | D13: ='2024'!$D$7 | E13: ='2024'!$F$7 | F13: ='2024'!$H$7 | G13: =IF(COUNT('2024'!$X$10:$X$108)=0,"",'2024'!$A$7/COUNT('2024'!$X$10:$X$108))
A14: 2023 | B14: =COUNT('2023'!$X$26:$X$127) | C14: ='2023'!$A$7 | D14: ='2023'!$D$7 | E14: ='2023'!$F$7 | F14: ='2023'!$H$7 | G14: =IF(COUNT('2023'!$X$26:$X$127)=0,"",'2023'!$A$7/COUNT('2023'!$X$26:$X$127))
A16: 2026 MÊS A MÊS vendas pela data do contrato · acumulado comparado à meta
A17: Mês | B17: Projetos | C17: Vendido | D17: Recebido | E17: A receber | F17: % recebido | G17: Acum. vendido | H17: Meta acum.
A18: Janeiro | B18: =COUNT('2026'!$X$11:$X$19) | C18: ='2026'!$C$10 | D18: ='2026'!$E$10 | E18: ='2026'!$F$10 | F18: ='2026'!$G$10 | G18: =IF(DATE(2026,1,1)>TODAY(),"",IF(SUM($C$18:$C18)=0,"",SUM($C$18:$C18))) | H18: =ROUND('2026'!$I$7/12*1,0)
A19: Fevereiro | B19: =COUNT('2026'!$X$18:$X$26) | C19: ='2026'!$C$17 | D19: ='2026'!$E$17 | E19: ='2026'!$F$17 | F19: ='2026'!$G$17 | G19: =IF(DATE(2026,2,1)>TODAY(),"",IF(SUM($C$18:$C19)=0,"",SUM($C$18:$C19))) | H19: =ROUND('2026'!$I$7/12*2,0)
A20: Março | B20: =COUNT('2026'!$X$28:$X$36) | C20: ='2026'!$C$27 | D20: ='2026'!$E$27 | E20: ='2026'!$F$27 | F20: ='2026'!$G$27 | G20: =IF(DATE(2026,3,1)>TODAY(),"",IF(SUM($C$18:$C20)=0,"",SUM($C$18:$C20))) | H20: =ROUND('2026'!$I$7/12*3,0)
A21: Abril | B21: =COUNT('2026'!$X$39:$X$47) | C21: ='2026'!$C$38 | D21: ='2026'!$E$38 | E21: ='2026'!$F$38 | F21: ='2026'!$G$38 | G21: =IF(DATE(2026,4,1)>TODAY(),"",IF(SUM($C$18:$C21)=0,"",SUM($C$18:$C21))) | H21: =ROUND('2026'!$I$7/12*4,0)
A22: Maio | B22: =COUNT('2026'!$X$50:$X$58) | C22: ='2026'!$C$49 | D22: ='2026'!$E$49 | E22: ='2026'!$F$49 | F22: ='2026'!$G$49 | G22: =IF(DATE(2026,5,1)>TODAY(),"",IF(SUM($C$18:$C22)=0,"",SUM($C$18:$C22))) | H22: =ROUND('2026'!$I$7/12*5,0)
A23: Junho | B23: =COUNT('2026'!$X$59:$X$67) | C23: ='2026'!$C$58 | D23: ='2026'!$E$58 | E23: ='2026'!$F$58 | F23: ='2026'!$G$58 | G23: =IF(DATE(2026,6,1)>TODAY(),"",IF(SUM($C$18:$C23)=0,"",SUM($C$18:$C23))) | H23: =ROUND('2026'!$I$7/12*6,0)
A24: Julho | B24: =COUNT('2026'!$X$70:$X$78) | C24: ='2026'!$C$69 | D24: ='2026'!$E$69 | E24: ='2026'!$F$69 | F24: ='2026'!$G$69 | G24: =IF(DATE(2026,7,1)>TODAY(),"",IF(SUM($C$18:$C24)=0,"",SUM($C$18:$C24))) | H24: =ROUND('2026'!$I$7/12*7,0)
A25: Agosto | B25: =COUNT('2026'!$X$81:$X$89) | C25: ='2026'!$C$80 | D25: ='2026'!$E$80 | E25: ='2026'!$F$80 | F25: ='2026'!$G$80 | G25: =IF(DATE(2026,8,1)>TODAY(),"",IF(SUM($C$18:$C25)=0,"",SUM($C$18:$C25))) | H25: =ROUND('2026'!$I$7/12*8,0)
A26: Setembro | B26: =COUNT('2026'!$X$89:$X$97) | C26: ='2026'!$C$88 | D26: ='2026'!$E$88 | E26: ='2026'!$F$88 | F26: ='2026'!$G$88 | G26: =IF(DATE(2026,9,1)>TODAY(),"",IF(SUM($C$18:$C26)=0,"",SUM($C$18:$C26))) | H26: =ROUND('2026'!$I$7/12*9,0)
A27: Outubro | B27: =COUNT('2026'!$X$94:$X$102) | C27: ='2026'!$C$93 | D27: ='2026'!$E$93 | E27: ='2026'!$F$93 | F27: ='2026'!$G$93 | G27: =IF(DATE(2026,10,1)>TODAY(),"",IF(SUM($C$18:$C27)=0,"",SUM($C$18:$C27))) | H27: =ROUND('2026'!$I$7/12*10,0)
A28: Novembro | B28: =COUNT('2026'!$X$99:$X$107) | C28: ='2026'!$C$98 | D28: ='2026'!$E$98 | E28: ='2026'!$F$98 | F28: ='2026'!$G$98 | G28: =IF(DATE(2026,11,1)>TODAY(),"",IF(SUM($C$18:$C28)=0,"",SUM($C$18:$C28))) | H28: =ROUND('2026'!$I$7/12*11,0)
A29: Dezembro | B29: =COUNT('2026'!$X$104:$X$112) | C29: ='2026'!$C$103 | D29: ='2026'!$E$103 | E29: ='2026'!$F$103 | F29: ='2026'!$G$103 | G29: =IF(DATE(2026,12,1)>TODAY(),"",IF(SUM($C$18:$C29)=0,"",SUM($C$18:$C29))) | H29: =ROUND('2026'!$I$7/12*12,0)
A31: MAIORES SALDOS EM ABERTO DE 2026 ordenado pelo saldo · empate exato mostra o primeiro da lista
A32: # | B32: Cliente | C32: Projeto | D32: Investimento | E32: Recebido | F32: Saldo a receber | G32: % recebido | H32: % do total em aberto
A33: 1 | B33: =IF(COUNT('2026'!$X$10:$X$106)<1,"",IF(LARGE('2026'!$X$10:$X$106,1)<=0,"",INDEX('2026'!$A$10:$A$106,MATCH(LARGE('2026'!$X$10:$X$106,1),'2026'!$X$10:$X$106,0)))) | C33: =IF(COUNT('2026'!$X$10:$X$106)<1,"",IF(LARGE('2026'!$X$10:$X$106,1)<=0,"",INDEX('2026'!$B$10:$B$106,MATCH(LARGE('2026'!$X$10:$X$106,1),'2026'!$X$10:$X$106,0)))) | D33: =IF(COUNT('2026'!$X$10:$X$106)<1,"",IF(LARGE('2026'!$X$10:$X$106,1)<=0,"",INDEX('2026'!$C$10:$C$106,MATCH(LARGE('2026'!$X$10:$X$106,1),'2026'!$X$10:$X$106,0)))) | E33: =IF(COUNT('2026'!$X$10:$X$106)<1,"",IF(LARGE('2026'!$X$10:$X$106,1)<=0,"",INDEX('2026'!$E$10:$E$106,MATCH(LARGE('2026'!$X$10:$X$106,1),'2026'!$X$10:$X$106,0)))) | F33: =IF(COUNT('2026'!$X$10:$X$106)<1,"",IF(LARGE('2026'!$X$10:$X$106,1)<=0,"",LARGE('2026'!$X$10:$X$106,1))) | G33: =IF(COUNT('2026'!$X$10:$X$106)<1,"",IF(LARGE('2026'!$X$10:$X$106,1)<=0,"",INDEX('2026'!$G$10:$G$106,MATCH(LARGE('2026'!$X$10:$X$106,1),'2026'!$X$10:$X$106,0)))) | H33: =IF($F33="","",$F33/'2026'!$F$7)
A34: 2 | B34: =IF(COUNT('2026'!$X$10:$X$106)<2,"",IF(LARGE('2026'!$X$10:$X$106,2)<=0,"",INDEX('2026'!$A$10:$A$106,MATCH(LARGE('2026'!$X$10:$X$106,2),'2026'!$X$10:$X$106,0)))) | C34: =IF(COUNT('2026'!$X$10:$X$106)<2,"",IF(LARGE('2026'!$X$10:$X$106,2)<=0,"",INDEX('2026'!$B$10:$B$106,MATCH(LARGE('2026'!$X$10:$X$106,2),'2026'!$X$10:$X$106,0)))) | D34: =IF(COUNT('2026'!$X$10:$X$106)<2,"",IF(LARGE('2026'!$X$10:$X$106,2)<=0,"",INDEX('2026'!$C$10:$C$106,MATCH(LARGE('2026'!$X$10:$X$106,2),'2026'!$X$10:$X$106,0)))) | E34: =IF(COUNT('2026'!$X$10:$X$106)<2,"",IF(LARGE('2026'!$X$10:$X$106,2)<=0,"",INDEX('2026'!$E$10:$E$106,MATCH(LARGE('2026'!$X$10:$X$106,2),'2026'!$X$10:$X$106,0)))) | F34: =IF(COUNT('2026'!$X$10:$X$106)<2,"",IF(LARGE('2026'!$X$10:$X$106,2)<=0,"",LARGE('2026'!$X$10:$X$106,2))) | G34: =IF(COUNT('2026'!$X$10:$X$106)<2,"",IF(LARGE('2026'!$X$10:$X$106,2)<=0,"",INDEX('2026'!$G$10:$G$106,MATCH(LARGE('2026'!$X$10:$X$106,2),'2026'!$X$10:$X$106,0)))) | H34: =IF($F34="","",$F34/'2026'!$F$7)
A35: 3 | B35: =IF(COUNT('2026'!$X$10:$X$106)<3,"",IF(LARGE('2026'!$X$10:$X$106,3)<=0,"",INDEX('2026'!$A$10:$A$106,MATCH(LARGE('2026'!$X$10:$X$106,3),'2026'!$X$10:$X$106,0)))) | C35: =IF(COUNT('2026'!$X$10:$X$106)<3,"",IF(LARGE('2026'!$X$10:$X$106,3)<=0,"",INDEX('2026'!$B$10:$B$106,MATCH(LARGE('2026'!$X$10:$X$106,3),'2026'!$X$10:$X$106,0)))) | D35: =IF(COUNT('2026'!$X$10:$X$106)<3,"",IF(LARGE('2026'!$X$10:$X$106,3)<=0,"",INDEX('2026'!$C$10:$C$106,MATCH(LARGE('2026'!$X$10:$X$106,3),'2026'!$X$10:$X$106,0)))) | E35: =IF(COUNT('2026'!$X$10:$X$106)<3,"",IF(LARGE('2026'!$X$10:$X$106,3)<=0,"",INDEX('2026'!$E$10:$E$106,MATCH(LARGE('2026'!$X$10:$X$106,3),'2026'!$X$10:$X$106,0)))) | F35: =IF(COUNT('2026'!$X$10:$X$106)<3,"",IF(LARGE('2026'!$X$10:$X$106,3)<=0,"",LARGE('2026'!$X$10:$X$106,3))) | G35: =IF(COUNT('2026'!$X$10:$X$106)<3,"",IF(LARGE('2026'!$X$10:$X$106,3)<=0,"",INDEX('2026'!$G$10:$G$106,MATCH(LARGE('2026'!$X$10:$X$106,3),'2026'!$X$10:$X$106,0)))) | H35: =IF($F35="","",$F35/'2026'!$F$7)
A36: 4 | B36: =IF(COUNT('2026'!$X$10:$X$106)<4,"",IF(LARGE('2026'!$X$10:$X$106,4)<=0,"",INDEX('2026'!$A$10:$A$106,MATCH(LARGE('2026'!$X$10:$X$106,4),'2026'!$X$10:$X$106,0)))) | C36: =IF(COUNT('2026'!$X$10:$X$106)<4,"",IF(LARGE('2026'!$X$10:$X$106,4)<=0,"",INDEX('2026'!$B$10:$B$106,MATCH(LARGE('2026'!$X$10:$X$106,4),'2026'!$X$10:$X$106,0)))) | D36: =IF(COUNT('2026'!$X$10:$X$106)<4,"",IF(LARGE('2026'!$X$10:$X$106,4)<=0,"",INDEX('2026'!$C$10:$C$106,MATCH(LARGE('2026'!$X$10:$X$106,4),'2026'!$X$10:$X$106,0)))) | E36: =IF(COUNT('2026'!$X$10:$X$106)<4,"",IF(LARGE('2026'!$X$10:$X$106,4)<=0,"",INDEX('2026'!$E$10:$E$106,MATCH(LARGE('2026'!$X$10:$X$106,4),'2026'!$X$10:$X$106,0)))) | F36: =IF(COUNT('2026'!$X$10:$X$106)<4,"",IF(LARGE('2026'!$X$10:$X$106,4)<=0,"",LARGE('2026'!$X$10:$X$106,4))) | G36: =IF(COUNT('2026'!$X$10:$X$106)<4,"",IF(LARGE('2026'!$X$10:$X$106,4)<=0,"",INDEX('2026'!$G$10:$G$106,MATCH(LARGE('2026'!$X$10:$X$106,4),'2026'!$X$10:$X$106,0)))) | H36: =IF($F36="","",$F36/'2026'!$F$7)
A37: 5 | B37: =IF(COUNT('2026'!$X$10:$X$106)<5,"",IF(LARGE('2026'!$X$10:$X$106,5)<=0,"",INDEX('2026'!$A$10:$A$106,MATCH(LARGE('2026'!$X$10:$X$106,5),'2026'!$X$10:$X$106,0)))) | C37: =IF(COUNT('2026'!$X$10:$X$106)<5,"",IF(LARGE('2026'!$X$10:$X$106,5)<=0,"",INDEX('2026'!$B$10:$B$106,MATCH(LARGE('2026'!$X$10:$X$106,5),'2026'!$X$10:$X$106,0)))) | D37: =IF(COUNT('2026'!$X$10:$X$106)<5,"",IF(LARGE('2026'!$X$10:$X$106,5)<=0,"",INDEX('2026'!$C$10:$C$106,MATCH(LARGE('2026'!$X$10:$X$106,5),'2026'!$X$10:$X$106,0)))) | E37: =IF(COUNT('2026'!$X$10:$X$106)<5,"",IF(LARGE('2026'!$X$10:$X$106,5)<=0,"",INDEX('2026'!$E$10:$E$106,MATCH(LARGE('2026'!$X$10:$X$106,5),'2026'!$X$10:$X$106,0)))) | F37: =IF(COUNT('2026'!$X$10:$X$106)<5,"",IF(LARGE('2026'!$X$10:$X$106,5)<=0,"",LARGE('2026'!$X$10:$X$106,5))) | G37: =IF(COUNT('2026'!$X$10:$X$106)<5,"",IF(LARGE('2026'!$X$10:$X$106,5)<=0,"",INDEX('2026'!$G$10:$G$106,MATCH(LARGE('2026'!$X$10:$X$106,5),'2026'!$X$10:$X$106,0)))) | H37: =IF($F37="","",$F37/'2026'!$F$7)
A38: 6 | B38: =IF(COUNT('2026'!$X$10:$X$106)<6,"",IF(LARGE('2026'!$X$10:$X$106,6)<=0,"",INDEX('2026'!$A$10:$A$106,MATCH(LARGE('2026'!$X$10:$X$106,6),'2026'!$X$10:$X$106,0)))) | C38: =IF(COUNT('2026'!$X$10:$X$106)<6,"",IF(LARGE('2026'!$X$10:$X$106,6)<=0,"",INDEX('2026'!$B$10:$B$106,MATCH(LARGE('2026'!$X$10:$X$106,6),'2026'!$X$10:$X$106,0)))) | D38: =IF(COUNT('2026'!$X$10:$X$106)<6,"",IF(LARGE('2026'!$X$10:$X$106,6)<=0,"",INDEX('2026'!$C$10:$C$106,MATCH(LARGE('2026'!$X$10:$X$106,6),'2026'!$X$10:$X$106,0)))) | E38: =IF(COUNT('2026'!$X$10:$X$106)<6,"",IF(LARGE('2026'!$X$10:$X$106,6)<=0,"",INDEX('2026'!$E$10:$E$106,MATCH(LARGE('2026'!$X$10:$X$106,6),'2026'!$X$10:$X$106,0)))) | F38: =IF(COUNT('2026'!$X$10:$X$106)<6,"",IF(LARGE('2026'!$X$10:$X$106,6)<=0,"",LARGE('2026'!$X$10:$X$106,6))) | G38: =IF(COUNT('2026'!$X$10:$X$106)<6,"",IF(LARGE('2026'!$X$10:$X$106,6)<=0,"",INDEX('2026'!$G$10:$G$106,MATCH(LARGE('2026'!$X$10:$X$106,6),'2026'!$X$10:$X$106,0)))) | H38: =IF($F38="","",$F38/'2026'!$F$7)
A39: 7 | B39: =IF(COUNT('2026'!$X$10:$X$106)<7,"",IF(LARGE('2026'!$X$10:$X$106,7)<=0,"",INDEX('2026'!$A$10:$A$106,MATCH(LARGE('2026'!$X$10:$X$106,7),'2026'!$X$10:$X$106,0)))) | C39: =IF(COUNT('2026'!$X$10:$X$106)<7,"",IF(LARGE('2026'!$X$10:$X$106,7)<=0,"",INDEX('2026'!$B$10:$B$106,MATCH(LARGE('2026'!$X$10:$X$106,7),'2026'!$X$10:$X$106,0)))) | D39: =IF(COUNT('2026'!$X$10:$X$106)<7,"",IF(LARGE('2026'!$X$10:$X$106,7)<=0,"",INDEX('2026'!$C$10:$C$106,MATCH(LARGE('2026'!$X$10:$X$106,7),'2026'!$X$10:$X$106,0)))) | E39: =IF(COUNT('2026'!$X$10:$X$106)<7,"",IF(LARGE('2026'!$X$10:$X$106,7)<=0,"",INDEX('2026'!$E$10:$E$106,MATCH(LARGE('2026'!$X$10:$X$106,7),'2026'!$X$10:$X$106,0)))) | F39: =IF(COUNT('2026'!$X$10:$X$106)<7,"",IF(LARGE('2026'!$X$10:$X$106,7)<=0,"",LARGE('2026'!$X$10:$X$106,7))) | G39: =IF(COUNT('2026'!$X$10:$X$106)<7,"",IF(LARGE('2026'!$X$10:$X$106,7)<=0,"",INDEX('2026'!$G$10:$G$106,MATCH(LARGE('2026'!$X$10:$X$106,7),'2026'!$X$10:$X$106,0)))) | H39: =IF($F39="","",$F39/'2026'!$F$7)
A40: 8 | B40: =IF(COUNT('2026'!$X$10:$X$106)<8,"",IF(LARGE('2026'!$X$10:$X$106,8)<=0,"",INDEX('2026'!$A$10:$A$106,MATCH(LARGE('2026'!$X$10:$X$106,8),'2026'!$X$10:$X$106,0)))) | C40: =IF(COUNT('2026'!$X$10:$X$106)<8,"",IF(LARGE('2026'!$X$10:$X$106,8)<=0,"",INDEX('2026'!$B$10:$B$106,MATCH(LARGE('2026'!$X$10:$X$106,8),'2026'!$X$10:$X$106,0)))) | D40: =IF(COUNT('2026'!$X$10:$X$106)<8,"",IF(LARGE('2026'!$X$10:$X$106,8)<=0,"",INDEX('2026'!$C$10:$C$106,MATCH(LARGE('2026'!$X$10:$X$106,8),'2026'!$X$10:$X$106,0)))) | E40: =IF(COUNT('2026'!$X$10:$X$106)<8,"",IF(LARGE('2026'!$X$10:$X$106,8)<=0,"",INDEX('2026'!$E$10:$E$106,MATCH(LARGE('2026'!$X$10:$X$106,8),'2026'!$X$10:$X$106,0)))) | F40: =IF(COUNT('2026'!$X$10:$X$106)<8,"",IF(LARGE('2026'!$X$10:$X$106,8)<=0,"",LARGE('2026'!$X$10:$X$106,8))) | G40: =IF(COUNT('2026'!$X$10:$X$106)<8,"",IF(LARGE('2026'!$X$10:$X$106,8)<=0,"",INDEX('2026'!$G$10:$G$106,MATCH(LARGE('2026'!$X$10:$X$106,8),'2026'!$X$10:$X$106,0)))) | H40: =IF($F40="","",$F40/'2026'!$F$7)
A41: 9 | B41: =IF(COUNT('2026'!$X$10:$X$106)<9,"",IF(LARGE('2026'!$X$10:$X$106,9)<=0,"",INDEX('2026'!$A$10:$A$106,MATCH(LARGE('2026'!$X$10:$X$106,9),'2026'!$X$10:$X$106,0)))) | C41: =IF(COUNT('2026'!$X$10:$X$106)<9,"",IF(LARGE('2026'!$X$10:$X$106,9)<=0,"",INDEX('2026'!$B$10:$B$106,MATCH(LARGE('2026'!$X$10:$X$106,9),'2026'!$X$10:$X$106,0)))) | D41: =IF(COUNT('2026'!$X$10:$X$106)<9,"",IF(LARGE('2026'!$X$10:$X$106,9)<=0,"",INDEX('2026'!$C$10:$C$106,MATCH(LARGE('2026'!$X$10:$X$106,9),'2026'!$X$10:$X$106,0)))) | E41: =IF(COUNT('2026'!$X$10:$X$106)<9,"",IF(LARGE('2026'!$X$10:$X$106,9)<=0,"",INDEX('2026'!$E$10:$E$106,MATCH(LARGE('2026'!$X$10:$X$106,9),'2026'!$X$10:$X$106,0)))) | F41: =IF(COUNT('2026'!$X$10:$X$106)<9,"",IF(LARGE('2026'!$X$10:$X$106,9)<=0,"",LARGE('2026'!$X$10:$X$106,9))) | G41: =IF(COUNT('2026'!$X$10:$X$106)<9,"",IF(LARGE('2026'!$X$10:$X$106,9)<=0,"",INDEX('2026'!$G$10:$G$106,MATCH(LARGE('2026'!$X$10:$X$106,9),'2026'!$X$10:$X$106,0)))) | H41: =IF($F41="","",$F41/'2026'!$F$7)
A42: 10 | B42: =IF(COUNT('2026'!$X$10:$X$106)<10,"",IF(LARGE('2026'!$X$10:$X$106,10)<=0,"",INDEX('2026'!$A$10:$A$106,MATCH(LARGE('2026'!$X$10:$X$106,10),'2026'!$X$10:$X$106,0)))) | C42: =IF(COUNT('2026'!$X$10:$X$106)<10,"",IF(LARGE('2026'!$X$10:$X$106,10)<=0,"",INDEX('2026'!$B$10:$B$106,MATCH(LARGE('2026'!$X$10:$X$106,10),'2026'!$X$10:$X$106,0)))) | D42: =IF(COUNT('2026'!$X$10:$X$106)<10,"",IF(LARGE('2026'!$X$10:$X$106,10)<=0,"",INDEX('2026'!$C$10:$C$106,MATCH(LARGE('2026'!$X$10:$X$106,10),'2026'!$X$10:$X$106,0)))) | E42: =IF(COUNT('2026'!$X$10:$X$106)<10,"",IF(LARGE('2026'!$X$10:$X$106,10)<=0,"",INDEX('2026'!$E$10:$E$106,MATCH(LARGE('2026'!$X$10:$X$106,10),'2026'!$X$10:$X$106,0)))) | F42: =IF(COUNT('2026'!$X$10:$X$106)<10,"",IF(LARGE('2026'!$X$10:$X$106,10)<=0,"",LARGE('2026'!$X$10:$X$106,10))) | G42: =IF(COUNT('2026'!$X$10:$X$106)<10,"",IF(LARGE('2026'!$X$10:$X$106,10)<=0,"",INDEX('2026'!$G$10:$G$106,MATCH(LARGE('2026'!$X$10:$X$106,10),'2026'!$X$10:$X$106,0)))) | H42: =IF($F42="","",$F42/'2026'!$F$7)
A43: 11 | B43: =IF(COUNT('2026'!$X$10:$X$106)<11,"",IF(LARGE('2026'!$X$10:$X$106,11)<=0,"",INDEX('2026'!$A$10:$A$106,MATCH(LARGE('2026'!$X$10:$X$106,11),'2026'!$X$10:$X$106,0)))) | C43: =IF(COUNT('2026'!$X$10:$X$106)<11,"",IF(LARGE('2026'!$X$10:$X$106,11)<=0,"",INDEX('2026'!$B$10:$B$106,MATCH(LARGE('2026'!$X$10:$X$106,11),'2026'!$X$10:$X$106,0)))) | D43: =IF(COUNT('2026'!$X$10:$X$106)<11,"",IF(LARGE('2026'!$X$10:$X$106,11)<=0,"",INDEX('2026'!$C$10:$C$106,MATCH(LARGE('2026'!$X$10:$X$106,11),'2026'!$X$10:$X$106,0)))) | E43: =IF(COUNT('2026'!$X$10:$X$106)<11,"",IF(LARGE('2026'!$X$10:$X$106,11)<=0,"",INDEX('2026'!$E$10:$E$106,MATCH(LARGE('2026'!$X$10:$X$106,11),'2026'!$X$10:$X$106,0)))) | F43: =IF(COUNT('2026'!$X$10:$X$106)<11,"",IF(LARGE('2026'!$X$10:$X$106,11)<=0,"",LARGE('2026'!$X$10:$X$106,11))) | G43: =IF(COUNT('2026'!$X$10:$X$106)<11,"",IF(LARGE('2026'!$X$10:$X$106,11)<=0,"",INDEX('2026'!$G$10:$G$106,MATCH(LARGE('2026'!$X$10:$X$106,11),'2026'!$X$10:$X$106,0)))) | H43: =IF($F43="","",$F43/'2026'!$F$7)
A44: 12 | B44: =IF(COUNT('2026'!$X$10:$X$106)<12,"",IF(LARGE('2026'!$X$10:$X$106,12)<=0,"",INDEX('2026'!$A$10:$A$106,MATCH(LARGE('2026'!$X$10:$X$106,12),'2026'!$X$10:$X$106,0)))) | C44: =IF(COUNT('2026'!$X$10:$X$106)<12,"",IF(LARGE('2026'!$X$10:$X$106,12)<=0,"",INDEX('2026'!$B$10:$B$106,MATCH(LARGE('2026'!$X$10:$X$106,12),'2026'!$X$10:$X$106,0)))) | D44: =IF(COUNT('2026'!$X$10:$X$106)<12,"",IF(LARGE('2026'!$X$10:$X$106,12)<=0,"",INDEX('2026'!$C$10:$C$106,MATCH(LARGE('2026'!$X$10:$X$106,12),'2026'!$X$10:$X$106,0)))) | E44: =IF(COUNT('2026'!$X$10:$X$106)<12,"",IF(LARGE('2026'!$X$10:$X$106,12)<=0,"",INDEX('2026'!$E$10:$E$106,MATCH(LARGE('2026'!$X$10:$X$106,12),'2026'!$X$10:$X$106,0)))) | F44: =IF(COUNT('2026'!$X$10:$X$106)<12,"",IF(LARGE('2026'!$X$10:$X$106,12)<=0,"",LARGE('2026'!$X$10:$X$106,12))) | G44: =IF(COUNT('2026'!$X$10:$X$106)<12,"",IF(LARGE('2026'!$X$10:$X$106,12)<=0,"",INDEX('2026'!$G$10:$G$106,MATCH(LARGE('2026'!$X$10:$X$106,12),'2026'!$X$10:$X$106,0)))) | H44: =IF($F44="","",$F44/'2026'!$F$7)
...

Sheet Análise & Sazonalidade
A1: VALVIC MARCENARIA
A2: Vargas Decor Ltda · CNPJ 17.269.304/0001-51 · Belo Horizonte / MG
A3: ANÁLISE & SAZONALIDADE
A4: Fluxo de caixa pela data do pagamento · padrão sazonal de vendas · concentração da carteira
A6: FLUXO DE CAIXA REALIZADO quanto entrou em cada mês, pela DATA DO PAGAMENTO — não pela data do contrato
A7: Mês | B7: 2023 | C7: 2024 | D7: 2025 | E7: 2026 | F7: Média 23–25 | G7: Peso no ano
A8: Janeiro | B8: =ROUND(SUMIFS('2026'!$I$10:$I$107,'2026'!$J$10:$J$107,">="&DATE(2023,1,1),'2026'!$J$10:$J$107,"<"&DATE(2023,2,1))+SUMIFS('2026'!$L$10:$L$107,'2026'!$M$10:$M$107,">="&DATE(2023,1,1),'2026'!$M$10:$M$107,"<"&DATE(2023,2,1))+SUMIFS('2026'!$O$10:$O$107,'2026'!$P$10:$P$107,">="&DATE(2023,1,1),'2026'!$P$10:$P$107,"<"&DATE(2023,2,1))+SUMIFS('2026'!$R$10:$R$107,'2026'!$S$10:$S$107,">="&DATE(2023,1,1),'2026'!$S$10:$S$107,"<"&DATE(2023,2,1))+SUMIFS('2026'!$U$10:$U$107,'2026'!$V$10:$V$107,">="&DATE(2023,1,1),'2026'!$V$10:$V$107,"<"&DATE(2023,2,1))+SUMIFS('2025'!$I$10:$I$112,'2025'!$J$10:$J$112,">="&DATE(2023,1,1),'2025'!$J$10:$J$112,"<"&DATE(2023,2,1))+SUMIFS('2025'!$L$10:$L$112,'2025'!$M$10:$M$112,">="&DATE(2023,1,1),'2025'!$M$10:$M$112,"<"&DATE(2023,2,1))+SUMIFS('2025'!$O$10:$O$112,'2025'!$P$10:$P$112,">="&DATE(2023,1,1),'2025'!$P$10:$P$112,"<"&DATE(2023,2,1))+SUMIFS('2025'!$R$10:$R$112,'2025'!$S$10:$S$112,">="&DATE(2023,1,1),'2025'!$S$10:$S$112,"<"&DATE(2023,2,1))+SUMIFS('2025'!$U$10:$U$112,'2025'!$V$10:$V$112,">="&DATE(2023,1,1),'2025'!$V$10:$V$112,"<"&DATE(2023,2,1))+SUMIFS('2024'!$I$10:$I$108,'2024'!$J$10:$J$108,">="&DATE(2023,1,1),'2024'!$J$10:$J$108,"<"&DATE(2023,2,1))+SUMIFS('2024'!$L$10:$L$108,'2024'!$M$10:$M$108,">="&DATE(2023,1,1),'2024'!$M$10:$M$108,"<"&DATE(2023,2,1))+SUMIFS('2024'!$O$10:$O$108,'2024'!$P$10:$P$108,">="&DATE(2023,1,1),'2024'!$P$10:$P$108,"<"&DATE(2023,2,1))+SUMIFS('2024'!$R$10:$R$108,'2024'!$S$10:$S$108,">="&DATE(2023,1,1),'2024'!$S$10:$S$108,"<"&DATE(2023,2,1))+SUMIFS('2024'!$U$10:$U$108,'2024'!$V$10:$V$108,">="&DATE(2023,1,1),'2024'!$V$10:$V$108,"<"&DATE(2023,2,1))+SUMIFS('2023'!$I$10:$I$127,'2023'!$J$10:$J$127,">="&DATE(2023,1,1),'2023'!$J$10:$J$127,"<"&DATE(2023,2,1))+SUMIFS('2023'!$L$10:$L$127,'2023'!$M$10:$M$127,">="&DATE(2023,1,1),'2023'!$M$10:$M$127,"<"&DATE(2023,2,1))+SUMIFS('2023'!$O$10:$O$127,'2023'!$P$10:$P$127,">="&DATE(2023,1,1),'2023'!$P$10:$P$127,"<"&DATE(2023,2,1))+SUMIFS('2023'!$R$10:$R$127,'2023'!$S$10:$S$127,">="&DATE(2023,1,1),'2023'!$S$10:$S$127,"<"&DATE(2023,2,1))+SUMIFS('2023'!$U$10:$U$127,'2023'!$V$10:$V$127,">="&DATE(2023,1,1),'2023'!$V$10:$V$127,"<"&DATE(2023,2,1)),2) | C8: =ROUND(SUMIFS('2026'!$I$10:$I$107,'2026'!$J$10:$J$107,">="&DATE(2024,1,1),'2026'!$J$10:$J$107,"<"&DATE(2024,2,1))+SUMIFS('2026'!$L$10:$L$107,'2026'!$M$10:$M$107,">="&DATE(2024,1,1),'2026'!$M$10:$M$107,"<"&DATE(2024,2,1))+SUMIFS('2026'!$O$10:$O$107,'2026'!$P$10:$P$107,">="&DATE(2024,1,1),'2026'!$P$10:$P$107,"<"&DATE(2024,2,1))+SUMIFS('2026'!$R$10:$R$107,'2026'!$S$10:$S$107,">="&DATE(2024,1,1),'2026'!$S$10:$S$107,"<"&DATE(2024,2,1))+SUMIFS('2026'!$U$10:$U$107,'2026'!$V$10:$V$107,">="&DATE(2024,1,1),'2026'!$V$10:$V$107,"<"&DATE(2024,2,1))+SUMIFS('2025'!$I$10:$I$112,'2025'!$J$10:$J$112,">="&DATE(2024,1,1),'2025'!$J$10:$J$112,"<"&DATE(2024,2,1))+SUMIFS('2025'!$L$10:$L$112,'2025'!$M$10:$M$112,">="&DATE(2024,1,1),'2025'!$M$10:$M$112,"<"&DATE(2024,2,1))+SUMIFS('2025'!$O$10:$O$112,'2025'!$P$10:$P$112,">="&DATE(2024,1,1),'2025'!$P$10:$P$112,"<"&DATE(2024,2,1))+SUMIFS('2025'!$R$10:$R$112,'2025'!$S$10:$S$112,">="&DATE(2024,1,1),'2025'!$S$10:$S$112,"<"&DATE(2024,2,1))+SUMIFS('2025'!$U$10:$U$112,'2025'!$V$10:$V$112,">="&DATE(2024,1,1),'2025'!$V$10:$V$112,"<"&DATE(2024,2,1))+SUMIFS('2024'!$I$10:$I$108,'2024'!$J$10:$J$108,">="&DATE(2024,1,1),'2024'!$J$10:$J$108,"<"&DATE(2024,2,1))+SUMIFS('2024'!$L$10:$L$108,'2024'!$M$10:$M$108,">="&DATE(2024,1,1),'2024'!$M$10:$M$108,"<"&DATE(2024,2,1))+SUMIFS('2024'!$O$10:$O$108,'2024'!$P$10:$P$108,">="&DATE(2024,1,1),'2024'!$P$10:$P$108,"<"&DATE(2024,2,1))+SUMIFS('2024'!$R$10:$R$108,'2024'!$S$10:$S$108,">="&DATE(2024,1,1),'2024'!$S$10:$S$108,"<"&DATE(2024,2,1))+SUMIFS('2024'!$U$10:$U$108,'2024'!$V$10:$V$108,">="&DATE(2024,1,1),'2024'!$V$10:$V$108,"<"&DATE(2024,2,1))+SUMIFS('2023'!$I$10:$I$127,'2023'!$J$10:$J$127,">="&DATE(2024,1,1),'2023'!$J$10:$J$127,"<"&DATE(2024,2,1))+SUMIFS('2023'!$L$10:$L$127,'2023'!$M$10:$M$127,">="&DATE(2024,1,1),'2023'!$M$10:$M$127,"<"&DATE(2024,2,1))+SUMIFS('2023'!$O$10:$O$127,'2023'!$P$10:$P$127,">="&DATE(2024,1,1),'2023'!$P$10:$P$127,"<"&DATE(2024,2,1))+SUMIFS('2023'!$R$10:$R$127,'2023'!$S$10:$S$127,">="&DATE(2024,1,1),'2023'!$S$10:$S$127,"<"&DATE(2024,2,1))+SUMIFS('2023'!$U$10:$U$127,'2023'!$V$10:$V$127,">="&DATE(2024,1,1),'2023'!$V$10:$V$127,"<"&DATE(2024,2,1)),2) | D8: =ROUND(SUMIFS('2026'!$I$10:$I$107,'2026'!$J$10:$J$107,">="&DATE(2025,1,1),'2026'!$J$10:$J$107,"<"&DATE(2025,2,1))+SUMIFS('2026'!$L$10:$L$107,'2026'!$M$10:$M$107,">="&DATE(2025,1,1),'2026'!$M$10:$M$107,"<"&DATE(2025,2,1))+SUMIFS('2026'!$O$10:$O$107,'2026'!$P$10:$P$107,">="&DATE(2025,1,1),'2026'!$P$10:$P$107,"<"&DATE(2025,2,1))+SUMIFS('2026'!$R$10:$R$107,'2026'!$S$10:$S$107,">="&DATE(2025,1,1),'2026'!$S$10:$S$107,"<"&DATE(2025,2,1))+SUMIFS('2026'!$U$10:$U$107,'2026'!$V$10:$V$107,">="&DATE(2025,1,1),'2026'!$V$10:$V$107,"<"&DATE(2025,2,1))+SUMIFS('2025'!$I$10:$I$112,'2025'!$J$10:$J$112,">="&DATE(2025,1,1),'2025'!$J$10:$J$112,"<"&DATE(2025,2,1))+SUMIFS('2025'!$L$10:$L$112,'2025'!$M$10:$M$112,">="&DATE(2025,1,1),'2025'!$M$10:$M$112,"<"&DATE(2025,2,1))+SUMIFS('2025'!$O$10:$O$112,'2025'!$P$10:$P$112,">="&DATE(2025,1,1),'2025'!$P$10:$P$112,"<"&DATE(2025,2,1))+SUMIFS('2025'!$R$10:$R$112,'2025'!$S$10:$S$112,">="&DATE(2025,1,1),'2025'!$S$10:$S$112,"<"&DATE(2025,2,1))+SUMIFS('2025'!$U$10:$U$112,'2025'!$V$10:$V$112,">="&DATE(2025,1,1),'2025'!$V$10:$V$112,"<"&DATE(2025,2,1))+SUMIFS('2024'!$I$10:$I$108,'2024'!$J$10:$J$108,">="&DATE(2025,1,1),'2024'!$J$10:$J$108,"<"&DATE(2025,2,1))+SUMIFS('2024'!$L$10:$L$108,'2024'!$M$10:$M$108,">="&DATE(2025,1,1),'2024'!$M$10:$M$108,"<"&DATE(2025,2,1))+SUMIFS('2024'!$O$10:$O$108,'2024'!$P$10:$P$108,">="&DATE(2025,1,1),'2024'!$P$10:$P$108,"<"&DATE(2025,2,1))+SUMIFS('2024'!$R$10:$R$108,'2024'!$S$10:$S$108,">="&DATE(2025,1,1),'2024'!$S$10:$S$108,"<"&DATE(2025,2,1))+SUMIFS('2024'!$U$10:$U$108,'2024'!$V$10:$V$108,">="&DATE(2025,1,1),'2024'!$V$10:$V$108,"<"&DATE(2025,2,1))+SUMIFS('2023'!$I$10:$I$127,'2023'!$J$10:$J$127,">="&DATE(2025,1,1),'2023'!$J$10:$J$127,"<"&DATE(2025,2,1))+SUMIFS('2023'!$L$10:$L$127,'2023'!$M$10:$M$127,">="&DATE(2025,1,1),'2023'!$M$10:$M$127,"<"&DATE(2025,2,1))+SUMIFS('2023'!$O$10:$O$127,'2023'!$P$10:$P$127,">="&DATE(2025,1,1),'2023'!$P$10:$P$127,"<"&DATE(2025,2,1))+SUMIFS('2023'!$R$10:$R$127,'2023'!$S$10:$S$127,">="&DATE(2025,1,1),'2023'!$S$10:$S$127,"<"&DATE(2025,2,1))+SUMIFS('2023'!$U$10:$U$127,'2023'!$V$10:$V$127,">="&DATE(2025,1,1),'2023'!$V$10:$V$127,"<"&DATE(2025,2,1)),2) | E8: =ROUND(SUMIFS('2026'!$I$10:$I$107,'2026'!$J$10:$J$107,">="&DATE(2026,1,1),'2026'!$J$10:$J$107,"<"&DATE(2026,2,1))+SUMIFS('2026'!$L$10:$L$107,'2026'!$M$10:$M$107,">="&DATE(2026,1,1),'2026'!$M$10:$M$107,"<"&DATE(2026,2,1))+SUMIFS('2026'!$O$10:$O$107,'2026'!$P$10:$P$107,">="&DATE(2026,1,1),'2026'!$P$10:$P$107,"<"&DATE(2026,2,1))+SUMIFS('2026'!$R$10:$R$107,'2026'!$S$10:$S$107,">="&DATE(2026,1,1),'2026'!$S$10:$S$107,"<"&DATE(2026,2,1))+SUMIFS('2026'!$U$10:$U$107,'2026'!$V$10:$V$107,">="&DATE(2026,1,1),'2026'!$V$10:$V$107,"<"&DATE(2026,2,1))+SUMIFS('2025'!$I$10:$I$112,'2025'!$J$10:$J$112,">="&DATE(2026,1,1),'2025'!$J$10:$J$112,"<"&DATE(2026,2,1))+SUMIFS('2025'!$L$10:$L$112,'2025'!$M$10:$M$112,">="&DATE(2026,1,1),'2025'!$M$10:$M$112,"<"&DATE(2026,2,1))+SUMIFS('2025'!$O$10:$O$112,'2025'!$P$10:$P$112,">="&DATE(2026,1,1),'2025'!$P$10:$P$112,"<"&DATE(2026,2,1))+SUMIFS('2025'!$R$10:$R$112,'2025'!$S$10:$S$112,">="&DATE(2026,1,1),'2025'!$S$10:$S$112,"<"&DATE(2026,2,1))+SUMIFS('2025'!$U$10:$U$112,'2025'!$V$10:$V$112,">="&DATE(2026,1,1),'2025'!$V$10:$V$112,"<"&DATE(2026,2,1))+SUMIFS('2024'!$I$10:$I$108,'2024'!$J$10:$J$108,">="&DATE(2026,1,1),'2024'!$J$10:$J$108,"<"&DATE(2026,2,1))+SUMIFS('2024'!$L$10:$L$108,'2024'!$M$10:$M$108,">="&DATE(2026,1,1),'2024'!$M$10:$M$108,"<"&DATE(2026,2,1))+SUMIFS('2024'!$O$10:$O$108,'2024'!$P$10:$P$108,">="&DATE(2026,1,1),'2024'!$P$10:$P$108,"<"&DATE(2026,2,1))+SUMIFS('2024'!$R$10:$R$108,'2024'!$S$10:$S$108,">="&DATE(2026,1,1),'2024'!$S$10:$S$108,"<"&DATE(2026,2,1))+SUMIFS('2024'!$U$10:$U$108,'2024'!$V$10:$V$108,">="&DATE(2026,1,1),'2024'!$V$10:$V$108,"<"&DATE(2026,2,1))+SUMIFS('2023'!$I$10:$I$127,'2023'!$J$10:$J$127,">="&DATE(2026,1,1),'2023'!$J$10:$J$127,"<"&DATE(2026,2,1))+SUMIFS('2023'!$L$10:$L$127,'2023'!$M$10:$M$127,">="&DATE(2026,1,1),'2023'!$M$10:$M$127,"<"&DATE(2026,2,1))+SUMIFS('2023'!$O$10:$O$127,'2023'!$P$10:$P$127,">="&DATE(2026,1,1),'2023'!$P$10:$P$127,"<"&DATE(2026,2,1))+SUMIFS('2023'!$R$10:$R$127,'2023'!$S$10:$S$127,">="&DATE(2026,1,1),'2023'!$S$10:$S$127,"<"&DATE(2026,2,1))+SUMIFS('2023'!$U$10:$U$127,'2023'!$V$10:$V$127,">="&DATE(2026,1,1),'2023'!$V$10:$V$127,"<"&DATE(2026,2,1)),2) | F8: =ROUND(AVERAGE($B8:$D8),0) | G8: =IF(SUM($F$8:$F$19)=0,"",$F8/SUM($F$8:$F$19))
A9: Fevereiro | B9: =ROUND(SUMIFS('2026'!$I$10:$I$107,'2026'!$J$10:$J$107,">="&DATE(2023,2,1),'2026'!$J$10:$J$107,"<"&DATE(2023,3,1))+SUMIFS('2026'!$L$10:$L$107,'2026'!$M$10:$M$107,">="&DATE(2023,2,1),'2026'!$M$10:$M$107,"<"&DATE(2023,3,1))+SUMIFS('2026'!$O$10:$O$107,'2026'!$P$10:$P$107,">="&DATE(2023,2,1),'2026'!$P$10:$P$107,"<"&DATE(2023,3,1))+SUMIFS('2026'!$R$10:$R$107,'2026'!$S$10:$S$107,">="&DATE(2023,2,1),'2026'!$S$10:$S$107,"<"&DATE(2023,3,1))+SUMIFS('2026'!$U$10:$U$107,'2026'!$V$10:$V$107,">="&DATE(2023,2,1),'2026'!$V$10:$V$107,"<"&DATE(2023,3,1))+SUMIFS('2025'!$I$10:$I$112,'2025'!$J$10:$J$112,">="&DATE(2023,2,1),'2025'!$J$10:$J$112,"<"&DATE(2023,3,1))+SUMIFS('2025'!$L$10:$L$112,'2025'!$M$10:$M$112,">="&DATE(2023,2,1),'2025'!$M$10:$M$112,"<"&DATE(2023,3,1))+SUMIFS('2025'!$O$10:$O$112,'2025'!$P$10:$P$112,">="&DATE(2023,2,1),'2025'!$P$10:$P$112,"<"&DATE(2023,3,1))+SUMIFS('2025'!$R$10:$R$112,'2025'!$S$10:$S$112,">="&DATE(2023,2,1),'2025'!$S$10:$S$112,"<"&DATE(2023,3,1))+SUMIFS('2025'!$U$10:$U$112,'2025'!$V$10:$V$112,">="&DATE(2023,2,1),'2025'!$V$10:$V$112,"<"&DATE(2023,3,1))+SUMIFS('2024'!$I$10:$I$108,'2024'!$J$10:$J$108,">="&DATE(2023,2,1),'2024'!$J$10:$J$108,"<"&DATE(2023,3,1))+SUMIFS('2024'!$L$10:$L$108,'2024'!$M$10:$M$108,">="&DATE(2023,2,1),'2024'!$M$10:$M$108,"<"&DATE(2023,3,1))+SUMIFS('2024'!$O$10:$O$108,'2024'!$P$10:$P$108,">="&DATE(2023,2,1),'2024'!$P$10:$P$108,"<"&DATE(2023,3,1))+SUMIFS('2024'!$R$10:$R$108,'2024'!$S$10:$S$108,">="&DATE(2023,2,1),'2024'!$S$10:$S$108,"<"&DATE(2023,3,1))+SUMIFS('2024'!$U$10:$U$108,'2024'!$V$10:$V$108,">="&DATE(2023,2,1),'2024'!$V$10:$V$108,"<"&DATE(2023,3,1))+SUMIFS('2023'!$I$10:$I$127,'2023'!$J$10:$J$127,">="&DATE(2023,2,1),'2023'!$J$10:$J$127,"<"&DATE(2023,3,1))+SUMIFS('2023'!$L$10:$L$127,'2023'!$M$10:$M$127,">="&DATE(2023,2,1),'2023'!$M$10:$M$127,"<"&DATE(2023,3,1))+SUMIFS('2023'!$O$10:$O$127,'2023'!$P$10:$P$127,">="&DATE(2023,2,1),'2023'!$P$10:$P$127,"<"&DATE(2023,3,1))+SUMIFS('2023'!$R$10:$R$127,'2023'!$S$10:$S$127,">="&DATE(2023,2,1),'2023'!$S$10:$S$127,"<"&DATE(2023,3,1))+SUMIFS('2023'!$U$10:$U$127,'2023'!$V$10:$V$127,">="&DATE(2023,2,1),'2023'!$V$10:$V$127,"<"&DATE(2023,3,1)),2) | C9: =ROUND(SUMIFS('2026'!$I$10:$I$107,'2026'!$J$10:$J$107,">="&DATE(2024,2,1),'2026'!$J$10:$J$107,"<"&DATE(2024,3,1))+SUMIFS('2026'!$L$10:$L$107,'2026'!$M$10:$M$107,">="&DATE(2024,2,1),'2026'!$M$10:$M$107,"<"&DATE(2024,3,1))+SUMIFS('2026'!$O$10:$O$107,'2026'!$P$10:$P$107,">="&DATE(2024,2,1),'2026'!$P$10:$P$107,"<"&DATE(2024,3,1))+SUMIFS('2026'!$R$10:$R$107,'2026'!$S$10:$S$107,">="&DATE(2024,2,1),'2026'!$S$10:$S$107,"<"&DATE(2024,3,1))+SUMIFS('2026'!$U$10:$U$107,'2026'!$V$10:$V$107,">="&DATE(2024,2,1),'2026'!$V$10:$V$107,"<"&DATE(2024,3,1))+SUMIFS('2025'!$I$10:$I$112,'2025'!$J$10:$J$112,">="&DATE(2024,2,1),'2025'!$J$10:$J$112,"<"&DATE(2024,3,1))+SUMIFS('2025'!$L$10:$L$112,'2025'!$M$10:$M$112,">="&DATE(2024,2,1),'2025'!$M$10:$M$112,"<"&DATE(2024,3,1))+SUMIFS('2025'!$O$10:$O$112,'2025'!$P$10:$P$112,">="&DATE(2024,2,1),'2025'!$P$10:$P$112,"<"&DATE(2024,3,1))+SUMIFS('2025'!$R$10:$R$112,'2025'!$S$10:$S$112,">="&DATE(2024,2,1),'2025'!$S$10:$S$112,"<"&DATE(2024,3,1))+SUMIFS('2025'!$U$10:$U$112,'2025'!$V$10:$V$112,">="&DATE(2024,2,1),'2025'!$V$10:$V$112,"<"&DATE(2024,3,1))+SUMIFS('2024'!$I$10:$I$108,'2024'!$J$10:$J$108,">="&DATE(2024,2,1),'2024'!$J$10:$J$108,"<"&DATE(2024,3,1))+SUMIFS('2024'!$L$10:$L$108,'2024'!$M$10:$M$108,">="&DATE(2024,2,1),'2024'!$M$10:$M$108,"<"&DATE(2024,3,1))+SUMIFS('2024'!$O$10:$O$108,'2024'!$P$10:$P$108,">="&DATE(2024,2,1),'2024'!$P$10:$P$108,"<"&DATE(2024,3,1))+SUMIFS('2024'!$R$10:$R$108,'2024'!$S$10:$S$108,">="&DATE(2024,2,1),'2024'!$S$10:$S$108,"<"&DATE(2024,3,1))+SUMIFS('2024'!$U$10:$U$108,'2024'!$V$10:$V$108,">="&DATE(2024,2,1),'2024'!$V$10:$V$108,"<"&DATE(2024,3,1))+SUMIFS('2023'!$I$10:$I$127,'2023'!$J$10:$J$127,">="&DATE(2024,2,1),'2023'!$J$10:$J$127,"<"&DATE(2024,3,1))+SUMIFS('2023'!$L$10:$L$127,'2023'!$M$10:$M$127,">="&DATE(2024,2,1),'2023'!$M$10:$M$127,"<"&DATE(2024,3,1))+SUMIFS('2023'!$O$10:$O$127,'2023'!$P$10:$P$127,">="&DATE(2024,2,1),'2023'!$P$10:$P$127,"<"&DATE(2024,3,1))+SUMIFS('2023'!$R$10:$R$127,'2023'!$S$10:$S$127,">="&DATE(2024,2,1),'2023'!$S$10:$S$127,"<"&DATE(2024,3,1))+SUMIFS('2023'!$U$10:$U$127,'2023'!$V$10:$V$127,">="&DATE(2024,2,1),'2023'!$V$10:$V$127,"<"&DATE(2024,3,1)),2) | D9: =ROUND(SUMIFS('2026'!$I$10:$I$107,'2026'!$J$10:$J$107,">="&DATE(2025,2,1),'2026'!$J$10:$J$107,"<"&DATE(2025,3,1))+SUMIFS('2026'!$L$10:$L$107,'2026'!$M$10:$M$107,">="&DATE(2025,2,1),'2026'!$M$10:$M$107,"<"&DATE(2025,3,1))+SUMIFS('2026'!$O$10:$O$107,'2026'!$P$10:$P$107,">="&DATE(2025,2,1),'2026'!$P$10:$P$107,"<"&DATE(2025,3,1))+SUMIFS('2026'!$R$10:$R$107,'2026'!$S$10:$S$107,">="&DATE(2025,2,1),'2026'!$S$10:$S$107,"<"&DATE(2025,3,1))+SUMIFS('2026'!$U$10:$U$107,'2026'!$V$10:$V$107,">="&DATE(2025,2,1),'2026'!$V$10:$V$107,"<"&DATE(2025,3,1))+SUMIFS('2025'!$I$10:$I$112,'2025'!$J$10:$J$112,">="&DATE(2025,2,1),'2025'!$J$10:$J$112,"<"&DATE(2025,3,1))+SUMIFS('2025'!$L$10:$L$112,'2025'!$M$10:$M$112,">="&DATE(2025,2,1),'2025'!$M$10:$M$112,"<"&DATE(2025,3,1))+SUMIFS('2025'!$O$10:$O$112,'2025'!$P$10:$P$112,">="&DATE(2025,2,1),'2025'!$P$10:$P$112,"<"&DATE(2025,3,1))+SUMIFS('2025'!$R$10:$R$112,'2025'!$S$10:$S$112,">="&DATE(2025,2,1),'2025'!$S$10:$S$112,"<"&DATE(2025,3,1))+SUMIFS('2025'!$U$10:$U$112,'2025'!$V$10:$V$112,">="&DATE(2025,2,1),'2025'!$V$10:$V$112,"<"&DATE(2025,3,1))+SUMIFS('2024'!$I$10:$I$108,'2024'!$J$10:$J$108,">="&DATE(2025,2,1),'2024'!$J$10:$J$108,"<"&DATE(2025,3,1))+SUMIFS('2024'!$L$10:$L$108,'2024'!$M$10:$M$108,">="&DATE(2025,2,1),'2024'!$M$10:$M$108,"<"&DATE(2025,3,1))+SUMIFS('2024'!$O$10:$O$108,'2024'!$P$10:$P$108,">="&DATE(2025,2,1),'2024'!$P$10:$P$108,"<"&DATE(2025,3,1))+SUMIFS('2024'!$R$10:$R$108,'2024'!$S$10:$S$108,">="&DATE(2025,2,1),'2024'!$S$10:$S$108,"<"&DATE(2025,3,1))+SUMIFS('2024'!$U$10:$U$108,'2024'!$V$10:$V$108,">="&DATE(2025,2,1),'2024'!$V$10:$V$108,"<"&DATE(2025,3,1))+SUMIFS('2023'!$I$10:$I$127,'2023'!$J$10:$J$127,">="&DATE(2025,2,1),'2023'!$J$10:$J$127,"<"&DATE(2025,3,1))+SUMIFS('2023'!$L$10:$L$127,'2023'!$M$10:$M$127,">="&DATE(2025,2,1),'2023'!$M$10:$M$127,"<"&DATE(2025,3,1))+SUMIFS('2023'!$O$10:$O$127,'2023'!$P$10:$P$127,">="&DATE(2025,2,1),'2023'!$P$10:$P$127,"<"&DATE(2025,3,1))+SUMIFS('2023'!$R$10:$R$127,'2023'!$S$10:$S$127,">="&DATE(2025,2,1),'2023'!$S$10:$S$127,"<"&DATE(2025,3,1))+SUMIFS('2023'!$U$10:$U$127,'2023'!$V$10:$V$127,">="&DATE(2025,2,1),'2023'!$V$10:$V$127,"<"&DATE(2025,3,1)),2) | E9: =ROUND(SUMIFS('2026'!$I$10:$I$107,'2026'!$J$10:$J$107,">="&DATE(2026,2,1),'2026'!$J$10:$J$107,"<"&DATE(2026,3,1))+SUMIFS('2026'!$L$10:$L$107,'2026'!$M$10:$M$107,">="&DATE(2026,2,1),'2026'!$M$10:$M$107,"<"&DATE(2026,3,1))+SUMIFS('2026'!$O$10:$O$107,'2026'!$P$10:$P$107,">="&DATE(2026,2,1),'2026'!$P$10:$P$107,"<"&DATE(2026,3,1))+SUMIFS('2026'!$R$10:$R$107,'2026'!$S$10:$S$107,">="&DATE(2026,2,1),'2026'!$S$10:$S$107,"<"&DATE(2026,3,1))+SUMIFS('2026'!$U$10:$U$107,'2026'!$V$10:$V$107,">="&DATE(2026,2,1),'2026'!$V$10:$V$107,"<"&DATE(2026,3,1))+SUMIFS('2025'!$I$10:$I$112,'2025'!$J$10:$J$112,">="&DATE(2026,2,1),'2025'!$J$10:$J$112,"<"&DATE(2026,3,1))+SUMIFS('2025'!$L$10:$L$112,'2025'!$M$10:$M$112,">="&DATE(2026,2,1),'2025'!$M$10:$M$112,"<"&DATE(2026,3,1))+SUMIFS('2025'!$O$10:$O$112,'2025'!$P$10:$P$112,">="&DATE(2026,2,1),'2025'!$P$10:$P$112,"<"&DATE(2026,3,1))+SUMIFS('2025'!$R$10:$R$112,'2025'!$S$10:$S$112,">="&DATE(2026,2,1),'2025'!$S$10:$S$112,"<"&DATE(2026,3,1))+SUMIFS('2025'!$U$10:$U$112,'2025'!$V$10:$V$112,">="&DATE(2026,2,1),'2025'!$V$10:$V$112,"<"&DATE(2026,3,1))+SUMIFS('2024'!$I$10:$I$108,'2024'!$J$10:$J$108,">="&DATE(2026,2,1),'2024'!$J$10:$J$108,"<"&DATE(2026,3,1))+SUMIFS('2024'!$L$10:$L$108,'2024'!$M$10:$M$108,">="&DATE(2026,2,1),'2024'!$M$10:$M$108,"<"&DATE(2026,3,1))+SUMIFS('2024'!$O$10:$O$108,'2024'!$P$10:$P$108,">="&DATE(2026,2,1),'2024'!$P$10:$P$108,"<"&DATE(2026,3,1))+SUMIFS('2024'!$R$10:$R$108,'2024'!$S$10:$S$108,">="&DATE(2026,2,1),'2024'!$S$10:$S$108,"<"&DATE(2026,3,1))+SUMIFS('2024'!$U$10:$U$108,'2024'!$V$10:$V$108,">="&DATE(2026,2,1),'2024'!$V$10:$V$108,"<"&DATE(2026,3,1))+SUMIFS('2023'!$I$10:$I$127,'2023'!$J$10:$J$127,">="&DATE(2026,2,1),'2023'!$J$10:$J$127,"<"&DATE(2026,3,1))+SUMIFS('2023'!$L$10:$L$127,'2023'!$M$10:$M$127,">="&DATE(2026,2,1),'2023'!$M$10:$M$127,"<"&DATE(2026,3,1))+SUMIFS('2023'!$O$10:$O$127,'2023'!$P$10:$P$127,">="&DATE(2026,2,1),'2023'!$P$10:$P$127,"<"&DATE(2026,3,1))+SUMIFS('2023'!$R$10:$R$127,'2023'!$S$10:$S$127,">="&DATE(2026,2,1),'2023'!$S$10:$S$127,"<"&DATE(2026,3,1))+SUMIFS('2023'!$U$10:$U$127,'2023'!$V$10:$V$127,">="&DATE(2026,2,1),'2023'!$V$10:$V$127,"<"&DATE(2026,3,1)),2) | F9: =ROUND(AVERAGE($B9:$D9),0) | G9: =IF(SUM($F$8:$F$19)=0,"",$F9/SUM($F$8:$F$19))
A10: Março | B10: =ROUND(SUMIFS('2026'!$I$10:$I$107,'2026'!$J$10:$J$107,">="&DATE(2023,3,1),'2026'!$J$10:$J$107,"<"&DATE(2023,4,1))+SUMIFS('2026'!$L$10:$L$107,'2026'!$M$10:$M$107,">="&DATE(2023,3,1),'2026'!$M$10:$M$107,"<"&DATE(2023,4,1))+SUMIFS('2026'!$O$10:$O$107,'2026'!$P$10:$P$107,">="&DATE(2023,3,1),'2026'!$P$10:$P$107,"<"&DATE(2023,4,1))+SUMIFS('2026'!$R$10:$R$107,'2026'!$S$10:$S$107,">="&DATE(2023,3,1),'2026'!$S$10:$S$107,"<"&DATE(2023,4,1))+SUMIFS('2026'!$U$10:$U$107,'2026'!$V$10:$V$107,">="&DATE(2023,3,1),'2026'!$V$10:$V$107,"<"&DATE(2023,4,1))+SUMIFS('2025'!$I$10:$I$112,'2025'!$J$10:$J$112,">="&DATE(2023,3,1),'2025'!$J$10:$J$112,"<"&DATE(2023,4,1))+SUMIFS('2025'!$L$10:$L$112,'2025'!$M$10:$M$112,">="&DATE(2023,3,1),'2025'!$M$10:$M$112,"<"&DATE(2023,4,1))+SUMIFS('2025'!$O$10:$O$112,'2025'!$P$10:$P$112,">="&DATE(2023,3,1),'2025'!$P$10:$P$112,"<"&DATE(2023,4,1))+SUMIFS('2025'!$R$10:$R$112,'2025'!$S$10:$S$112,">="&DATE(2023,3,1),'2025'!$S$10:$S$112,"<"&DATE(2023,4,1))+SUMIFS('2025'!$U$10:$U$112,'2025'!$V$10:$V$112,">="&DATE(2023,3,1),'2025'!$V$10:$V$112,"<"&DATE(2023,4,1))+SUMIFS('2024'!$I$10:$I$108,'2024'!$J$10:$J$108,">="&DATE(2023,3,1),'2024'!$J$10:$J$108,"<"&DATE(2023,4,1))+SUMIFS('2024'!$L$10:$L$108,'2024'!$M$10:$M$108,">="&DATE(2023,3,1),'2024'!$M$10:$M$108,"<"&DATE(2023,4,1))+SUMIFS('2024'!$O$10:$O$108,'2024'!$P$10:$P$108,">="&DATE(2023,3,1),'2024'!$P$10:$P$108,"<"&DATE(2023,4,1))+SUMIFS('2024'!$R$10:$R$108,'2024'!$S$10:$S$108,">="&DATE(2023,3,1),'2024'!$S$10:$S$108,"<"&DATE(2023,4,1))+SUMIFS('2024'!$U$10:$U$108,'2024'!$V$10:$V$108,">="&DATE(2023,3,1),'2024'!$V$10:$V$108,"<"&DATE(2023,4,1))+SUMIFS('2023'!$I$10:$I$127,'2023'!$J$10:$J$127,">="&DATE(2023,3,1),'2023'!$J$10:$J$127,"<"&DATE(2023,4,1))+SUMIFS('2023'!$L$10:$L$127,'2023'!$M$10:$M$127,">="&DATE(2023,3,1),'2023'!$M$10:$M$127,"<"&DATE(2023,4,1))+SUMIFS('2023'!$O$10:$O$127,'2023'!$P$10:$P$127,">="&DATE(2023,3,1),'2023'!$P$10:$P$127,"<"&DATE(2023,4,1))+SUMIFS('2023'!$R$10:$R$127,'2023'!$S$10:$S$127,">="&DATE(2023,3,1),'2023'!$S$10:$S$127,"<"&DATE(2023,4,1))+SUMIFS('2023'!$U$10:$U$127,'2023'!$V$10:$V$127,">="&DATE(2023,3,1),'2023'!$V$10:$V$127,"<"&DATE(2023,4,1)),2) | C10: =ROUND(SUMIFS('2026'!$I$10:$I$107,'2026'!$J$10:$J$107,">="&DATE(2024,3,1),'2026'!$J$10:$J$107,"<"&DATE(2024,4,1))+SUMIFS('2026'!$L$10:$L$107,'2026'!$M$10:$M$107,">="&DATE(2024,3,1),'2026'!$M$10:$M$107,"<"&DATE(2024,4,1))+SUMIFS('2026'!$O$10:$O$107,'2026'!$P$10:$P$107,">="&DATE(2024,3,1),'2026'!$P$10:$P$107,"<"&DATE(2024,4,1))+SUMIFS('2026'!$R$10:$R$107,'2026'!$S$10:$S$107,">="&DATE(2024,3,1),'2026'!$S$10:$S$107,"<"&DATE(2024,4,1))+SUMIFS('2026'!$U$10:$U$107,'2026'!$V$10:$V$107,">="&DATE(2024,3,1),'2026'!$V$10:$V$107,"<"&DATE(2024,4,1))+SUMIFS('2025'!$I$10:$I$112,'2025'!$J$10:$J$112,">="&DATE(2024,3,1),'2025'!$J$10:$J$112,"<"&DATE(2024,4,1))+SUMIFS('2025'!$L$10:$L$112,'2025'!$M$10:$M$112,">="&DATE(2024,3,1),'2025'!$M$10:$M$112,"<"&DATE(2024,4,1))+SUMIFS('2025'!$O$10:$O$112,'2025'!$P$10:$P$112,">="&DATE(2024,3,1),'2025'!$P$10:$P$112,"<"&DATE(2024,4,1))+SUMIFS('2025'!$R$10:$R$112,'2025'!$S$10:$S$112,">="&DATE(2024,3,1),'2025'!$S$10:$S$112,"<"&DATE(2024,4,1))+SUMIFS('2025'!$U$10:$U$112,'2025'!$V$10:$V$112,">="&DATE(2024,3,1),'2025'!$V$10:$V$112,"<"&DATE(2024,4,1))+SUMIFS('2024'!$I$10:$I$108,'2024'!$J$10:$J$108,">="&DATE(2024,3,1),'2024'!$J$10:$J$108,"<"&DATE(2024,4,1))+SUMIFS('2024'!$L$10:$L$108,'2024'!$M$10:$M$108,">="&DATE(2024,3,1),'2024'!$M$10:$M$108,"<"&DATE(2024,4,1))+SUMIFS('2024'!$O$10:$O$108,'2024'!$P$10:$P$108,">="&DATE(2024,3,1),'2024'!$P$10:$P$108,"<"&DATE(2024,4,1))+SUMIFS('2024'!$R$10:$R$108,'2024'!$S$10:$S$108,">="&DATE(2024,3,1),'2024'!$S$10:$S$108,"<"&DATE(2024,4,1))+SUMIFS('2024'!$U$10:$U$108,'2024'!$V$10:$V$108,">="&DATE(2024,3,1),'2024'!$V$10:$V$108,"<"&DATE(2024,4,1))+SUMIFS('2023'!$I$10:$I$127,'2023'!$J$10:$J$127,">="&DATE(2024,3,1),'2023'!$J$10:$J$127,"<"&DATE(2024,4,1))+SUMIFS('2023'!$L$10:$L$127,'2023'!$M$10:$M$127,">="&DATE(2024,3,1),'2023'!$M$10:$M$127,"<"&DATE(2024,4,1))+SUMIFS('2023'!$O$10:$O$127,'2023'!$P$10:$P$127,">="&DATE(2024,3,1),'2023'!$P$10:$P$127,"<"&DATE(2024,4,1))+SUMIFS('2023'!$R$10:$R$127,'2023'!$S$10:$S$127,">="&DATE(2024,3,1),'2023'!$S$10:$S$127,"<"&DATE(2024,4,1))+SUMIFS('2023'!$U$10:$U$127,'2023'!$V$10:$V$127,">="&DATE(2024,3,1),'2023'!$V$10:$V$127,"<"&DATE(2024,4,1)),2) | D10: =ROUND(SUMIFS('2026'!$I$10:$I$107,'2026'!$J$10:$J$107,">="&DATE(2025,3,1),'2026'!$J$10:$J$107,"<"&DATE(2025,4,1))+SUMIFS('2026'!$L$10:$L$107,'2026'!$M$10:$M$107,">="&DATE(2025,3,1),'2026'!$M$10:$M$107,"<"&DATE(2025,4,1))+SUMIFS('2026'!$O$10:$O$107,'2026'!$P$10:$P$107,">="&DATE(2025,3,1),'2026'!$P$10:$P$107,"<"&DATE(2025,4,1))+SUMIFS('2026'!$R$10:$R$107,'2026'!$S$10:$S$107,">="&DATE(2025,3,1),'2026'!$S$10:$S$107,"<"&DATE(2025,4,1))+SUMIFS('2026'!$U$10:$U$107,'2026'!$V$10:$V$107,">="&DATE(2025,3,1),'2026'!$V$10:$V$107,"<"&DATE(2025,4,1))+SUMIFS('2025'!$I$10:$I$112,'2025'!$J$10:$J$112,">="&DATE(2025,3,1),'2025'!$J$10:$J$112,"<"&DATE(2025,4,1))+SUMIFS('2025'!$L$10:$L$112,'2025'!$M$10:$M$112,">="&DATE(2025,3,1),'2025'!$M$10:$M$112,"<"&DATE(2025,4,1))+SUMIFS('2025'!$O$10:$O$112,'2025'!$P$10:$P$112,">="&DATE(2025,3,1),'2025'!$P$10:$P$112,"<"&DATE(2025,4,1))+SUMIFS('2025'!$R$10:$R$112,'2025'!$S$10:$S$112,">="&DATE(2025,3,1),'2025'!$S$10:$S$112,"<"&DATE(2025,4,1))+SUMIFS('2025'!$U$10:$U$112,'2025'!$V$10:$V$112,">="&DATE(2025,3,1),'2025'!$V$10:$V$112,"<"&DATE(2025,4,1))+SUMIFS('2024'!$I$10:$I$108,'2024'!$J$10:$J$108,">="&DATE(2025,3,1),'2024'!$J$10:$J$108,"<"&DATE(2025,4,1))+SUMIFS('2024'!$L$10:$L$108,'2024'!$M$10:$M$108,">="&DATE(2025,3,1),'2024'!$M$10:$M$108,"<"&DATE(2025,4,1))+SUMIFS('2024'!$O$10:$O$108,'2024'!$P$10:$P$108,">="&DATE(2025,3,1),'2024'!$P$10:$P$108,"<"&DATE(2025,4,1))+SUMIFS('2024'!$R$10:$R$108,'2024'!$S$10:$S$108,">="&DATE(2025,3,1),'2024'!$S$10:$S$108,"<"&DATE(2025,4,1))+SUMIFS('2024'!$U$10:$U$108,'2024'!$V$10:$V$108,">="&DATE(2025,3,1),'2024'!$V$10:$V$108,"<"&DATE(2025,4,1))+SUMIFS('2023'!$I$10:$I$127,'2023'!$J$10:$J$127,">="&DATE(2025,3,1),'2023'!$J$10:$J$127,"<"&DATE(2025,4,1))+SUMIFS('2023'!$L$10:$L$127,'2023'!$M$10:$M$127,">="&DATE(2025,3,1),'2023'!$M$10:$M$127,"<"&DATE(2025,4,1))+SUMIFS('2023'!$O$10:$O$127,'2023'!$P$10:$P$127,">="&DATE(2025,3,1),'2023'!$P$10:$P$127,"<"&DATE(2025,4,1))+SUMIFS('2023'!$R$10:$R$127,'2023'!$S$10:$S$127,">="&DATE(2025,3,1),'2023'!$S$10:$S$127,"<"&DATE(2025,4,1))+SUMIFS('2023'!$U$10:$U$127,'2023'!$V$10:$V$127,">="&DATE(2025,3,1),'2023'!$V$10:$V$127,"<"&DATE(2025,4,1)),2) | E10: =ROUND(SUMIFS('2026'!$I$10:$I$107,'2026'!$J$10:$J$107,">="&DATE(2026,3,1),'2026'!$J$10:$J$107,"<"&DATE(2026,4,1))+SUMIFS('2026'!$L$10:$L$107,'2026'!$M$10:$M$107,">="&DATE(2026,3,1),'2026'!$M$10:$M$107,"<"&DATE(2026,4,1))+SUMIFS('2026'!$O$10:$O$107,'2026'!$P$10:$P$107,">="&DATE(2026,3,1),'2026'!$P$10:$P$107,"<"&DATE(2026,4,1))+SUMIFS('2026'!$R$10:$R$107,'2026'!$S$10:$S$107,">="&DATE(2026,3,1),'2026'!$S$10:$S$107,"<"&DATE(2026,4,1))+SUMIFS('2026'!$U$10:$U$107,'2026'!$V$10:$V$107,">="&DATE(2026,3,1),'2026'!$V$10:$V$107,"<"&DATE(2026,4,1))+SUMIFS('2025'!$I$10:$I$112,'2025'!$J$10:$J$112,">="&DATE(2026,3,1),'2025'!$J$10:$J$112,"<"&DATE(2026,4,1))+SUMIFS('2025'!$L$10:$L$112,'2025'!$M$10:$M$112,">="&DATE(2026,3,1),'2025'!$M$10:$M$112,"<"&DATE(2026,4,1))+SUMIFS('2025'!$O$10:$O$112,'2025'!$P$10:$P$112,">="&DATE(2026,3,1),'2025'!$P$10:$P$112,"<"&DATE(2026,4,1))+SUMIFS('2025'!$R$10:$R$112,'2025'!$S$10:$S$112,">="&DATE(2026,3,1),'2025'!$S$10:$S$112,"<"&DATE(2026,4,1))+SUMIFS('2025'!$U$10:$U$112,'2025'!$V$10:$V$112,">="&DATE(2026,3,1),'2025'!$V$10:$V$112,"<"&DATE(2026,4,1))+SUMIFS('2024'!$I$10:$I$108,'2024'!$J$10:$J$108,">="&DATE(2026,3,1),'2024'!$J$10:$J$108,"<"&DATE(2026,4,1))+SUMIFS('2024'!$L$10:$L$108,'2024'!$M$10:$M$108,">="&DATE(2026,3,1),'2024'!$M$10:$M$108,"<"&DATE(2026,4,1))+SUMIFS('2024'!$O$10:$O$108,'2024'!$P$10:$P$108,">="&DATE(2026,3,1),'2024'!$P$10:$P$108,"<"&DATE(2026,4,1))+SUMIFS('2024'!$R$10:$R$108,'2024'!$S$10:$S$108,">="&DATE(2026,3,1),'2024'!$S$10:$S$108,"<"&DATE(2026,4,1))+SUMIFS('2024'!$U$10:$U$108,'2024'!$V$10:$V$108,">="&DATE(2026,3,1),'2024'!$V$10:$V$108,"<"&DATE(2026,4,1))+SUMIFS('2023'!$I$10:$I$127,'2023'!$J$10:$J$127,">="&DATE(2026,3,1),'2023'!$J$10:$J$127,"<"&DATE(2026,4,1))+SUMIFS('2023'!$L$10:$L$127,'2023'!$M$10:$M$127,">="&DATE(2026,3,1),'2023'!$M$10:$M$127,"<"&DATE(2026,4,1))+SUMIFS('2023'!$O$10:$O$127,'2023'!$P$10:$P$127,">="&DATE(2026,3,1),'2023'!$P$10:$P$127,"<"&DATE(2026,4,1))+SUMIFS('2023'!$R$10:$R$127,'2023'!$S$10:$S$127,">="&DATE(2026,3,1),'2023'!$S$10:$S$127,"<"&DATE(2026,4,1))+SUMIFS('2023'!$U$10:$U$127,'2023'!$V$10:$V$127,">="&DATE(2026,3,1),'2023'!$V$10:$V$127,"<"&DATE(2026,4,1)),2) | F10: =ROUND(AVERAGE($B10:$D10),0) | G10: =IF(SUM($F$8:$F$19)=0,"",$F10/SUM($F$8:$F$19))
A11: Abril | B11: =ROUND(SUMIFS('2026'!$I$10:$I$107,'2026'!$J$10:$J$107,">="&DATE(2023,4,1),'2026'!$J$10:$J$107,"<"&DATE(2023,5,1))+SUMIFS('2026'!$L$10:$L$107,'2026'!$M$10:$M$107,">="&DATE(2023,4,1),'2026'!$M$10:$M$107,"<"&DATE(2023,5,1))+SUMIFS('2026'!$O$10:$O$107,'2026'!$P$10:$P$107,">="&DATE(2023,4,1),'2026'!$P$10:$P$107,"<"&DATE(2023,5,1))+SUMIFS('2026'!$R$10:$R$107,'2026'!$S$10:$S$107,">="&DATE(2023,4,1),'2026'!$S$10:$S$107,"<"&DATE(2023,5,1))+SUMIFS('2026'!$U$10:$U$107,'2026'!$V$10:$V$107,">="&DATE(2023,4,1),'2026'!$V$10:$V$107,"<"&DATE(2023,5,1))+SUMIFS('2025'!$I$10:$I$112,'2025'!$J$10:$J$112,">="&DATE(2023,4,1),'2025'!$J$10:$J$112,"<"&DATE(2023,5,1))+SUMIFS('2025'!$L$10:$L$112,'2025'!$M$10:$M$112,">="&DATE(2023,4,1),'2025'!$M$10:$M$112,"<"&DATE(2023,5,1))+SUMIFS('2025'!$O$10:$O$112,'2025'!$P$10:$P$112,">="&DATE(2023,4,1),'2025'!$P$10:$P$112,"<"&DATE(2023,5,1))+SUMIFS('2025'!$R$10:$R$112,'2025'!$S$10:$S$112,">="&DATE(2023,4,1),'2025'!$S$10:$S$112,"<"&DATE(2023,5,1))+SUMIFS('2025'!$U$10:$U$112,'2025'!$V$10:$V$112,">="&DATE(2023,4,1),'2025'!$V$10:$V$112,"<"&DATE(2023,5,1))+SUMIFS('2024'!$I$10:$I$108,'2024'!$J$10:$J$108,">="&DATE(2023,4,1),'2024'!$J$10:$J$108,"<"&DATE(2023,5,1))+SUMIFS('2024'!$L$10:$L$108,'2024'!$M$10:$M$108,">="&DATE(2023,4,1),'2024'!$M$10:$M$108,"<"&DATE(2023,5,1))+SUMIFS('2024'!$O$10:$O$108,'2024'!$P$10:$P$108,">="&DATE(2023,4,1),'2024'!$P$10:$P$108,"<"&DATE(2023,5,1))+SUMIFS('2024'!$R$10:$R$108,'2024'!$S$10:$S$108,">="&DATE(2023,4,1),'2024'!$S$10:$S$108,"<"&DATE(2023,5,1))+SUMIFS('2024'!$U$10:$U$108,'2024'!$V$10:$V$108,">="&DATE(2023,4,1),'2024'!$V$10:$V$108,"<"&DATE(2023,5,1))+SUMIFS('2023'!$I$10:$I$127,'2023'!$J$10:$J$127,">="&DATE(2023,4,1),'2023'!$J$10:$J$127,"<"&DATE(2023,5,1))+SUMIFS('2023'!$L$10:$L$127,'2023'!$M$10:$M$127,">="&DATE(2023,4,1),'2023'!$M$10:$M$127,"<"&DATE(2023,5,1))+SUMIFS('2023'!$O$10:$O$127,'2023'!$P$10:$P$127,">="&DATE(2023,4,1),'2023'!$P$10:$P$127,"<"&DATE(2023,5,1))+SUMIFS('2023'!$R$10:$R$127,'2023'!$S$10:$S$127,">="&DATE(2023,4,1),'2023'!$S$10:$S$127,"<"&DATE(2023,5,1))+SUMIFS('2023'!$U$10:$U$127,'2023'!$V$10:$V$127,">="&DATE(2023,4,1),'2023'!$V$10:$V$127,"<"&DATE(2023,5,1)),2) | C11: =ROUND(SUMIFS('2026'!$I$10:$I$107,'2026'!$J$10:$J$107,">="&DATE(2024,4,1),'2026'!$J$10:$J$107,"<"&DATE(2024,5,1))+SUMIFS('2026'!$L$10:$L$107,'2026'!$M$10:$M$107,">="&DATE(2024,4,1),'2026'!$M$10:$M$107,"<"&DATE(2024,5,1))+SUMIFS('2026'!$O$10:$O$107,'2026'!$P$10:$P$107,">="&DATE(2024,4,1),'2026'!$P$10:$P$107,"<"&DATE(2024,5,1))+SUMIFS('2026'!$R$10:$R$107,'2026'!$S$10:$S$107,">="&DATE(2024,4,1),'2026'!$S$10:$S$107,"<"&DATE(2024,5,1))+SUMIFS('2026'!$U$10:$U$107,'2026'!$V$10:$V$107,">="&DATE(2024,4,1),'2026'!$V$10:$V$107,"<"&DATE(2024,5,1))+SUMIFS('2025'!$I$10:$I$112,'2025'!$J$10:$J$112,">="&DATE(2024,4,1),'2025'!$J$10:$J$112,"<"&DATE(2024,5,1))+SUMIFS('2025'!$L$10:$L$112,'2025'!$M$10:$M$112,">="&DATE(2024,4,1),'2025'!$M$10:$M$112,"<"&DATE(2024,5,1))+SUMIFS('2025'!$O$10:$O$112,'2025'!$P$10:$P$112,">="&DATE(2024,4,1),'2025'!$P$10:$P$112,"<"&DATE(2024,5,1))+SUMIFS('2025'!$R$10:$R$112,'2025'!$S$10:$S$112,">="&DATE(2024,4,1),'2025'!$S$10:$S$112,"<"&DATE(2024,5,1))+SUMIFS('2025'!$U$10:$U$112,'2025'!$V$10:$V$112,">="&DATE(2024,4,1),'2025'!$V$10:$V$112,"<"&DATE(2024,5,1))+SUMIFS('2024'!$I$10:$I$108,'2024'!$J$10:$J$108,">="&DATE(2024,4,1),'2024'!$J$10:$J$108,"<"&DATE(2024,5,1))+SUMIFS('2024'!$L$10:$L$108,'2024'!$M$10:$M$108,">="&DATE(2024,4,1),'2024'!$M$10:$M$108,"<"&DATE(2024,5,1))+SUMIFS('2024'!$O$10:$O$108,'2024'!$P$10:$P$108,">="&DATE(2024,4,1),'2024'!$P$10:$P$108,"<"&DATE(2024,5,1))+SUMIFS('2024'!$R$10:$R$108,'2024'!$S$10:$S$108,">="&DATE(2024,4,1),'2024'!$S$10:$S$108,"<"&DATE(2024,5,1))+SUMIFS('2024'!$U$10:$U$108,'2024'!$V$10:$V$108,">="&DATE(2024,4,1),'2024'!$V$10:$V$108,"<"&DATE(2024,5,1))+SUMIFS('2023'!$I$10:$I$127,'2023'!$J$10:$J$127,">="&DATE(2024,4,1),'2023'!$J$10:$J$127,"<"&DATE(2024,5,1))+SUMIFS('2023'!$L$10:$L$127,'2023'!$M$10:$M$127,">="&DATE(2024,4,1),'2023'!$M$10:$M$127,"<"&DATE(2024,5,1))+SUMIFS('2023'!$O$10:$O$127,'2023'!$P$10:$P$127,">="&DATE(2024,4,1),'2023'!$P$10:$P$127,"<"&DATE(2024,5,1))+SUMIFS('2023'!$R$10:$R$127,'2023'!$S$10:$S$127,">="&DATE(2024,4,1),'2023'!$S$10:$S$127,"<"&DATE(2024,5,1))+SUMIFS('2023'!$U$10:$U$127,'2023'!$V$10:$V$127,">="&DATE(2024,4,1),'2023'!$V$10:$V$127,"<"&DATE(2024,5,1)),2) | D11: =ROUND(SUMIFS('2026'!$I$10:$I$107,'2026'!$J$10:$J$107,">="&DATE(2025,4,1),'2026'!$J$10:$J$107,"<"&DATE(2025,5,1))+SUMIFS('2026'!$L$10:$L$107,'2026'!$M$10:$M$107,">="&DATE(2025,4,1),'2026'!$M$10:$M$107,"<"&DATE(2025,5,1))+SUMIFS('2026'!$O$10:$O$107,'2026'!$P$10:$P$107,">="&DATE(2025,4,1),'2026'!$P$10:$P$107,"<"&DATE(2025,5,1))+SUMIFS('2026'!$R$10:$R$107,'2026'!$S$10:$S$107,">="&DATE(2025,4,1),'2026'!$S$10:$S$107,"<"&DATE(2025,5,1))+SUMIFS('2026'!$U$10:$U$107,'2026'!$V$10:$V$107,">="&DATE(2025,4,1),'2026'!$V$10:$V$107,"<"&DATE(2025,5,1))+SUMIFS('2025'!$I$10:$I$112,'2025'!$J$10:$J$112,">="&DATE(2025,4,1),'2025'!$J$10:$J$112,"<"&DATE(2025,5,1))+SUMIFS('2025'!$L$10:$L$112,'2025'!$M$10:$M$112,">="&DATE(2025,4,1),'2025'!$M$10:$M$112,"<"&DATE(2025,5,1))+SUMIFS('2025'!$O$10:$O$112,'2025'!$P$10:$P$112,">="&DATE(2025,4,1),'2025'!$P$10:$P$112,"<"&DATE(2025,5,1))+SUMIFS('2025'!$R$10:$R$112,'2025'!$S$10:$S$112,">="&DATE(2025,4,1),'2025'!$S$10:$S$112,"<"&DATE(2025,5,1))+SUMIFS('2025'!$U$10:$U$112,'2025'!$V$10:$V$112,">="&DATE(2025,4,1),'2025'!$V$10:$V$112,"<"&DATE(2025,5,1))+SUMIFS('2024'!$I$10:$I$108,'2024'!$J$10:$J$108,">="&DATE(2025,4,1),'2024'!$J$10:$J$108,"<"&DATE(2025,5,1))+SUMIFS('2024'!$L$10:$L$108,'2024'!$M$10:$M$108,">="&DATE(2025,4,1),'2024'!$M$10:$M$108,"<"&DATE(2025,5,1))+SUMIFS('2024'!$O$10:$O$108,'2024'!$P$10:$P$108,">="&DATE(2025,4,1),'2024'!$P$10:$P$108,"<"&DATE(2025,5,1))+SUMIFS('2024'!$R$10:$R$108,'2024'!$S$10:$S$108,">="&DATE(2025,4,1),'2024'!$S$10:$S$108,"<"&DATE(2025,5,1))+SUMIFS('2024'!$U$10:$U$108,'2024'!$V$10:$V$108,">="&DATE(2025,4,1),'2024'!$V$10:$V$108,"<"&DATE(2025,5,1))+SUMIFS('2023'!$I$10:$I$127,'2023'!$J$10:$J$127,">="&DATE(2025,4,1),'2023'!$J$10:$J$127,"<"&DATE(2025,5,1))+SUMIFS('2023'!$L$10:$L$127,'2023'!$M$10:$M$127,">="&DATE(2025,4,1),'2023'!$M$10:$M$127,"<"&DATE(2025,5,1))+SUMIFS('2023'!$O$10:$O$127,'2023'!$P$10:$P$127,">="&DATE(2025,4,1),'2023'!$P$10:$P$127,"<"&DATE(2025,5,1))+SUMIFS('2023'!$R$10:$R$127,'2023'!$S$10:$S$127,">="&DATE(2025,4,1),'2023'!$S$10:$S$127,"<"&DATE(2025,5,1))+SUMIFS('2023'!$U$10:$U$127,'2023'!$V$10:$V$127,">="&DATE(2025,4,1),'2023'!$V$10:$V$127,"<"&DATE(2025,5,1)),2) | E11: =ROUND(SUMIFS('2026'!$I$10:$I$107,'2026'!$J$10:$J$107,">="&DATE(2026,4,1),'2026'!$J$10:$J$107,"<"&DATE(2026,5,1))+SUMIFS('2026'!$L$10:$L$107,'2026'!$M$10:$M$107,">="&DATE(2026,4,1),'2026'!$M$10:$M$107,"<"&DATE(2026,5,1))+SUMIFS('2026'!$O$10:$O$107,'2026'!$P$10:$P$107,">="&DATE(2026,4,1),'2026'!$P$10:$P$107,"<"&DATE(2026,5,1))+SUMIFS('2026'!$R$10:$R$107,'2026'!$S$10:$S$107,">="&DATE(2026,4,1),'2026'!$S$10:$S$107,"<"&DATE(2026,5,1))+SUMIFS('2026'!$U$10:$U$107,'2026'!$V$10:$V$107,">="&DATE(2026,4,1),'2026'!$V$10:$V$107,"<"&DATE(2026,5,1))+SUMIFS('2025'!$I$10:$I$112,'2025'!$J$10:$J$112,">="&DATE(2026,4,1),'2025'!$J$10:$J$112,"<"&DATE(2026,5,1))+SUMIFS('2025'!$L$10:$L$112,'2025'!$M$10:$M$112,">="&DATE(2026,4,1),'2025'!$M$10:$M$112,"<"&DATE(2026,5,1))+SUMIFS('2025'!$O$10:$O$112,'2025'!$P$10:$P$112,">="&DATE(2026,4,1),'2025'!$P$10:$P$112,"<"&DATE(2026,5,1))+SUMIFS('2025'!$R$10:$R$112,'2025'!$S$10:$S$112,">="&DATE(2026,4,1),'2025'!$S$10:$S$112,"<"&DATE(2026,5,1))+SUMIFS('2025'!$U$10:$U$112,'2025'!$V$10:$V$112,">="&DATE(2026,4,1),'2025'!$V$10:$V$112,"<"&DATE(2026,5,1))+SUMIFS('2024'!$I$10:$I$108,'2024'!$J$10:$J$108,">="&DATE(2026,4,1),'2024'!$J$10:$J$108,"<"&DATE(2026,5,1))+SUMIFS('2024'!$L$10:$L$108,'2024'!$M$10:$M$108,">="&DATE(2026,4,1),'2024'!$M$10:$M$108,"<"&DATE(2026,5,1))+SUMIFS('2024'!$O$10:$O$108,'2024'!$P$10:$P$108,">="&DATE(2026,4,1),'2024'!$P$10:$P$108,"<"&DATE(2026,5,1))+SUMIFS('2024'!$R$10:$R$108,'2024'!$S$10:$S$108,">="&DATE(2026,4,1),'2024'!$S$10:$S$108,"<"&DATE(2026,5,1))+SUMIFS('2024'!$U$10:$U$108,'2024'!$V$10:$V$108,">="&DATE(2026,4,1),'2024'!$V$10:$V$108,"<"&DATE(2026,5,1))+SUMIFS('2023'!$I$10:$I$127,'2023'!$J$10:$J$127,">="&DATE(2026,4,1),'2023'!$J$10:$J$127,"<"&DATE(2026,5,1))+SUMIFS('2023'!$L$10:$L$127,'2023'!$M$10:$M$127,">="&DATE(2026,4,1),'2023'!$M$10:$M$127,"<"&DATE(2026,5,1))+SUMIFS('2023'!$O$10:$O$127,'2023'!$P$10:$P$127,">="&DATE(2026,4,1),'2023'!$P$10:$P$127,"<"&DATE(2026,5,1))+SUMIFS('2023'!$R$10:$R$127,'2023'!$S$10:$S$127,">="&DATE(2026,4,1),'2023'!$S$10:$S$127,"<"&DATE(2026,5,1))+SUMIFS('2023'!$U$10:$U$127,'2023'!$V$10:$V$127,">="&DATE(2026,4,1),'2023'!$V$10:$V$127,"<"&DATE(2026,5,1)),2) | F11: =ROUND(AVERAGE($B11:$D11),0) | G11: =IF(SUM($F$8:$F$19)=0,"",$F11/SUM($F$8:$F$19))
