Workbook

Sheet Resumo Geral
A1: Jéssica e Michell — levantamento de quantitativo
A2: Projeto ICA · Iara Cezar Arquitetura e Interiores · executivo 10/2026 · 235 páginas · 20 ambientes · 94 detalhamentos
A3: Cada ambiente tem a sua aba. Os números aqui são somas das abas, não valores digitados.
A5: LEVANTAMENTO POR AMBIENTE
A6: Ambiente | B6: Páginas | C6: DET | D6: Área de chapa (m²) | E6: Chapas | F6: Chapa | G6: Fita | H6: Ferragem Blum | I6: Alma de aço | J6: Terceirizados | K6: Custo direto | L6: % do total | M6: Situação
A7: Living | B7: 012–026 | C7: 8 | D7: ='01 Living'!$G$35 | E7: ='01 Living'!$G$36 | F7: ='01 Living'!$G$37 | G7: ='01 Living'!$G$47 | H7: ='01 Living'!$G$61 | I7: ='01 Living'!$G$70 | J7: ='01 Living'!$G$80 | K7: ='01 Living'!$G$100 | L7: =IF($K$27=0,0,K7/$K$27) | M7: Levantado
A8: Cozinha | B8: 028–043 | C8: 5 | L8: =IF($K$27=0,0,K8/$K$27) | M8: A levantar
A9: Lavanderia | B9: 045–060 | C9: 6 | L9: =IF($K$27=0,0,K9/$K$27) | M9: A levantar
A10: Quarto | B10: 062–071 | C10: 6 | L10: =IF($K$27=0,0,K10/$K$27) | M10: A levantar
A11: Lavabo | B11: 073–077 | C11: 2 | L11: =IF($K$27=0,0,K11/$K$27) | M11: A levantar
A12: Área Gourmet | B12: 079–088 | C12: 4 | L12: =IF($K$27=0,0,K12/$K$27) | M12: A levantar
A13: Banho Gourmet | B13: 090–094 | C13: 2 | L13: =IF($K$27=0,0,K13/$K$27) | M13: A levantar
A14: Home Office | B14: 096–104 | C14: 4 | L14: =IF($K$27=0,0,K14/$K$27) | M14: A levantar
A15: Suíte Hóspedes | B15: 106–118 | C15: 8 | L15: =IF($K$27=0,0,K15/$K$27) | M15: A levantar
A16: Banho Hóspedes | B16: 120–124 | C16: 2 | L16: =IF($K$27=0,0,K16/$K$27) | M16: A levantar
A17: Cinema e Ateliê | B17: 127–141 | C17: 10 | L17: =IF($K$27=0,0,K17/$K$27) | M17: A levantar
A18: Suíte Master | B18: 143–153 | C18: 3 | L18: =IF($K$27=0,0,K18/$K$27) | M18: A levantar
A19: Closet Master | B19: 155–166 | C19: 5 | L19: =IF($K$27=0,0,K19/$K$27) | M19: A levantar
... A26: Banho 03 | B26: 232–235 | C26: 2 | L26: =IF($K$27=0,0,K26/$K$27) | M26: A levantar
A27: TOTAL | D27: =SUM(D7:D26) | E27: =SUM(E7:E26) | F27: =SUM(F7:F26) | G27: =SUM(G7:G26) | H27: =SUM(H7:H26) | I27: =SUM(I7:I26) | J27: =SUM(J7:J26) | K27: =SUM(K7:K26)
A29: MATERIAIS, TERCEIRIZADOS E COMISSÕES
A30: Linha | B30: Valor | C30: % do custo direto | M30: Observação
A31: MDF — chapa | B31: =F27 | C31: =IF($K$27=0,0,B31/$K$27) | M31: Todos os padrões Duratex a R$ 600
A32: Fita de borda | B32: =G27 | C32: =IF($K$27=0,0,B32/$K$27)
A33: Ferragem Blum | B33: =H27 | C33: =IF($K$27=0,0,B33/$K$27) | M33: Dobradiça 50, corrediça 250, HK-XS 250, puxador slim 35
A34: Alma de aço | B34: =I27 | C34: =IF($K$27=0,0,B34/$K$27) | M34: Barra chata de 5 mm, uma por peça acima de 30 mm
A35: Iluminação e terceirizados | B35: =J27 | C35: =IF($K$27=0,0,B35/$K$27)
A36: CUSTO DIRETO DO PROJETO | B36: =K27
A38: O que a prancha traz e NÃO é marcenaria
A39: Parede com pedra Atacama Branca, revestimentos e pinturas
A40: Pedras de bancada: quartzito, granito e travertino
A41: Mobiliário solto, luminárias, tapetes, cortinas e espelhos
A42: Eletrodomésticos, cubas, torneiras e metais

Sheet Custos
A1: Custos financeiros e operacionais
A2: Operacional é o que sai da fábrica. Financeiro é o que sai do preço antes de a fábrica ver.
A4: ENTRADAS
A5: Entrada | B5: Valor | D5: Observação
A6: Preço de venda | B6: 0 | D6: A definir — alinhar as questões técnicas antes
A7: Margem de contribuição alvo | B7: 0.4 | D7: Faixa ideal da casa: 35 a 40%
A8: Número de parcelas no cartão | B8: 0 | D8: Zero quando não há cartão
A9: Tem RT? 1 para sim, 0 para não | B9: 1 | D9: Projeto de arquiteta
A10: Tem comissão de vendedor? 1 ou 0 | B10: 0
A12: CUSTOS FINANCEIROS — o que sai do preço antes da fábrica
A13: Linha | B13: Valor | C13: % do preço | D13: Observação
A14: Nota fiscal | B14: =$B$6*'Base de Preços'!$B$33 | C14: =IF($B$6=0,0,B14/$B$6)
A15: Taxa de máquina de cartão | B15: =$B$6*'Base de Preços'!$B$37*$B$8 | C15: =IF($B$6=0,0,B15/$B$6)
A16: Líquido = preço − nota − cartão | B16: =$B$6-B14-B15 | C16: =IF($B$6=0,0,B16/$B$6) | D16: Base da RT e da comissão de vendedor
A17: RT da arquiteta | B17: =$B$16*'Base de Preços'!$B$41*$B$9 | C17: =IF($B$6=0,0,B17/$B$6)
A18: Comissão de vendedor | B18: =$B$16*'Base de Preços'!$B$42*$B$10 | C18: =IF($B$6=0,0,B18/$B$6)
A19: Líquido 2 = líquido − RT − vendedor | B19: =$B$16-B17-B18 | C19: =IF($B$6=0,0,B19/$B$6) | D19: Base de todas as comissões internas
A20: TOTAL FINANCEIRO | B20: =B14+B15+B17+B18 | C20: =IF($B$6=0,0,B20/$B$6)
A22: CUSTOS OPERACIONAIS — o que sai da fábrica
A23: Linha | B23: Valor | C23: % do preço | D23: Observação
A24: Materiais, ferragem e terceirizados | B24: ='Resumo Geral'!$B$36 | C24: =IF($B$6=0,0,B24/$B$6) | D24: Custo direto somado das vinte abas de ambiente
A25: Comissão de produção | B25: =$B$19*'Base de Preços'!$B$46 | C25: =IF($B$6=0,0,B25/$B$6)
A26: Comissão de montagem | B26: =$B$19*'Base de Preços'!$B$47 | C26: =IF($B$6=0,0,B26/$B$6)
A27: Comissão de projeto | B27: =$B$19*'Base de Preços'!$B$48 | C27: =IF($B$6=0,0,B27/$B$6)
A28: Comissão de coordenação | B28: =$B$19*'Base de Preços'!$B$49 | C28: =IF($B$6=0,0,B28/$B$6)
A29: Comissão de gestão de projetos | B29: =$B$19*'Base de Preços'!$B$50 | C29: =IF($B$6=0,0,B29/$B$6)
A30: Margem de erro | B30: =$B$6*'Base de Preços'!$B$34 | C30: =IF($B$6=0,0,B30/$B$6)
A31: Desgaste de serra e fresa | B31: =$B$6*'Base de Preços'!$B$35 | C31: =IF($B$6=0,0,B31/$B$6)
A32: Manutenção de máquinas | B32: =$B$6*'Base de Preços'!$B$36 | C32: =IF($B$6=0,0,B32/$B$6)
A33: TOTAL OPERACIONAL | B33: =SUM(B24:B32) | C33: =IF($B$6=0,0,B33/$B$6)
A35: A BASE DA CASA, NESTA CONDIÇÃO
A36: Linha | B36: Valor | D36: Observação
A37: Encargos sobre o preço, somados | B37: ='Base de Preços'!$B$33+'Base de Preços'!$B$37*$B$8+'Base de Preços'!$B$34+'Base de Preços'!$B$35+'Base de Preços'!$B$36
A38: Líquido, como fração do preço | B38: =1-'Base de Preços'!$B$33-'Base de Preços'!$B$37*$B$8
A39: RT e vendedor, como fração do preço | B39: =B38*('Base de Preços'!$B$41*$B$9+'Base de Preços'!$B$42*$B$10)
A40: Comissões internas, como fração do preço | B40: =(B38-B39)*'Base de Preços'!$B$52
A41: BASE = o que sobra para custo e margem | B41: =1-B37-B39-B40 | D41: Com RT e sem vendedor dá 76,09%; sem os dois, 84,88%
A43: RESULTADO
A44: Linha | B44: Valor | D44: Observação
A45: Preço de venda | B45: =$B$6
...

Sheet Base de Preços
A1: Base de preços e percentuais
A2: Toda célula azul é entrada: mude aqui e o levantamento inteiro acompanha.
A4: MDF — todos os padrões Duratex do projeto
A5: Item | B5: Valor | C5: Origem
A6: Chapa 18 mm | B6: 600 | C6: Jonathan, 26/10/2026
A7: Chapa 15 mm | B7: 500 | C7: base da casa
A8: Chapa 6 mm | B8: 300 | C8: base da casa
A9: Fita de borda de cor, com filetagem (R$/m) | B9: 5.5 | C9: base da casa
A11: Ferragem Blum
A12: Item | B12: Valor | C12: Origem
A13: Dobradiça | B13: 50 | C13: Jonathan, 26/10/2026
A14: Corrediça (por gaveta) | B14: 250 | C14: Jonathan, 26/10/2026
A15: Báscula AVENTOS HK-XS | B15: 250 | C15: Jonathan, 26/10/2026
A16: Puxador slim para báscula | B16: 35 | C16: Jonathan, 26/10/2026
A17: Pulsador por porta | B17: 100 | C17: Jonathan, 26/10/2026 — não usar neste projeto
A19: Estrutura e acabamento
A20: Item | B20: Valor | C20: Origem
A21: Alma de aço — barra chata de 5 mm, barra de 3 m | B21: 50 | C21: Jonathan, 26/10/2026. Uma por peça acima de 30 mm
A22: Perfil de LED com difusor (R$/m) | B22: 65 | C22: base da casa, linha Essencial
A23: Fonte de LED | B23: 120 | C23: base da casa
A25: Rendimento e perdas
A26: Item | B26: Valor | C26: Origem
A27: Aproveitamento de chapa | B27: 0.8 | C27: base da casa
A28: Consumíveis sobre chapa e fita | B28: 0.06 | C28: base da casa
A29: Embalagem sobre o custo direto | B29: 0.02 | C29: base da casa
A31: Cascata — sobre o preço de venda
A32: Item | B32: Valor | C32: Origem
A33: Nota fiscal | B33: 0.05 | C33: base da casa
A34: Margem de erro | B34: 0.02 | C34: base da casa
A35: Desgaste de serra e fresa | B35: 0.005 | C35: base da casa
A36: Manutenção de máquinas | B36: 0.005 | C36: base da casa
A37: Taxa de cartão, por parcela | B37: 0.012 | C37: base da casa
A39: Cascata — sobre o líquido (bruto menos nota e cartão)
A40: Item | B40: Valor | C40: Origem
A41: RT da arquiteta | B41: 0.1 | C41: base da casa
A42: Comissão de vendedor | B42: 0.1 | C42: base da casa
A44: Comissões internas — sobre o líquido 2 (líquido menos RT e vendedor)
A45: Item | B45: Valor | C45: Origem
A46: Produção | B46: 0.025 | C46: Base · Comissões, N.GESTÃO 2
A47: Montagem | B47: 0.025 | C47: Base · Comissões, N.GESTÃO 2
...

Sheet 01 Living
A1: Living
A2: Projeto ICA · páginas 012–026 · 8 detalhamentos · MDF Nogueira Caiena
A4: MÓVEIS DO AMBIENTE
A5: DET | B5: Móvel | C5: O que o projeto especifica | H5: Conferência
A6: 01 | B6: Sapateira com painel | C6: Painel de 300 de altura. Sapateira com puxador cava usinado na própria madeira e LED na base. | H6: Larguras das frentes a confirmar no desenho
A7: 02 | B7: Aparador com gaveta | C7: 185 × 50, altura 45. Gaveta com puxador cava. Vão deixado para planta.
A8: 03 | B8: Prateleira | C8: 135 × 45, com iluminação.
A9: 04 | B9: Divisória em ripas | C9: Onze ripas de 7 com vão de 10, profundidade 20, altura 300. Largura total 177. | H9: Cadeia de cota fecha: 11×7 + 10×10 = 177
A10: 05 | B10: Jardineira com banco | C10: Conjunto de 520. Floreira de 500 × 50. Banco de 80 × 50, altura 44, com LED inferior. | H10: O projeto pede reforço estrutural na parede
A11: 06 | B11: Divisória com cristaleira | C11: Divisória de 360 × 300. Cristaleira de 100 × 260 com portas de giro em vidro reflecta champagne e prateleiras internas iluminadas. Rack com gavetas e base recuada com LED. | H11: Contagem de gavetas e portas a fechar
A12: 07 | B12: Estante | C12: 300 × 215, profundidade 40. Quatro nichos de 48 com fundo ripado. Gavetas com puxador cava. | H12: Contagem de gavetas a fechar
A13: 08 | B13: Painel com porta mimetizada | C13: Painel de 400 × 300. Porta mimetizada de giro de 90 × 210, com puxador cava.
A19: CHAPA | H19: Medidas lidas dos detalhamentos. Levantamento parcial — faltam as peças de caixaria.
A20: Peça | B20: Móvel | C20: Comprimento (cm) | D20: Largura (cm) | E20: Qtd | F20: Esp (mm) | G20: Área (m²) | H20: Observação
A21: Ripa do brise | B21: DET 04 Divisória | C21: 7 | D21: 300 | E21: 11 | F21: 18 | G21: =IF(C21="","",C21*D21*E21/10000) | H21: Vão de 10 entre ripas
A22: Travessa da divisória | B22: DET 04 Divisória | C22: 177 | D22: 20 | E22: 2 | F22: 18 | G22: =IF(C22="","",C22*D22*E22/10000)
A23: Tampo do aparador | B23: DET 02 Aparador | C23: 185 | D23: 50 | E23: 1 | F23: 18 | G23: =IF(C23="","",C23*D23*E23/10000)
A24: Prateleira | B24: DET 03 Prateleira | C24: 135 | D24: 45 | E24: 1 | F24: 18 | G24: =IF(C24="","",C24*D24*E24/10000) | H24: Com iluminação
A25: Lateral da estante | B25: DET 07 Estante | C25: 40 | D25: 215 | E25: 2 | F25: 18 | G25: =IF(C25="","",C25*D25*E25/10000)
A26: Prateleira da estante | B26: DET 07 Estante | C26: 300 | D26: 40 | E26: 4 | F26: 18 | G26: =IF(C26="","",C26*D26*E26/10000) | H26: Quatro nichos de 48
A27: Painel da porta mimetizada | B27: DET 08 Painel | C27: 400 | D27: 300 | E27: 1 | F27: 18 | G27: =IF(C27="","",C27*D27*E27/10000)
A28: Folha da porta mimetizada | B28: DET 08 Painel | C28: 90 | D28: 210 | E28: 1 | F28: 18 | G28: =IF(C28="","",C28*D28*E28/10000)
A29: Floreira | B29: DET 05 Jardineira | C29: 500 | D29: 50 | E29: 1 | F29: 18 | G29: =IF(C29="","",C29*D29*E29/10000)
A30: Assento do banco | B30: DET 05 Jardineira | C30: 80 | D30: 50 | E30: 1 | F30: 18 | G30: =IF(C30="","",C30*D30*E30/10000) | H30: Com LED inferior
G31: =IF(C31="","",C31*D31*E31/10000)
G32: =IF(C32="","",C32*D32*E32/10000)
G33: =IF(C33="","",C33*D33*E33/10000)
G34: =IF(C34="","",C34*D34*E34/10000)
A35: Área total (m²) | G35: =SUM(G21:G34)
A36: Chapas, com aproveitamento | G36: =IF($G$35=0,0,ROUNDUP($G$35/('Base de Preços'!$B$59*'Base de Preços'!$B$27),0))
A37: Custo de chapa | G37: =$G$36*'Base de Preços'!$B$6
A39: FITA DE BORDA
A40: Onde | B40: Móvel | C40: Metros | G40: Custo | H40: Observação
G41: =IF(C41="","",C41*'Base de Preços'!$B$9)
G42: =IF(C42="","",C42*'Base de Preços'!$B$9)
G43: =IF(C43="","",C43*'Base de Preços'!$B$9)
G44: =IF(C44="","",C44*'Base de Preços'!$B$9)
G45: =IF(C45="","",C45*'Base de Preços'!$B$9)
G46: =IF(C46="","",C46*'Base de Preços'!$B$9)
A47: Custo de fita | G47: =SUM(G41:G46)
...
